<robot name="omnibot">
    <link name="base">
        <visual>
            <origin xyz="0 0 0" rpy="0 -0 0" />
            <geometry>
                <mesh filename="package://omnibot_description/urdf/base.stl"/>
            </geometry>
            <material name="base_material">
                <color rgba="0.98039215686274505668 0.71372549019607844922 0.0039215686274509803377 1.0"/>
            </material>
        </visual>
        <collision>
            <origin xyz="0 0 0" rpy="0 -0 0" />
            <geometry>
                <mesh filename="package://omnibot_description/urdf/base.stl"/>
            </geometry>
        </collision>
        <inertial>
            <origin xyz="5.7125161491566575863e-17 -6.5024821714209305867e-17 0.0080527486487109532082" rpy="0 0 0"/>
            <mass value="0.33121488483749478293" />
            <inertia ixx="0.0012461406422939467261" ixy="0"  ixz="0" iyy="0.0012461406422939458587" iyz="0" izz="0.0024316574431770781976" />
        </inertial>
    </link>

    <link name="motor">
        <visual>
            <origin xyz="7.9043193428368358577e-18 0.015229328657860308205 -0.057370000000000025142" rpy="1.1520632371359762718e-32 2.2226360665914211532e-18 -4.9713570571472892865e-32" />
            <geometry>
                <mesh filename="package://omnibot_description/urdf/part_1.stl"/>
            </geometry>
            <material name="part_1_material">
                <color rgba="0.90196078431372550543 0.91764705882352937127 0.92941176470588238168 1.0"/>
            </material>
        </visual>
        <collision>
            <origin xyz="7.9043193428368358577e-18 0.015229328657860308205 -0.057370000000000025142" rpy="1.1520632371359762718e-32 2.2226360665914211532e-18 -4.9713570571472892865e-32" />
            <geometry>
                <mesh filename="package://omnibot_description/urdf/part_1.stl"/>
            </geometry>
        </collision>
        <inertial>
            <origin xyz="-2.098830552812477813e-06 0.015050377580170262726 -0.02165928006021894392" rpy="0 0 0"/>
            <mass value="0.1286049482749511419" />
            <inertia ixx="4.6506247208995554765e-05" ixy="1.6921131916578413861e-09"  ixz="-3.4608427741392948627e-09" iyy="4.6246527094885937542e-05" iyz="1.0074294037198131716e-06" izz="1.0661244977444005866e-05" />
        </inertial>
    </link>

    <link name="wheel">
        <visual>
            <origin xyz="0.018849292529230034926 -0.025304642924402168114 -0.024199999508976458018" rpy="3.141592653589793116 -4.7644572900755180601e-17 1.8430678811938725481" />
            <geometry>
                <mesh filename="package://omnibot_description/urdf/axys_rod.stl"/>
            </geometry>
            <material name="axys_rod_material">
                <color rgba="0.61568627450980395466 0.81176470588235294379 0.92941176470588238168 1.0"/>
            </material>
        </visual>
        <collision>
            <origin xyz="0.018849292529230034926 -0.025304642924402168114 -0.024199999508976458018" rpy="3.141592653589793116 -4.7644572900755180601e-17 1.8430678811938725481" />
            <geometry>
                <mesh filename="package://omnibot_description/urdf/axys_rod.stl"/>
            </geometry>
        </collision>
        <visual>
            <origin xyz="-0.0029828434134273208028 0.031522754648300330138 -0.00999999706275848943" rpy="2.4614437732346262287e-17 2.1952416273112084314e-17 1.2985250346548160572" />
            <geometry>
                <mesh filename="package://omnibot_description/urdf/axys_rod.stl"/>
            </geometry>
            <material name="axys_rod_material">
                <color rgba="0.61568627450980395466 0.81176470588235294379 0.92941176470588238168 1.0"/>
            </material>
        </visual>
        <collision>
            <origin xyz="-0.0029828434134273208028 0.031522754648300330138 -0.00999999706275848943" rpy="2.4614437732346262287e-17 2.1952416273112084314e-17 1.2985250346548160572" />
            <geometry>
                <mesh filename="package://omnibot_description/urdf/axys_rod.stl"/>
            </geometry>
        </collision>
        <visual>
            <origin xyz="-0.019217739019543406132 -0.025322796751039058916 -0.010000003715208136135" rpy="2.4614437732346262287e-17 2.1952416273112084314e-17 1.2985250346548160572" />
            <geometry>
                <mesh filename="package://omnibot_description/urdf/axys_rod.stl"/>
            </geometry>
            <material name="axys_rod_material">
                <color rgba="0.61568627450980395466 0.81176470588235294379 0.92941176470588238168 1.0"/>
            </material>
        </visual>
        <collision>
            <origin xyz="-0.019217739019543406132 -0.025322796751039058916 -0.010000003715208136135" rpy="2.4614437732346262287e-17 2.1952416273112084314e-17 1.2985250346548160572" />
            <geometry>
                <mesh filename="package://omnibot_description/urdf/axys_rod.stl"/>
            </geometry>
        </collision>
        <visual>
            <origin xyz="-0.025693795923572966544 -0.018315214244011321365 -0.010000001453652943018" rpy="-3.141592653589793116 -1.3043559180657304432e-17 0.25132812119095515602" />
            <geometry>
                <mesh filename="package://omnibot_description/urdf/axys_rod.stl"/>
            </geometry>
            <material name="axys_rod_material">
                <color rgba="0.61568627450980395466 0.81176470588235294379 0.92941176470588238168 1.0"/>
            </material>
        </visual>
        <collision>
            <origin xyz="-0.025693795923572966544 -0.018315214244011321365 -0.010000001453652943018" rpy="-3.141592653589793116 -1.3043559180657304432e-17 0.25132812119095515602" />
            <geometry>
                <mesh filename="package://omnibot_description/urdf/axys_rod.stl"/>
            </geometry>
        </collision>
        <visual>
            <origin xyz="0.028708342606700746474 0.01309387383940342417 -0.024199995144404365388" rpy="3.141592653589793116 -1.3122498566019725294e-16 0.79586976703605860628" />
            <geometry>
                <mesh filename="package://omnibot_description/urdf/axys_rod.stl"/>
            </geometry>
            <material name="axys_rod_material">
                <color rgba="0.61568627450980395466 0.81176470588235294379 0.92941176470588238168 1.0"/>
            </material>
        </visual>
        <collision>
            <origin xyz="0.028708342606700746474 0.01309387383940342417 -0.024199995144404365388" rpy="3.141592653589793116 -1.3122498566019725294e-16 0.79586976703605860628" />
            <geometry>
                <mesh filename="package://omnibot_description/urdf/axys_rod.stl"/>
            </geometry>
        </collision>
        <visual>
            <origin xyz="0.025693839153634077249 -0.01831520409297256527 -0.024199999328582064151" rpy="3.141592653589793116 2.1897413049154641094e-17 -0.25132764401668117316" />
            <geometry>
                <mesh filename="package://omnibot_description/urdf/axys_rod.stl"/>
            </geometry>
            <material name="axys_rod_material">
                <color rgba="0.61568627450980395466 0.81176470588235294379 0.92941176470588238168 1.0"/>
            </material>
        </visual>
        <collision>
            <origin xyz="0.025693839153634077249 -0.01831520409297256527 -0.024199999328582064151" rpy="3.141592653589793116 2.1897413049154641094e-17 -0.25132764401668117316" />
            <geometry>
                <mesh filename="package://omnibot_description/urdf/axys_rod.stl"/>
            </geometry>
        </collision>
        <visual>
            <origin xyz="-1.9642151932730556041e-09 -1.7891382439102956554e-10 -0.022199999809268053386" rpy="-3.141592653589793116 -7.2197123923000667429e-17 1.0471975511965978534" />
            <geometry>
                <mesh filename="package://omnibot_description/urdf/plate2.stl"/>
            </geometry>
            <material name="plate2_material">
                <color rgba="0.98039215686274505668 0.79607843137254896693 0.26274509803921569651 1.0"/>
            </material>
        </visual>
        <!-- Shapes for plate2 -->
        <collision>
            <origin xyz="-1.9642151932730556041e-09 -1.7891382428589131662e-10 -0.024199999809268051693" rpy="-3.141592653589793116 -7.2197123923000667429e-17 1.0471975511965978534" />
            <geometry>
                <cylinder length="0.0030000000000000000625" radius="0.034000000000000002442" />
            </geometry>
        </collision>
        <visual>
            <origin xyz="0.015937773618267953024 0.0042705139175610584701 -0.012000000000003036016" rpy="-3.141592653589793116 1.6962974652580569478e-28 -2.3422611302673121514e-32" />
            <geometry>
                <mesh filename="package://omnibot_description/urdf/spacer.stl"/>
            </geometry>
            <material name="spacer_material">
                <color rgba="1 0.7568627450980391913 0.054901960784313724728 1.0"/>
            </material>
        </visual>
        <collision>
            <origin xyz="0.015937773618267953024 0.0042705139175610584701 -0.012000000000003036016" rpy="-3.141592653589793116 1.6962974652580569478e-28 -2.3422611302673121514e-32" />
            <geometry>
                <mesh filename="package://omnibot_description/urdf/spacer.stl"/>
            </geometry>
        </collision>
        <visual>
            <origin xyz="2.001760042447120469e-11 -1.9338654079413060799e-11 -0.012000000000003147038" rpy="1.9022338643349641804e-17 1.6962974652580569478e-28 -2.3422611302673121514e-32" />
            <geometry>
                <mesh filename="package://omnibot_description/urdf/plate1.stl"/>
            </geometry>
            <material name="plate1_material">
                <color rgba="1 0.7568627450980391913 0.054901960784313724728 1.0"/>
            </material>
        </visual>
        <!-- Shapes for plate1 -->
        <collision>
            <origin xyz="2.001760042447120469e-11 -1.9338654184551312951e-11 -0.010000000000003146997" rpy="1.9022338643349641804e-17 1.6962974652580569478e-28 -2.3422611302673121514e-32" />
            <geometry>
                <cylinder length="0.0030000000000000000625" radius="0.034000000000000002442" />
            </geometry>
        </collision>
        <visual>
            <origin xyz="-0.028790909644556491459 0.013178153068647131124 -0.01000000062226605313" rpy="-3.141592653589793116 7.5788537773920091237e-17 -0.79586931499755342312" />
            <geometry>
                <mesh filename="package://omnibot_description/urdf/axys_rod.stl"/>
            </geometry>
            <material name="axys_rod_material">
                <color rgba="0.61568627450980395466 0.81176470588235294379 0.92941176470588238168 1.0"/>
            </material>
        </visual>
        <collision>
            <origin xyz="-0.028790909644556491459 0.013178153068647131124 -0.01000000062226605313" rpy="-3.141592653589793116 7.5788537773920091237e-17 -0.79586931499755342312" />
            <geometry>
                <mesh filename="package://omnibot_description/urdf/axys_rod.stl"/>
            </geometry>
        </collision>
        <visual>
            <origin xyz="0.02580811602108519856 0.018344566682607629793 -0.010000000481623277926" rpy="3.5691146390301812134e-17 -1.2715429987453172065e-17 0.25132812119095515602" />
            <geometry>
                <mesh filename="package://omnibot_description/urdf/axys_rod.stl"/>
            </geometry>
            <material name="axys_rod_material">
                <color rgba="0.61568627450980395466 0.81176470588235294379 0.92941176470588238168 1.0"/>
            </material>
        </visual>
        <collision>
            <origin xyz="0.02580811602108519856 0.018344566682607629793 -0.010000000481623277926" rpy="3.5691146390301812134e-17 -1.2715429987453172065e-17 0.25132812119095515602" />
            <geometry>
                <mesh filename="package://omnibot_description/urdf/axys_rod.stl"/>
            </geometry>
        </collision>
        <visual>
            <origin xyz="-0.025693825391882991332 0.018315274927571172092 -0.024199999573447886214" rpy="-2.849706463173791796e-17 2.2225542242358670231e-17 -0.25132764401668117316" />
            <geometry>
                <mesh filename="package://omnibot_description/urdf/axys_rod.stl"/>
            </geometry>
            <material name="axys_rod_material">
                <color rgba="0.61568627450980395466 0.81176470588235294379 0.92941176470588238168 1.0"/>
            </material>
        </visual>
        <collision>
            <origin xyz="-0.025693825391882991332 0.018315274927571172092 -0.024199999573447886214" rpy="-2.849706463173791796e-17 2.2225542242358670231e-17 -0.25132764401668117316" />
            <geometry>
                <mesh filename="package://omnibot_description/urdf/axys_rod.stl"/>
            </geometry>
        </collision>
        <visual>
            <origin xyz="-0.015937773364185364722 -0.0042705132347586136771 -0.012000000000003202549" rpy="-3.141592653589793116 1.6962974652580569478e-28 -2.3422611302673121514e-32" />
            <geometry>
                <mesh filename="package://omnibot_description/urdf/spacer.stl"/>
            </geometry>
            <material name="spacer_material">
                <color rgba="1 0.7568627450980391913 0.054901960784313724728 1.0"/>
            </material>
        </visual>
        <collision>
            <origin xyz="-0.015937773364185364722 -0.0042705132347586136771 -0.012000000000003202549" rpy="-3.141592653589793116 1.6962974652580569478e-28 -2.3422611302673121514e-32" />
            <geometry>
                <mesh filename="package://omnibot_description/urdf/spacer.stl"/>
            </geometry>
        </collision>
        <visual>
            <origin xyz="0.028790823204502383886 -0.013178235601432183519 -0.010000000285351320906" rpy="5.4374863009449955638e-17 7.5788537773920091237e-17 -0.79586931499755342312" />
            <geometry>
                <mesh filename="package://omnibot_description/urdf/axys_rod.stl"/>
            </geometry>
            <material name="axys_rod_material">
                <color rgba="0.61568627450980395466 0.81176470588235294379 0.92941176470588238168 1.0"/>
            </material>
        </visual>
        <collision>
            <origin xyz="0.028790823204502383886 -0.013178235601432183519 -0.010000000285351320906" rpy="5.4374863009449955638e-17 7.5788537773920091237e-17 -0.79586931499755342312" />
            <geometry>
                <mesh filename="package://omnibot_description/urdf/axys_rod.stl"/>
            </geometry>
        </collision>
        <visual>
            <origin xyz="0.0030145071180058581606 0.031409130275868703264 -0.024199999101464725326" rpy="3.141592653589793116 -4.8957089673571784025e-17 1.843067881193871882" />
            <geometry>
                <mesh filename="package://omnibot_description/urdf/axys_rod.stl"/>
            </geometry>
            <material name="axys_rod_material">
                <color rgba="0.61568627450980395466 0.81176470588235294379 0.92941176470588238168 1.0"/>
            </material>
        </visual>
        <collision>
            <origin xyz="0.0030145071180058581606 0.031409130275868703264 -0.024199999101464725326" rpy="3.141592653589793116 -4.8957089673571784025e-17 1.843067881193871882" />
            <geometry>
                <mesh filename="package://omnibot_description/urdf/axys_rod.stl"/>
            </geometry>
        </collision>
        <visual>
            <origin xyz="-0.028708344080531279785 -0.013093882512642342902 -0.02419999841828643361" rpy="-9.6174079307260302496e-17 -1.3122498566019725294e-16 0.79586976703605860628" />
            <geometry>
                <mesh filename="package://omnibot_description/urdf/axys_rod.stl"/>
            </geometry>
            <material name="axys_rod_material">
                <color rgba="0.61568627450980395466 0.81176470588235294379 0.92941176470588238168 1.0"/>
            </material>
        </visual>
        <collision>
            <origin xyz="-0.028708344080531279785 -0.013093882512642342902 -0.02419999841828643361" rpy="-9.6174079307260302496e-17 -1.3122498566019725294e-16 0.79586976703605860628" />
            <geometry>
                <mesh filename="package://omnibot_description/urdf/axys_rod.stl"/>
            </geometry>
        </collision>
        <inertial>
            <origin xyz="-9.4588917160583760242e-06 -8.8415141495200006669e-06 -0.015131125342708530435" rpy="0 0 0"/>
            <mass value="0.019223052335254620093" />
            <inertia ixx="5.399262953463332839e-06" ixy="-7.3246329002135788826e-08"  ixz="-1.2642889979755781e-09" iyy="5.6557979176500377362e-06" iyz="1.9098649289524068763e-09" izz="8.6846392930505500327e-06" />
        </inertial>
    </link>

    <link name="roller">
        <visual>
            <origin xyz="1.3877787807814456755e-17 1.3877787807814456755e-17 1.7347234759768070944e-18" rpy="8.4604260194624822847e-17 -1.8219368201364345511e-17 1.6366358251416698839e-17" />
            <geometry>
                <mesh filename="package://omnibot_description/urdf/roller.stl"/>
            </geometry>
            <material name="roller_material">
                <color rgba="0.098039215686274508443 0.098039215686274508443 0.098039215686274508443 1.0"/>
            </material>
        </visual>
        <!-- Shapes for roller -->
        <collision>
            <origin xyz="1.3877787807814456755e-17 1.3877787807814456755e-17 1.7347234759768070944e-18" rpy="8.4604260194624822847e-17 -1.8219368201364345511e-17 1.6366358251416698839e-17" />
            <geometry>
                <sphere radius="0.007700000000000000247" />
            </geometry>
        </collision>
        <inertial>
            <origin xyz="4.0756135840652012993e-11 8.4957117072138698775e-11 2.4283850775576134338e-11" rpy="0 0 0"/>
            <mass value="0.0037899803393768708749" />
            <inertia ixx="1.8303635244743848899e-07" ixy="4.2716081106694475295e-16"  ixz="-1.7514569765292920798e-15" iyy="1.830363607521377626e-07" iyz="-3.3429142897629588724e-15" izz="9.8097062080638907831e-08" />
        </inertial>
    </link>

    <joint name="roller2_1" type="revolute">
        <origin xyz="0.020681564833504317152 -0.021119421197575767579 -0.010000000285351307028" rpy="1.570796326794896336 -0.6597090063277464278 2.3457233385922444668" />
        <parent link="wheel" />
        <child link="roller" />
        <axis xyz="0 0 1"/>
        <limit effort="1" velocity="20" />
        <joint_properties friction="0.0"/>
    </joint>

    <link name="roller_2">
        <visual>
            <origin xyz="0 -6.9388939039072283776e-18 3.9031278209478159624e-18" rpy="4.4368715758058417424e-17 2.6090501985764299822e-17 7.8538928552350257608e-17" />
            <geometry>
                <mesh filename="package://omnibot_description/urdf/roller.stl"/>
            </geometry>
            <material name="roller_material">
                <color rgba="0.098039215686274508443 0.098039215686274508443 0.098039215686274508443 1.0"/>
            </material>
        </visual>
        <!-- Shapes for roller -->
        <collision>
            <origin xyz="0 -6.9388939039072283776e-18 3.9031278209478159624e-18" rpy="4.4368715758058417424e-17 2.6090501985764299822e-17 7.8538928552350257608e-17" />
            <geometry>
                <sphere radius="0.007700000000000000247" />
            </geometry>
        </collision>
        <inertial>
            <origin xyz="4.0756121962864192254e-11 8.4957096255456987054e-11 2.4283852943980476078e-11" rpy="0 0 0"/>
            <mass value="0.0037899803393768708749" />
            <inertia ixx="1.8303635244743854193e-07" ixy="4.2716078458527829931e-16"  ixz="-1.751456981042169681e-15" iyy="1.8303636075213770966e-07" iyz="-3.3429143019086877485e-15" izz="9.80970620806389343e-08" />
        </inertial>
    </link>

    <joint name="roller2_2" type="revolute">
        <origin xyz="0.028630754033681701104 0.0073511498047736482941 -0.01000000048162325017" rpy="-1.57079632679489678 -0.95923833802399638415 -2.8902645323988411796" />
        <parent link="wheel" />
        <child link="roller_2" />
        <axis xyz="0 0 1"/>
        <limit effort="1" velocity="20" />
        <joint_properties friction="0.0"/>
    </joint>

    <link name="roller_3">
        <visual>
            <origin xyz="1.3877787807814456755e-17 -1.3877787807814456755e-17 0" rpy="-6.4068643054909384684e-17 1.9741880418348328749e-17 2.3062138514014462605e-17" />
            <geometry>
                <mesh filename="package://omnibot_description/urdf/roller.stl"/>
            </geometry>
            <material name="roller_material">
                <color rgba="0.098039215686274508443 0.098039215686274508443 0.098039215686274508443 1.0"/>
            </material>
        </visual>
        <!-- Shapes for roller -->
        <collision>
            <origin xyz="1.3877787807814456755e-17 -1.3877787807814456755e-17 0" rpy="-6.4068643054909384684e-17 1.9741880418348328749e-17 2.3062138514014462605e-17" />
            <geometry>
                <sphere radius="0.007700000000000000247" />
            </geometry>
        </collision>
        <inertial>
            <origin xyz="4.0756135840652019455e-11 8.4957089316563096071e-11 2.4283849040852648668e-11" rpy="0 0 0"/>
            <mass value="0.0037899803393768708749" />
            <inertia ixx="1.8303635244743854193e-07" ixy="4.2716080627510399541e-16"  ixz="-1.7514569870059841569e-15" iyy="1.8303636075213781554e-07" iyz="-3.3429143193791973637e-15" izz="9.80970620806389343e-08" />
        </inertial>
    </link>

    <joint name="roller2_3" type="revolute">
        <origin xyz="0.020599080645981818899 0.021035055769849139717 -0.024199995144404309877" rpy="1.570796326794896558 -1.0050751734414828942 0.79586976703605405437" />
        <parent link="wheel" />
        <child link="roller_3" />
        <axis xyz="0 0 1"/>
        <limit effort="1" velocity="20" />
        <joint_properties friction="0.0"/>
    </joint>

    <link name="roller_4">
        <visual>
            <origin xyz="1.3877787807814456755e-17 0 -1.7347234759768070944e-18" rpy="-1.7676075678995796423e-17 1.2049021684086540012e-17 -4.6130461232397385939e-18" />
            <geometry>
                <mesh filename="package://omnibot_description/urdf/roller.stl"/>
            </geometry>
            <material name="roller_material">
                <color rgba="0.098039215686274508443 0.098039215686274508443 0.098039215686274508443 1.0"/>
            </material>
        </visual>
        <!-- Shapes for roller -->
        <collision>
            <origin xyz="1.3877787807814456755e-17 0 -1.7347234759768070944e-18" rpy="-1.7676075678995796423e-17 1.2049021684086540012e-17 -4.6130461232397385939e-18" />
            <geometry>
                <sphere radius="0.007700000000000000247" />
            </geometry>
        </collision>
        <inertial>
            <origin xyz="4.0756135840652019455e-11 8.495710319435091681e-11 2.4283847306129175922e-11" rpy="0 0 0"/>
            <mass value="0.0037899803393768708749" />
            <inertia ixx="1.8303635244743854193e-07" ixy="4.271608092272604783e-16"  ixz="-1.751456983106221873e-15" iyy="1.8303636075213792142e-07" iyz="-3.3429143109759634615e-15" izz="9.8097062080638907831e-08" />
        </inertial>
    </link>

    <joint name="roller2_4" type="revolute">
        <origin xyz="0.0079490519369571598085 0.028470515462351391606 -0.00999999706275848943" rpy="1.570796326794896558 1.0765431582887567963 -1.8430676189349801675" />
        <parent link="wheel" />
        <child link="roller_4" />
        <axis xyz="0 0 1"/>
        <limit effort="1" velocity="20" />
        <joint_properties friction="0.0"/>
    </joint>

    <link name="roller_5">
        <visual>
            <origin xyz="-1.3877787807814456755e-17 0 0" rpy="1.7019252966706433505e-18 8.6411508423669180333e-18 -1.3187109991941148993e-17" />
            <geometry>
                <mesh filename="package://omnibot_description/urdf/roller.stl"/>
            </geometry>
            <material name="roller_material">
                <color rgba="0.098039215686274508443 0.098039215686274508443 0.098039215686274508443 1.0"/>
            </material>
        </visual>
        <!-- Shapes for roller -->
        <collision>
            <origin xyz="-1.3877787807814456755e-17 0 0" rpy="1.7019252966706433505e-18 8.6411508423669180333e-18 -1.3187109991941148993e-17" />
            <geometry>
                <sphere radius="0.007700000000000000247" />
            </geometry>
        </collision>
        <inertial>
            <origin xyz="4.0756108085076403826e-11 8.4957103194350890961e-11 2.428384904085265513e-11" rpy="0 0 0"/>
            <mass value="0.0037899803393768708749" />
            <inertia ixx="1.8303635244743854193e-07" ixy="4.2716081044029204016e-16"  ixz="-1.7514569809710087081e-15" iyy="1.830363607521377626e-07" iyz="-3.3429143052953934379e-15" izz="9.80970620806389343e-08" />
        </inertial>
    </link>

    <joint name="roller2_5" type="revolute">
        <origin xyz="-0.0079173874319013633205 0.028356888222933061133 -0.024199999101464753082" rpy="1.57079632679489678 -1.0027977690887008855 1.8430678811938736583" />
        <parent link="wheel" />
        <child link="roller_5" />
        <axis xyz="0 0 1"/>
        <limit effort="1" velocity="20" />
        <joint_properties friction="0.0"/>
    </joint>

    <link name="roller_6">
        <visual>
            <origin xyz="-6.9388939039072283776e-18 1.3877787807814456755e-17 1.7347234759768070944e-18" rpy="-8.4604260194624822847e-17 -1.8219368201364345511e-17 -1.6366358251416698839e-17" />
            <geometry>
                <mesh filename="package://omnibot_description/urdf/roller.stl"/>
            </geometry>
            <material name="roller_material">
                <color rgba="0.098039215686274508443 0.098039215686274508443 0.098039215686274508443 1.0"/>
            </material>
        </visual>
        <!-- Shapes for roller -->
        <collision>
            <origin xyz="-6.9388939039072283776e-18 1.3877787807814456755e-17 1.7347234759768070944e-18" rpy="-8.4604260194624822847e-17 -1.8219368201364345511e-17 -1.6366358251416698839e-17" />
            <geometry>
                <sphere radius="0.007700000000000000247" />
            </geometry>
        </collision>
        <inertial>
            <origin xyz="4.0756115023970301271e-11 8.4957117072138698775e-11 2.4283850775576121413e-11" rpy="0 0 0"/>
            <mass value="0.0037899803393768708749" />
            <inertia ixx="1.8303635244743848899e-07" ixy="4.2716080676782262181e-16"  ixz="-1.7514569765292920798e-15" iyy="1.830363607521377626e-07" iyz="-3.3429143217847628243e-15" izz="9.8097062080638907831e-08" />
        </inertial>
    </link>

    <joint name="roller2_6" type="revolute">
        <origin xyz="-0.020681651273558431664 0.021119338664790682225 -0.010000000622266080885" rpy="1.57079632679489678 0.6597090063277464278 -0.7958693149975488712" />
        <parent link="wheel" />
        <child link="roller_6" />
        <axis xyz="0 0 1"/>
        <limit effort="1" velocity="20" />
        <joint_properties friction="0.0"/>
    </joint>

    <link name="roller_7">
        <visual>
            <origin xyz="0 0 -4.7704895589362195096e-18" rpy="5.7642868478283196294e-17 5.5471936067846187847e-18 -1.4245567939603574315e-17" />
            <geometry>
                <mesh filename="package://omnibot_description/urdf/roller.stl"/>
            </geometry>
            <material name="roller_material">
                <color rgba="0.098039215686274508443 0.098039215686274508443 0.098039215686274508443 1.0"/>
            </material>
        </visual>
        <!-- Shapes for roller -->
        <collision>
            <origin xyz="0 0 -4.7704895589362195096e-18" rpy="5.7642868478283196294e-17 5.5471936067846187847e-18 -1.4245567939603574315e-17" />
            <geometry>
                <sphere radius="0.007700000000000000247" />
            </geometry>
        </collision>
        <inertial>
            <origin xyz="4.0756121962864211641e-11 8.4957103194350890961e-11 2.4283844270363099425e-11" rpy="0 0 0"/>
            <mass value="0.0037899803393768708749" />
            <inertia ixx="1.8303635244743854193e-07" ixy="4.271608046425789332e-16"  ixz="-1.7514569811553552465e-15" iyy="1.830363607521377626e-07" iyz="-3.34291429855321464e-15" izz="9.8097062080638907831e-08" />
        </inertial>
    </link>

    <joint name="roller2_7" type="revolute">
        <origin xyz="-0.028516458158703433812 0.0073218567028481632009 -0.024199999573447886214" rpy="-1.570796326794896558 -0.029118128194412656179 -0.25132764401667873067" />
        <parent link="wheel" />
        <child link="roller_7" />
        <axis xyz="0 0 1"/>
        <limit effort="1" velocity="20" />
        <joint_properties friction="0.0"/>
    </joint>

    <link name="roller_8">
        <visual>
            <origin xyz="-1.3877787807814456755e-17 -6.9388939039072283776e-18 6.9388939039072283776e-18" rpy="-6.4068643054909384684e-17 1.9741880418348328749e-17 2.3062138514014462605e-17" />
            <geometry>
                <mesh filename="package://omnibot_description/urdf/roller.stl"/>
            </geometry>
            <material name="roller_material">
                <color rgba="0.098039215686274508443 0.098039215686274508443 0.098039215686274508443 1.0"/>
            </material>
        </visual>
        <!-- Shapes for roller -->
        <collision>
            <origin xyz="-1.3877787807814456755e-17 -6.9388939039072283776e-18 6.9388939039072283776e-18" rpy="-6.4068643054909384684e-17 1.9741880418348328749e-17 2.3062138514014462605e-17" />
            <geometry>
                <sphere radius="0.007700000000000000247" />
            </geometry>
        </collision>
        <inertial>
            <origin xyz="4.0756108085076403826e-11 8.4957096255456999978e-11 2.4283855979746552575e-11" rpy="0 0 0"/>
            <mass value="0.0037899803393768708749" />
            <inertia ixx="1.8303635244743854193e-07" ixy="4.2716080627510399541e-16"  ixz="-1.7514569870059841569e-15" iyy="1.8303636075213781554e-07" iyz="-3.3429143193791973637e-15" izz="9.80970620806389343e-08" />
        </inertial>
    </link>

    <joint name="roller2_8" type="revolute">
        <origin xyz="-0.02059908211981235221 -0.021035064443088044572 -0.02419999841828643361" rpy="1.570796326794896558 -1.0050751734414828942 0.79586976703605405437" />
        <parent link="wheel" />
        <child link="roller_8" />
        <axis xyz="0 0 1"/>
        <limit effort="1" velocity="20" />
        <joint_properties friction="0.0"/>
    </joint>

    <link name="roller_9">
        <visual>
            <origin xyz="1.3877787807814456755e-17 1.3877787807814456755e-17 -8.6736173798840354721e-19" rpy="-2.2776860711251902308e-17 -3.2825902441946524091e-17 -2.292842158329127773e-17" />
            <geometry>
                <mesh filename="package://omnibot_description/urdf/roller.stl"/>
            </geometry>
            <material name="roller_material">
                <color rgba="0.098039215686274508443 0.098039215686274508443 0.098039215686274508443 1.0"/>
            </material>
        </visual>
        <!-- Shapes for roller -->
        <collision>
            <origin xyz="1.3877787807814456755e-17 1.3877787807814456755e-17 -8.6736173798840354721e-19" rpy="-2.2776860711251902308e-17 -3.2825902441946524091e-17 -2.292842158329127773e-17" />
            <geometry>
                <sphere radius="0.007700000000000000247" />
            </geometry>
        </collision>
        <inertial>
            <origin xyz="4.0756135840652000068e-11 8.4957117072138698775e-11 2.4283848173490913911e-11" rpy="0 0 0"/>
            <mass value="0.0037899803393768708749" />
            <inertia ixx="1.8303635244743854193e-07" ixy="4.2716076907875811034e-16"  ixz="-1.7514569754125442947e-15" iyy="1.830363607521377626e-07" iyz="-3.3429143098803315108e-15" izz="9.80970620806389343e-08" />
        </inertial>
    </link>

    <joint name="roller2_9" type="revolute">
        <origin xyz="-0.028516433936169462149 -0.0073217973661773502747 -0.010000001453652984651" rpy="-1.570796326794896558 -0.95923833802399638415 -2.8902645323988411796" />
        <parent link="wheel" />
        <child link="roller_9" />
        <axis xyz="0 0 1"/>
        <limit effort="1" velocity="20" />
        <joint_properties friction="0.0"/>
    </joint>

    <link name="roller_10">
        <visual>
            <origin xyz="2.7755575615628913511e-17 -6.9388939039072283776e-18 0" rpy="-1.7676075678995796423e-17 1.2049021684086540012e-17 -4.6130461232397385939e-18" />
            <geometry>
                <mesh filename="package://omnibot_description/urdf/roller.stl"/>
            </geometry>
            <material name="roller_material">
                <color rgba="0.098039215686274508443 0.098039215686274508443 0.098039215686274508443 1.0"/>
            </material>
        </visual>
        <!-- Shapes for roller -->
        <collision>
            <origin xyz="2.7755575615628913511e-17 -6.9388939039072283776e-18 0" rpy="-1.7676075678995796423e-17 1.2049021684086540012e-17 -4.6130461232397385939e-18" />
            <geometry>
                <sphere radius="0.007700000000000000247" />
            </geometry>
        </collision>
        <inertial>
            <origin xyz="4.075614971843982727e-11 8.4957096255457012903e-11 2.4283849040852651899e-11" rpy="0 0 0"/>
            <mass value="0.0037899803393768708749" />
            <inertia ixx="1.8303635244743854193e-07" ixy="4.271608092272604783e-16"  ixz="-1.751456983106221873e-15" iyy="1.8303636075213792142e-07" iyz="-3.3429143109759634615e-15" izz="9.8097062080638907831e-08" />
        </inertial>
    </link>

    <joint name="roller2_10" type="revolute">
        <origin xyz="-0.0082858436691589446021 -0.028375035936988014795 -0.010000003715208150012" rpy="1.570796326794896558 1.0765431582887567963 -1.8430676189349801675" />
        <parent link="wheel" />
        <child link="roller_10" />
        <axis xyz="0 0 1"/>
        <limit effort="1" velocity="20" />
        <joint_properties friction="0.0"/>
    </joint>

    <link name="roller_11">
        <visual>
            <origin xyz="1.3877787807814456755e-17 6.9388939039072283776e-18 3.4694469519536141888e-18" rpy="-5.896634328144456999e-17 -1.0144966984938724273e-17 -8.8020282851431897244e-18" />
            <geometry>
                <mesh filename="package://omnibot_description/urdf/roller.stl"/>
            </geometry>
            <material name="roller_material">
                <color rgba="0.098039215686274508443 0.098039215686274508443 0.098039215686274508443 1.0"/>
            </material>
        </visual>
        <!-- Shapes for roller -->
        <collision>
            <origin xyz="1.3877787807814456755e-17 6.9388939039072283776e-18 3.4694469519536141888e-18" rpy="-5.896634328144456999e-17 -1.0144966984938724273e-17 -8.8020282851431897244e-18" />
            <geometry>
                <sphere radius="0.007700000000000000247" />
            </geometry>
        </collision>
        <inertial>
            <origin xyz="4.0756135840652019455e-11 8.4957110133244794868e-11 2.4283852510299600621e-11" rpy="0 0 0"/>
            <mass value="0.0037899803393768708749" />
            <inertia ixx="1.8303635244743854193e-07" ixy="4.2716080561380086318e-16"  ixz="-1.7514569822298226508e-15" iyy="1.830363607521377626e-07" iyz="-3.342914316635861385e-15" izz="9.80970620806389343e-08" />
        </inertial>
    </link>

    <joint name="roller2_11" type="revolute">
        <origin xyz="0.0079173979793228238533 -0.028356884977337862286 -0.024199999508976485774" rpy="1.570796326794896558 1.0027977690887006634 -1.2985247723959187915" />
        <parent link="wheel" />
        <child link="roller_11" />
        <axis xyz="0 0 1"/>
        <limit effort="1" velocity="20" />
        <joint_properties friction="0.0"/>
    </joint>

    <link name="roller_12">
        <visual>
            <origin xyz="6.9388939039072283776e-18 0 4.336808689942017736e-18" rpy="-8.7335640646425253836e-17 -2.0296175043529748205e-17 2.7316262322877970588e-17" />
            <geometry>
                <mesh filename="package://omnibot_description/urdf/roller.stl"/>
            </geometry>
            <material name="roller_material">
                <color rgba="0.098039215686274508443 0.098039215686274508443 0.098039215686274508443 1.0"/>
            </material>
        </visual>
        <!-- Shapes for roller -->
        <collision>
            <origin xyz="6.9388939039072283776e-18 0 4.336808689942017736e-18" rpy="-8.7335640646425253836e-17 -2.0296175043529748205e-17 2.7316262322877970588e-17" />
            <geometry>
                <sphere radius="0.007700000000000000247" />
            </geometry>
        </collision>
        <inertial>
            <origin xyz="4.0756128901758115548e-11 8.4957103194350903886e-11 2.428385337766133861e-11" rpy="0 0 0"/>
            <mass value="0.0037899803393768708749" />
            <inertia ixx="1.8303635244743854193e-07" ixy="4.2716081815891749243e-16"  ixz="-1.7514569816829783549e-15" iyy="1.8303636075213781554e-07" iyz="-3.3429143248306135495e-15" izz="9.80970620806389343e-08" />
        </inertial>
    </link>

    <joint name="roller2_12" type="revolute">
        <origin xyz="0.028516471920454564831 -0.0073217858682495711234 -0.024199999328582064151" rpy="-1.570796326794896558 -0.029118128194412718629 -0.25132764401667873067" />
        <parent link="wheel" />
        <child link="roller_12" />
        <axis xyz="0 0 1"/>
        <limit effort="1" velocity="20" />
        <joint_properties friction="0.0"/>
    </joint>

    <joint name="wheel2" type="revolute">
        <origin xyz="1.6916223843148240913e-18 0.015229328657860304735 2.999999999994673594e-05" rpy="3.141592653589793116 -3.460379863012290867e-16 1.570796326794896558" />
        <parent link="motor" />
        <child link="wheel" />
        <axis xyz="0 0 1"/>
        <limit effort="1" velocity="20" />
        <joint_properties friction="0.0"/>
    </joint>

    <joint name="motor1" type="fixed">
        <origin xyz="0.073581777378123131017 -0.041158680771919600727 2.6020852139652106416e-17" rpy="-1.570796326794896336 -1.660721004497953203e-16 -2.0807970750313837804" />
        <parent link="base" />
        <child link="motor" />
        <axis xyz="0 0 1"/>
        <limit effort="1" velocity="20" />
        <joint_properties friction="0.0"/>
    </joint>

    <link name="motor_2">
        <visual>
            <origin xyz="-4.0834403682039520383e-19 0.015229328657860308205 -0.057370000000000032081" rpy="0 -1.9568663227028638094e-18 0" />
            <geometry>
                <mesh filename="package://omnibot_description/urdf/part_1.stl"/>
            </geometry>
            <material name="part_1_material">
                <color rgba="0.90196078431372550543 0.91764705882352937127 0.92941176470588238168 1.0"/>
            </material>
        </visual>
        <collision>
            <origin xyz="-4.0834403682039520383e-19 0.015229328657860308205 -0.057370000000000032081" rpy="0 -1.9568663227028638094e-18 0" />
            <geometry>
                <mesh filename="package://omnibot_description/urdf/part_1.stl"/>
            </geometry>
        </collision>
        <inertial>
            <origin xyz="-2.0988305528217147073e-06 0.015050377580170262726 -0.021659280060218950859" rpy="0 0 0"/>
            <mass value="0.1286049482749511419" />
            <inertia ixx="4.6506247208995541212e-05" ixy="1.6921131916578151231e-09"  ixz="-3.4608427741393759264e-09" iyy="4.6246527094885937542e-05" iyz="1.0074294037198131716e-06" izz="1.0661244977444005866e-05" />
        </inertial>
    </link>

    <link name="wheel_2">
        <visual>
            <origin xyz="0.018849292529232342108 -0.025304642924407171056 -0.024199999508977207419" rpy="3.1415926535897824579 2.4975157029890339545e-14 1.8430678811939182893" />
            <geometry>
                <mesh filename="package://omnibot_description/urdf/axys_rod.stl"/>
            </geometry>
            <material name="axys_rod_material">
                <color rgba="0.61568627450980395466 0.81176470588235294379 0.92941176470588238168 1.0"/>
            </material>
        </visual>
        <collision>
            <origin xyz="0.018849292529232342108 -0.025304642924407171056 -0.024199999508977207419" rpy="3.1415926535897824579 2.4975157029890339545e-14 1.8430678811939182893" />
            <geometry>
                <mesh filename="package://omnibot_description/urdf/axys_rod.stl"/>
            </geometry>
        </collision>
        <visual>
            <origin xyz="-0.0029828434134281061989 0.031522754648305895131 -0.0099999970627596551642" rpy="4.2008548985063396812e-14 -5.1841994795787341209e-14 1.2985250346548573575" />
            <geometry>
                <mesh filename="package://omnibot_description/urdf/axys_rod.stl"/>
            </geometry>
            <material name="axys_rod_material">
                <color rgba="0.61568627450980395466 0.81176470588235294379 0.92941176470588238168 1.0"/>
            </material>
        </visual>
        <collision>
            <origin xyz="-0.0029828434134281061989 0.031522754648305895131 -0.0099999970627596551642" rpy="4.2008548985063396812e-14 -5.1841994795787341209e-14 1.2985250346548573575" />
            <geometry>
                <mesh filename="package://omnibot_description/urdf/axys_rod.stl"/>
            </geometry>
        </collision>
        <visual>
            <origin xyz="-0.019217739019544832074 -0.025322796751043246538 -0.010000003715206873256" rpy="4.2008548985063396812e-14 -5.1841994795787341209e-14 1.2985250346548573575" />
            <geometry>
                <mesh filename="package://omnibot_description/urdf/axys_rod.stl"/>
            </geometry>
            <material name="axys_rod_material">
                <color rgba="0.61568627450980395466 0.81176470588235294379 0.92941176470588238168 1.0"/>
            </material>
        </visual>
        <collision>
            <origin xyz="-0.019217739019544832074 -0.025322796751043246538 -0.010000003715206873256" rpy="4.2008548985063396812e-14 -5.1841994795787341209e-14 1.2985250346548573575" />
            <geometry>
                <mesh filename="package://omnibot_description/urdf/axys_rod.stl"/>
            </geometry>
        </collision>
        <visual>
            <origin xyz="-0.025693795923575037804 -0.018315214244014266926 -0.01000000145365198545" rpy="3.141592653589628803 1.323052793671451623e-14 0.25132812119096081815" />
            <geometry>
                <mesh filename="package://omnibot_description/urdf/axys_rod.stl"/>
            </geometry>
            <material name="axys_rod_material">
                <color rgba="0.61568627450980395466 0.81176470588235294379 0.92941176470588238168 1.0"/>
            </material>
        </visual>
        <collision>
            <origin xyz="-0.025693795923575037804 -0.018315214244014266926 -0.01000000145365198545" rpy="3.141592653589628803 1.323052793671451623e-14 0.25132812119096081815" />
            <geometry>
                <mesh filename="package://omnibot_description/urdf/axys_rod.stl"/>
            </geometry>
        </collision>
        <visual>
            <origin xyz="0.028708342606703379785 0.013093873839405009707 -0.024199995144406571956" rpy="3.141592653589708739 5.5072761469850945214e-14 0.79586976703608003358" />
            <geometry>
                <mesh filename="package://omnibot_description/urdf/axys_rod.stl"/>
            </geometry>
            <material name="axys_rod_material">
                <color rgba="0.61568627450980395466 0.81176470588235294379 0.92941176470588238168 1.0"/>
            </material>
        </visual>
        <collision>
            <origin xyz="0.028708342606703379785 0.013093873839405009707 -0.024199995144406571956" rpy="3.141592653589708739 5.5072761469850945214e-14 0.79586976703608003358" />
            <geometry>
                <mesh filename="package://omnibot_description/urdf/axys_rod.stl"/>
            </geometry>
        </collision>
        <visual>
            <origin xyz="0.025693839153636922196 -0.018315204092976419825 -0.024199999328582841307" rpy="3.1415926535896376848 -6.0602781200459059868e-14 -0.25132764401669138721" />
            <geometry>
                <mesh filename="package://omnibot_description/urdf/axys_rod.stl"/>
            </geometry>
            <material name="axys_rod_material">
                <color rgba="0.61568627450980395466 0.81176470588235294379 0.92941176470588238168 1.0"/>
            </material>
        </visual>
        <collision>
            <origin xyz="0.025693839153636922196 -0.018315204092976419825 -0.024199999328582841307" rpy="3.1415926535896376848 -6.0602781200459059868e-14 -0.25132764401669138721" />
            <geometry>
                <mesh filename="package://omnibot_description/urdf/axys_rod.stl"/>
            </geometry>
        </collision>
        <visual>
            <origin xyz="-1.964215067004160091e-09 -1.7891429830718674765e-10 -0.022199999809269455042" rpy="3.1415926535897229499 7.4942515224149867956e-14 1.0471975511966264971" />
            <geometry>
                <mesh filename="package://omnibot_description/urdf/plate2.stl"/>
            </geometry>
            <material name="plate2_material">
                <color rgba="0.98039215686274505668 0.79607843137254896693 0.26274509803921569651 1.0"/>
            </material>
        </visual>
        <!-- Shapes for plate2 -->
        <collision>
            <origin xyz="-1.9642150199087717088e-09 -1.7891449832634449534e-10 -0.024199999809269456819" rpy="3.1415926535897229499 7.4942515224149867956e-14 1.0471975511966264971" />
            <geometry>
                <cylinder length="0.0030000000000000000625" radius="0.034000000000000002442" />
            </geometry>
        </collision>
        <visual>
            <origin xyz="0.015937773618269389375 0.0042705139175617454206 -0.012000000000003174794" rpy="3.1415926535896292471 -2.3444515713653181886e-14 -2.2147947750392495488e-15" />
            <geometry>
                <mesh filename="package://omnibot_description/urdf/spacer.stl"/>
            </geometry>
            <material name="spacer_material">
                <color rgba="1 0.7568627450980391913 0.054901960784313724728 1.0"/>
            </material>
        </visual>
        <collision>
            <origin xyz="0.015937773618269389375 0.0042705139175617454206 -0.012000000000003174794" rpy="3.1415926535896292471 -2.3444515713653181886e-14 -2.2147947750392495488e-15" />
            <geometry>
                <mesh filename="package://omnibot_description/urdf/spacer.stl"/>
            </geometry>
        </collision>
        <visual>
            <origin xyz="2.0017600573549003407e-11 -1.9338659146272973999e-11 -0.012000000000003147038" rpy="-8.0975201453402400743e-21 -1.8949663385004863385e-18 -1.3571789178431508351e-18" />
            <geometry>
                <mesh filename="package://omnibot_description/urdf/plate1.stl"/>
            </geometry>
            <material name="plate1_material">
                <color rgba="1 0.7568627450980391913 0.054901960784313724728 1.0"/>
            </material>
        </visual>
        <!-- Shapes for plate1 -->
        <collision>
            <origin xyz="2.0017600577621821023e-11 -1.9338659146267797658e-11 -0.010000000000003146997" rpy="-8.0975201453402400743e-21 -1.8949663385004863385e-18 -1.3571789178431508351e-18" />
            <geometry>
                <cylinder length="0.0030000000000000000625" radius="0.034000000000000002442" />
            </geometry>
        </collision>
        <visual>
            <origin xyz="-0.028790909644559475183 0.013178153068649570145 -0.010000000622266511097" rpy="3.1415926535896803173 -1.2723043315105820041e-13 -0.79586931499758128972" />
            <geometry>
                <mesh filename="package://omnibot_description/urdf/axys_rod.stl"/>
            </geometry>
            <material name="axys_rod_material">
                <color rgba="0.61568627450980395466 0.81176470588235294379 0.92941176470588238168 1.0"/>
            </material>
        </visual>
        <collision>
            <origin xyz="-0.028790909644559475183 0.013178153068649570145 -0.010000000622266511097" rpy="3.1415926535896803173 -1.2723043315105820041e-13 -0.79586931499758128972" />
            <geometry>
                <mesh filename="package://omnibot_description/urdf/axys_rod.stl"/>
            </geometry>
        </collision>
        <visual>
            <origin xyz="0.025808116021087221248 0.018344566682610804337 -0.010000000481623472215" rpy="1.4717752522695077532e-15 -2.3269174378083599674e-17 0.25132812119096276104" />
            <geometry>
                <mesh filename="package://omnibot_description/urdf/axys_rod.stl"/>
            </geometry>
            <material name="axys_rod_material">
                <color rgba="0.61568627450980395466 0.81176470588235294379 0.92941176470588238168 1.0"/>
            </material>
        </visual>
        <collision>
            <origin xyz="0.025808116021087221248 0.018344566682610804337 -0.010000000481623472215" rpy="1.4717752522695077532e-15 -2.3269174378083599674e-17 0.25132812119096276104" />
            <geometry>
                <mesh filename="package://omnibot_description/urdf/axys_rod.stl"/>
            </geometry>
        </collision>
        <visual>
            <origin xyz="-0.025693825391885621173 0.018315274927573715197 -0.02419999957345080055" rpy="-4.0037006727892683257e-16 -5.5047058924669506872e-16 -0.25132764401668966636" />
            <geometry>
                <mesh filename="package://omnibot_description/urdf/axys_rod.stl"/>
            </geometry>
            <material name="axys_rod_material">
                <color rgba="0.61568627450980395466 0.81176470588235294379 0.92941176470588238168 1.0"/>
            </material>
        </visual>
        <collision>
            <origin xyz="-0.025693825391885621173 0.018315274927573715197 -0.02419999957345080055" rpy="-4.0037006727892683257e-16 -5.5047058924669506872e-16 -0.25132764401668966636" />
            <geometry>
                <mesh filename="package://omnibot_description/urdf/axys_rod.stl"/>
            </geometry>
        </collision>
        <visual>
            <origin xyz="-0.015937773364186821889 -0.0042705132347593648123 -0.01200000000000313316" rpy="3.1415926535896292471 -2.3444515713653181886e-14 -2.2147947750392495488e-15" />
            <geometry>
                <mesh filename="package://omnibot_description/urdf/spacer.stl"/>
            </geometry>
            <material name="spacer_material">
                <color rgba="1 0.7568627450980391913 0.054901960784313724728 1.0"/>
            </material>
        </visual>
        <collision>
            <origin xyz="-0.015937773364186821889 -0.0042705132347593648123 -0.01200000000000313316" rpy="3.1415926535896292471 -2.3444515713653181886e-14 -2.2147947750392495488e-15" />
            <geometry>
                <mesh filename="package://omnibot_description/urdf/spacer.stl"/>
            </geometry>
        </collision>
        <visual>
            <origin xyz="0.028790823204505270466 -0.013178235601434447333 -0.010000000285350058027" rpy="-4.2898894479494871054e-15 -4.681811561625178854e-15 -0.79586931499757906927" />
            <geometry>
                <mesh filename="package://omnibot_description/urdf/axys_rod.stl"/>
            </geometry>
            <material name="axys_rod_material">
                <color rgba="0.61568627450980395466 0.81176470588235294379 0.92941176470588238168 1.0"/>
            </material>
        </visual>
        <collision>
            <origin xyz="0.028790823204505270466 -0.013178235601434447333 -0.010000000285350058027" rpy="-4.2898894479494871054e-15 -4.681811561625178854e-15 -0.79586931499757906927" />
            <geometry>
                <mesh filename="package://omnibot_description/urdf/axys_rod.stl"/>
            </geometry>
        </collision>
        <visual>
            <origin xyz="0.0030145071180057879043 0.031409130275873553551 -0.024199999101467986606" rpy="3.1415926535897829019 2.6543635029429278118e-14 1.8430678811939189554" />
            <geometry>
                <mesh filename="package://omnibot_description/urdf/axys_rod.stl"/>
            </geometry>
            <material name="axys_rod_material">
                <color rgba="0.61568627450980395466 0.81176470588235294379 0.92941176470588238168 1.0"/>
            </material>
        </visual>
        <collision>
            <origin xyz="0.0030145071180057879043 0.031409130275873553551 -0.024199999101467986606" rpy="3.1415926535897829019 2.6543635029429278118e-14 1.8430678811939189554" />
            <geometry>
                <mesh filename="package://omnibot_description/urdf/axys_rod.stl"/>
            </geometry>
        </collision>
        <visual>
            <origin xyz="-0.028708344080533642478 -0.013093882512645066418 -0.0241999984182880018" rpy="5.7941372090396261656e-14 -3.4961474371000560903e-14 0.79586976703608214301" />
            <geometry>
                <mesh filename="package://omnibot_description/urdf/axys_rod.stl"/>
            </geometry>
            <material name="axys_rod_material">
                <color rgba="0.61568627450980395466 0.81176470588235294379 0.92941176470588238168 1.0"/>
            </material>
        </visual>
        <collision>
            <origin xyz="-0.028708344080533642478 -0.013093882512645066418 -0.0241999984182880018" rpy="5.7941372090396261656e-14 -3.4961474371000560903e-14 0.79586976703608214301" />
            <geometry>
                <mesh filename="package://omnibot_description/urdf/axys_rod.stl"/>
            </geometry>
        </collision>
        <inertial>
            <origin xyz="-9.4588917159855837068e-06 -8.8415141497942513005e-06 -0.015131125342709179221" rpy="0 0 0"/>
            <mass value="0.019223052335254620093" />
            <inertia ixx="5.3992629534639384676e-06" ixy="-7.3246329002134650625e-08"  ixz="-1.2642889980049264682e-09" iyy="5.655797917650546803e-06" iyz="1.9098649291001876558e-09" izz="8.6846392930512293531e-06" />
        </inertial>
    </link>

    <link name="roller_13">
        <visual>
            <origin xyz="0 0 1.7347234759768070944e-18" rpy="2.6381075324365411321e-17 -5.7075779819544149807e-19 3.7136266349427270889e-19" />
            <geometry>
                <mesh filename="package://omnibot_description/urdf/roller.stl"/>
            </geometry>
            <material name="roller_material">
                <color rgba="0.098039215686274508443 0.098039215686274508443 0.098039215686274508443 1.0"/>
            </material>
        </visual>
        <!-- Shapes for roller -->
        <collision>
            <origin xyz="0 0 1.7347234759768070944e-18" rpy="2.6381075324365411321e-17 -5.7075779819544149807e-19 3.7136266349427270889e-19" />
            <geometry>
                <sphere radius="0.007700000000000000247" />
            </geometry>
        </collision>
        <inertial>
            <origin xyz="4.0756121962864205179e-11 8.4957103194350890961e-11 2.4283850775576140801e-11" rpy="0 0 0"/>
            <mass value="0.0037899803393768708749" />
            <inertia ixx="1.8303635244743848899e-07" ixy="4.2716080870125931727e-16"  ixz="-1.7514569836935301974e-15" iyy="1.830363607521377626e-07" iyz="-3.3429143047818757542e-15" izz="9.809706208063898724e-08" />
        </inertial>
    </link>

    <joint name="roller1_1" type="revolute">
        <origin xyz="0.020681564833506995565 -0.021119421197577783328 -0.010000000285350016394" rpy="-0.7749270117973218186 1.5707963267948548136 0" />
        <parent link="wheel_2" />
        <child link="roller_13" />
        <axis xyz="0 0 1"/>
        <limit effort="1" velocity="20" />
        <joint_properties friction="0.0"/>
    </joint>

    <link name="roller_14">
        <visual>
            <origin xyz="0 -1.3877787807814456755e-17 -1.7347234759768070944e-18" rpy="-1.1202669234443344491e-18 -1.1834155083362201496e-17 4.8544730945660298507e-18" />
            <geometry>
                <mesh filename="package://omnibot_description/urdf/roller.stl"/>
            </geometry>
            <material name="roller_material">
                <color rgba="0.098039215686274508443 0.098039215686274508443 0.098039215686274508443 1.0"/>
            </material>
        </visual>
        <!-- Shapes for roller -->
        <collision>
            <origin xyz="0 -1.3877787807814456755e-17 -1.7347234759768070944e-18" rpy="-1.1202669234443344491e-18 -1.1834155083362201496e-17 4.8544730945660298507e-18" />
            <geometry>
                <sphere radius="0.007700000000000000247" />
            </geometry>
        </collision>
        <inertial>
            <origin xyz="4.0756121962864211641e-11 8.4957089316563083146e-11 2.4283847306129179153e-11" rpy="0 0 0"/>
            <mass value="0.0037899803393768708749" />
            <inertia ixx="1.8303635244743854193e-07" ixy="4.2716081162000399094e-16"  ixz="-1.7514569764370523491e-15" iyy="1.8303636075213770966e-07" iyz="-3.3429143065183999981e-15" izz="9.80970620806389343e-08" />
        </inertial>
    </link>

    <joint name="roller1_2" type="revolute">
        <origin xyz="-0.0082858436691602352364 -0.028375035936991754859 -0.010000003715207331223" rpy="-1.5707963267948545916 -0.039422984638902945631 1.2985250346548480316" />
        <parent link="wheel_2" />
        <child link="roller_14" />
        <axis xyz="0 0 1"/>
        <limit effort="1" velocity="20" />
        <joint_properties friction="0.0"/>
    </joint>

    <link name="roller_15">
        <visual>
            <origin xyz="-1.3877787807814456755e-17 0 0" rpy="-5.5121975380512306723e-18 3.5354151599519008653e-18 3.3430108168877011178e-17" />
            <geometry>
                <mesh filename="package://omnibot_description/urdf/roller.stl"/>
            </geometry>
            <material name="roller_material">
                <color rgba="0.098039215686274508443 0.098039215686274508443 0.098039215686274508443 1.0"/>
            </material>
        </visual>
        <!-- Shapes for roller -->
        <collision>
            <origin xyz="-1.3877787807814456755e-17 0 0" rpy="-5.5121975380512306723e-18 3.5354151599519008653e-18 3.3430108168877011178e-17" />
            <geometry>
                <sphere radius="0.007700000000000000247" />
            </geometry>
        </collision>
        <inertial>
            <origin xyz="4.0756108085076403826e-11 8.4957103194350890961e-11 2.428384904085265513e-11" rpy="0 0 0"/>
            <mass value="0.0037899803393768708749" />
            <inertia ixx="1.8303635244743848899e-07" ixy="4.2716082681537012459e-16"  ixz="-1.7514569838598017631e-15" iyy="1.830363607521377626e-07" iyz="-3.342914307355667775e-15" izz="9.80970620806389343e-08" />
        </inertial>
    </link>

    <joint name="roller1_3" type="revolute">
        <origin xyz="0.028630754033683800119 0.0073511498047768263076 -0.010000000481623513848" rpy="1.5707963267948983344 0.47506888631432148129 0.2513281211909595414" />
        <parent link="wheel_2" />
        <child link="roller_15" />
        <axis xyz="0 0 1"/>
        <limit effort="1" velocity="20" />
        <joint_properties friction="0.0"/>
    </joint>

    <link name="roller_16">
        <visual>
            <origin xyz="0 -1.3877787807814456755e-17 0" rpy="-1.1202669234443344491e-18 -1.1834155083362201496e-17 4.8544730945660298507e-18" />
            <geometry>
                <mesh filename="package://omnibot_description/urdf/roller.stl"/>
            </geometry>
            <material name="roller_material">
                <color rgba="0.098039215686274508443 0.098039215686274508443 0.098039215686274508443 1.0"/>
            </material>
        </visual>
        <!-- Shapes for roller -->
        <collision>
            <origin xyz="0 -1.3877787807814456755e-17 0" rpy="-1.1202669234443344491e-18 -1.1834155083362201496e-17 4.8544730945660298507e-18" />
            <geometry>
                <sphere radius="0.007700000000000000247" />
            </geometry>
        </collision>
        <inertial>
            <origin xyz="4.0756121962864211641e-11 8.4957089316563083146e-11 2.428384904085265513e-11" rpy="0 0 0"/>
            <mass value="0.0037899803393768708749" />
            <inertia ixx="1.8303635244743854193e-07" ixy="4.2716081162000399094e-16"  ixz="-1.7514569764370523491e-15" iyy="1.8303636075213770966e-07" iyz="-3.3429143065183999981e-15" izz="9.80970620806389343e-08" />
        </inertial>
    </link>

    <joint name="roller1_4" type="revolute">
        <origin xyz="0.0079490519369564867358 0.028470515462357379871 -0.009999997062760127009" rpy="-1.5707963267948545916 -0.039422984638902945631 1.2985250346548480316" />
        <parent link="wheel_2" />
        <child link="roller_16" />
        <axis xyz="0 0 1"/>
        <limit effort="1" velocity="20" />
        <joint_properties friction="0.0"/>
    </joint>

    <link name="roller_17">
        <visual>
            <origin xyz="-6.9388939039072283776e-18 0 -8.6736173798840354721e-19" rpy="-3.6253444694832495679e-18 -6.4300198763429314923e-17 7.5517975809926424682e-18" />
            <geometry>
                <mesh filename="package://omnibot_description/urdf/roller.stl"/>
            </geometry>
            <material name="roller_material">
                <color rgba="0.098039215686274508443 0.098039215686274508443 0.098039215686274508443 1.0"/>
            </material>
        </visual>
        <!-- Shapes for roller -->
        <collision>
            <origin xyz="-6.9388939039072283776e-18 0 -8.6736173798840354721e-19" rpy="-3.6253444694832495679e-18 -6.4300198763429314923e-17 7.5517975809926424682e-18" />
            <geometry>
                <sphere radius="0.007700000000000000247" />
            </geometry>
        </collision>
        <inertial>
            <origin xyz="4.0756115023970307734e-11 8.495710319435091681e-11 2.4283848173490920373e-11" rpy="0 0 0"/>
            <mass value="0.0037899803393768708749" />
            <inertia ixx="1.8303635244743854193e-07" ixy="4.2716081054278646961e-16"  ixz="-1.7514569706762102064e-15" iyy="1.8303636075213792142e-07" iyz="-3.3429143065103835935e-15" izz="9.80970620806389343e-08" />
        </inertial>
    </link>

    <joint name="roller1_5" type="revolute">
        <origin xyz="-0.0079173874319012869927 0.028356888222937384064 -0.024199999101468097629" rpy="-1.5707963267948861219 0.03562903164307405085 -1.2985247723958699417" />
        <parent link="wheel_2" />
        <child link="roller_17" />
        <axis xyz="0 0 1"/>
        <limit effort="1" velocity="20" />
        <joint_properties friction="0.0"/>
    </joint>

    <link name="roller_18">
        <visual>
            <origin xyz="1.7347234759768070944e-18 -1.3877787807814456755e-17 0" rpy="-1.0656737069284046429e-17 -2.4517658101723973321e-17 2.3642205129207112737e-17" />
            <geometry>
                <mesh filename="package://omnibot_description/urdf/roller.stl"/>
            </geometry>
            <material name="roller_material">
                <color rgba="0.098039215686274508443 0.098039215686274508443 0.098039215686274508443 1.0"/>
            </material>
        </visual>
        <!-- Shapes for roller -->
        <collision>
            <origin xyz="1.7347234759768070944e-18 -1.3877787807814456755e-17 0" rpy="-1.0656737069284046429e-17 -2.4517658101723973321e-17 2.3642205129207112737e-17" />
            <geometry>
                <sphere radius="0.007700000000000000247" />
            </geometry>
        </collision>
        <inertial>
            <origin xyz="4.0756123697587681155e-11 8.4957089316563096071e-11 2.428384904085265513e-11" rpy="0 0 0"/>
            <mass value="0.0037899803393768708749" />
            <inertia ixx="1.8303635244743854193e-07" ixy="4.2716080107737462991e-16"  ixz="-1.7514569737809348042e-15" iyy="1.8303636075213781554e-07" iyz="-3.342914309274934803e-15" izz="9.80970620806389343e-08" />
        </inertial>
    </link>

    <joint name="roller1_6" type="revolute">
        <origin xyz="-0.020681651273561196813 0.021119338664792892263 -0.010000000622267801731" rpy="-1.5707963267947777641 -0.32376586976593907385 2.3457233385921831825" />
        <parent link="wheel_2" />
        <child link="roller_18" />
        <axis xyz="0 0 1"/>
        <limit effort="1" velocity="20" />
        <joint_properties friction="0.0"/>
    </joint>

    <link name="roller_19">
        <visual>
            <origin xyz="-1.3877787807814456755e-17 1.3877787807814456755e-17 -1.7347234759768070944e-18" rpy="-7.0809491836362829046e-18 -1.0252765330516707878e-17 -8.282552874394391317e-17" />
            <geometry>
                <mesh filename="package://omnibot_description/urdf/roller.stl"/>
            </geometry>
            <material name="roller_material">
                <color rgba="0.098039215686274508443 0.098039215686274508443 0.098039215686274508443 1.0"/>
            </material>
        </visual>
        <!-- Shapes for roller -->
        <collision>
            <origin xyz="-1.3877787807814456755e-17 1.3877787807814456755e-17 -1.7347234759768070944e-18" rpy="-7.0809491836362829046e-18 -1.0252765330516707878e-17 -8.282552874394391317e-17" />
            <geometry>
                <sphere radius="0.007700000000000000247" />
            </geometry>
        </collision>
        <inertial>
            <origin xyz="4.0756108085076410289e-11 8.49571170721387117e-11 2.4283847306129179153e-11" rpy="0 0 0"/>
            <mass value="0.0037899803393768708749" />
            <inertia ixx="1.8303635244743864781e-07" ixy="4.2716078804164237882e-16"  ixz="-1.7514569845453351031e-15" iyy="1.8303636075213781554e-07" iyz="-3.3429143071976751073e-15" izz="9.80970620806389343e-08" />
        </inertial>
    </link>

    <joint name="roller1_7" type="revolute">
        <origin xyz="-0.028516458158706171205 0.0073218567028507756944 -0.024199999573450814427" rpy="-1.5707963267948970021 -0.49987551737802066176 -0.25132764401668405974" />
        <parent link="wheel_2" />
        <child link="roller_19" />
        <axis xyz="0 0 1"/>
        <limit effort="1" velocity="20" />
        <joint_properties friction="0.0"/>
    </joint>

    <link name="roller_20">
        <visual>
            <origin xyz="1.0408340855860842566e-17 -1.3877787807814456755e-17 0" rpy="5.9922109016072439774e-19 8.635001293765755397e-18 -4.2710620983530114615e-17" />
            <geometry>
                <mesh filename="package://omnibot_description/urdf/roller.stl"/>
            </geometry>
            <material name="roller_material">
                <color rgba="0.098039215686274508443 0.098039215686274508443 0.098039215686274508443 1.0"/>
            </material>
        </visual>
        <!-- Shapes for roller -->
        <collision>
            <origin xyz="1.0408340855860842566e-17 -1.3877787807814456755e-17 0" rpy="5.9922109016072439774e-19 8.635001293765755397e-18 -4.2710620983530114615e-17" />
            <geometry>
                <sphere radius="0.007700000000000000247" />
            </geometry>
        </collision>
        <inertial>
            <origin xyz="4.0756132371205054577e-11 8.4957089316563096071e-11 2.428384904085265513e-11" rpy="0 0 0"/>
            <mass value="0.0037899803393768708749" />
            <inertia ixx="1.8303635244743848899e-07" ixy="4.2716079294772454285e-16"  ixz="-1.7514569867289460678e-15" iyy="1.8303636075213781554e-07" iyz="-3.342914303817672369e-15" izz="9.80970620806389343e-08" />
        </inertial>
    </link>

    <joint name="roller1_8" type="revolute">
        <origin xyz="-0.028516433936171599328 -0.0073217973661802958352 -0.010000001453653845074" rpy="1.5707963267947118169 0.475068886313615657 0.25132812119087311054" />
        <parent link="wheel_2" />
        <child link="roller_20" />
        <axis xyz="0 0 1"/>
        <limit effort="1" velocity="20" />
        <joint_properties friction="0.0"/>
    </joint>

    <link name="roller_21">
        <visual>
            <origin xyz="6.9388939039072283776e-18 0 -1.7347234759768070944e-18" rpy="2.1404042137452075338e-17 7.1055133128053132523e-18 -1.7988082966273498118e-17" />
            <geometry>
                <mesh filename="package://omnibot_description/urdf/roller.stl"/>
            </geometry>
            <material name="roller_material">
                <color rgba="0.098039215686274508443 0.098039215686274508443 0.098039215686274508443 1.0"/>
            </material>
        </visual>
        <!-- Shapes for roller -->
        <collision>
            <origin xyz="6.9388939039072283776e-18 0 -1.7347234759768070944e-18" rpy="2.1404042137452075338e-17 7.1055133128053132523e-18 -1.7988082966273498118e-17" />
            <geometry>
                <sphere radius="0.007700000000000000247" />
            </geometry>
        </collision>
        <inertial>
            <origin xyz="4.0756128901758115548e-11 8.4957103194350903886e-11 2.4283847306129179153e-11" rpy="0 0 0"/>
            <mass value="0.0037899803393768708749" />
            <inertia ixx="1.8303635244743848899e-07" ixy="4.2716080905926914657e-16"  ixz="-1.7514569718066853544e-15" iyy="1.8303636075213781554e-07" iyz="-3.3429143091571077771e-15" izz="9.8097062080638907831e-08" />
        </inertial>
    </link>

    <joint name="roller1_9" type="revolute">
        <origin xyz="-0.020599082119814537961 -0.021035064443090573799 -0.024199998418288681812" rpy="-1.5707963267949580644 0.33636312788314187694 -2.3457228865537405049" />
        <parent link="wheel_2" />
        <child link="roller_21" />
        <axis xyz="0 0 1"/>
        <limit effort="1" velocity="20" />
        <joint_properties friction="0.0"/>
    </joint>

    <link name="roller_22">
        <visual>
            <origin xyz="3.4694469519536141888e-18 0 -8.6736173798840354721e-19" rpy="2.4004055127112631687e-18 -1.0459116250148264473e-17 -1.013087807607497131e-17" />
            <geometry>
                <mesh filename="package://omnibot_description/urdf/roller.stl"/>
            </geometry>
            <material name="roller_material">
                <color rgba="0.098039215686274508443 0.098039215686274508443 0.098039215686274508443 1.0"/>
            </material>
        </visual>
        <!-- Shapes for roller -->
        <collision>
            <origin xyz="3.4694469519536141888e-18 0 -8.6736173798840354721e-19" rpy="2.4004055127112631687e-18 -1.0459116250148264473e-17 -1.013087807607497131e-17" />
            <geometry>
                <sphere radius="0.007700000000000000247" />
            </geometry>
        </collision>
        <inertial>
            <origin xyz="4.0756125432311157132e-11 8.495710319435091681e-11 2.4283848173490917142e-11" rpy="0 0 0"/>
            <mass value="0.0037899803393768708749" />
            <inertia ixx="1.8303635244743848899e-07" ixy="4.2716080575711430852e-16"  ixz="-1.7514569793892820481e-15" iyy="1.8303636075213792142e-07" iyz="-3.3429143053301037122e-15" izz="9.80970620806389343e-08" />
        </inertial>
    </link>

    <joint name="roller1_10" type="revolute">
        <origin xyz="0.0079173979793252698134 -0.028356884977343323195 -0.024199999508977318441" rpy="-1.5707963267949074382 -0.035629031643076292113 1.8430678811939233963" />
        <parent link="wheel_2" />
        <child link="roller_22" />
        <axis xyz="0 0 1"/>
        <limit effort="1" velocity="20" />
        <joint_properties friction="0.0"/>
    </joint>

    <link name="roller_23">
        <visual>
            <origin xyz="-3.4694469519536141888e-18 1.3877787807814456755e-17 1.7347234759768070944e-18" rpy="2.7816778514036671498e-18 -3.1491216315564483362e-17 -4.9789190131121355372e-17" />
            <geometry>
                <mesh filename="package://omnibot_description/urdf/roller.stl"/>
            </geometry>
            <material name="roller_material">
                <color rgba="0.098039215686274508443 0.098039215686274508443 0.098039215686274508443 1.0"/>
            </material>
        </visual>
        <!-- Shapes for roller -->
        <collision>
            <origin xyz="-3.4694469519536141888e-18 1.3877787807814456755e-17 1.7347234759768070944e-18" rpy="2.7816778514036671498e-18 -3.1491216315564483362e-17 -4.9789190131121355372e-17" />
            <geometry>
                <sphere radius="0.007700000000000000247" />
            </geometry>
        </collision>
        <inertial>
            <origin xyz="4.075611849341726615e-11 8.49571170721387117e-11 2.4283850775576127876e-11" rpy="0 0 0"/>
            <mass value="0.0037899803393768708749" />
            <inertia ixx="1.8303635244743854193e-07" ixy="4.2716081292559955466e-16"  ixz="-1.7514569738614319459e-15" iyy="1.8303636075213781554e-07" iyz="-3.3429143051088451888e-15" izz="9.8097062080638907831e-08" />
        </inertial>
    </link>

    <joint name="roller1_11" type="revolute">
        <origin xyz="0.028516471920457482636 -0.007321785868253466445 -0.024199999328584589908" rpy="-1.5707963267950737496 -0.49987551737868846091 -0.25132764401660151465" />
        <parent link="wheel_2" />
        <child link="roller_23" />
        <axis xyz="0 0 1"/>
        <limit effort="1" velocity="20" />
        <joint_properties friction="0.0"/>
    </joint>

    <link name="roller_24">
        <visual>
            <origin xyz="4.336808689942017736e-19 -1.3877787807814456755e-17 -1.7347234759768070944e-18" rpy="-1.9247068053441299646e-18 -5.3000383419476060054e-17 -6.0582161742732488833e-18" />
            <geometry>
                <mesh filename="package://omnibot_description/urdf/roller.stl"/>
            </geometry>
            <material name="roller_material">
                <color rgba="0.098039215686274508443 0.098039215686274508443 0.098039215686274508443 1.0"/>
            </material>
        </visual>
        <!-- Shapes for roller -->
        <collision>
            <origin xyz="4.336808689942017736e-19 -1.3877787807814456755e-17 -1.7347234759768070944e-18" rpy="-1.9247068053441299646e-18 -5.3000383419476060054e-17 -6.0582161742732488833e-18" />
            <geometry>
                <sphere radius="0.007700000000000000247" />
            </geometry>
        </collision>
        <inertial>
            <origin xyz="4.0756122396545080635e-11 8.4957089316563083146e-11 2.4283847306129179153e-11" rpy="0 0 0"/>
            <mass value="0.0037899803393768708749" />
            <inertia ixx="1.8303635244743854193e-07" ixy="4.2716080088234898565e-16"  ixz="-1.7514569789260672633e-15" iyy="1.830363607521377626e-07" iyz="-3.342914315767449774e-15" izz="9.8097062080638907831e-08" />
        </inertial>
    </link>

    <joint name="roller1_" type="revolute">
        <origin xyz="0.020599080645984285676 0.021035055769850537905 -0.024199995144407515646" rpy="-1.570796326794807074 0.3363631278837400651 -2.345722886553691211" />
        <parent link="wheel_2" />
        <child link="roller_24" />
        <axis xyz="0 0 1"/>
        <limit effort="1" velocity="20" />
        <joint_properties friction="0.0"/>
    </joint>

    <joint name="wheel1" type="revolute">
        <origin xyz="-3.9587095435201457741e-17 0.015229328657860325552 2.9999999999558157882e-05" rpy="3.141592653589793116 -6.6889720988138117189e-17 -3.1336648471671013638" />
        <parent link="motor_2" />
        <child link="wheel_2" />
        <axis xyz="0 0 1"/>
        <limit effort="1" velocity="20" />
        <joint_properties friction="0.0"/>
    </joint>

    <joint name="motor2" type="fixed">
        <origin xyz="-0.0011464255543250467632 0.084303028851025418877 -1.561251128379126385e-17" rpy="-1.57079632679489678 2.4978401230941900222e-18 0.013598027361811270558" />
        <parent link="base" />
        <child link="motor_2" />
        <axis xyz="0 0 1"/>
        <limit effort="1" velocity="20" />
        <joint_properties friction="0.0"/>
    </joint>

    <link name="motor_3">
        <visual>
            <origin xyz="7.6908859669402865442e-18 0.01522932865786030994 -0.057370000000000004325" rpy="-2.4651903288156618919e-32 -7.8754369550006080045e-17 0" />
            <geometry>
                <mesh filename="package://omnibot_description/urdf/part_1.stl"/>
            </geometry>
            <material name="part_1_material">
                <color rgba="0.90196078431372550543 0.91764705882352937127 0.92941176470588238168 1.0"/>
            </material>
        </visual>
        <collision>
            <origin xyz="7.6908859669402865442e-18 0.01522932865786030994 -0.057370000000000004325" rpy="-2.4651903288156618919e-32 -7.8754369550006080045e-17 0" />
            <geometry>
                <mesh filename="package://omnibot_description/urdf/part_1.stl"/>
            </geometry>
        </collision>
        <inertial>
            <origin xyz="-2.0988305528127929092e-06 0.01505037758017026446 -0.021659280060218923103" rpy="0 0 0"/>
            <mass value="0.1286049482749511419" />
            <inertia ixx="4.6506247208995554765e-05" ixy="1.6921131916578386978e-09"  ixz="-3.4608427741355589014e-09" iyy="4.6246527094885937542e-05" iyz="1.0074294037198131716e-06" izz="1.0661244977444005866e-05" />
        </inertial>
    </link>

    <link name="wheel_3">
        <visual>
            <origin xyz="0.018849292529230045334 -0.02530464292440212648 -0.024199999508976388629" rpy="3.1415926535897922278 -5.9329090903087851725e-16 1.8430678811938723261" />
            <geometry>
                <mesh filename="package://omnibot_description/urdf/axys_rod.stl"/>
            </geometry>
            <material name="axys_rod_material">
                <color rgba="0.61568627450980395466 0.81176470588235294379 0.92941176470588238168 1.0"/>
            </material>
        </visual>
        <collision>
            <origin xyz="0.018849292529230045334 -0.02530464292440212648 -0.024199999508976388629" rpy="3.1415926535897922278 -5.9329090903087851725e-16 1.8430678811938723261" />
            <geometry>
                <mesh filename="package://omnibot_description/urdf/axys_rod.stl"/>
            </geometry>
        </collision>
        <visual>
            <origin xyz="-0.0029828434134273589667 0.031522754648300461977 -0.0099999970627584339189" rpy="2.3919443049460285885e-16 -1.0692622008545688203e-15 1.2985250346548162792" />
            <geometry>
                <mesh filename="package://omnibot_description/urdf/axys_rod.stl"/>
            </geometry>
            <material name="axys_rod_material">
                <color rgba="0.61568627450980395466 0.81176470588235294379 0.92941176470588238168 1.0"/>
            </material>
        </visual>
        <collision>
            <origin xyz="-0.0029828434134273589667 0.031522754648300461977 -0.0099999970627584339189" rpy="2.3919443049460285885e-16 -1.0692622008545688203e-15 1.2985250346548162792" />
            <geometry>
                <mesh filename="package://omnibot_description/urdf/axys_rod.stl"/>
            </geometry>
        </collision>
        <visual>
            <origin xyz="-0.019217739019543454704 -0.025322796751039211571 -0.010000003715208094501" rpy="2.3919443049460285885e-16 -1.0692622008545688203e-15 1.2985250346548162792" />
            <geometry>
                <mesh filename="package://omnibot_description/urdf/axys_rod.stl"/>
            </geometry>
            <material name="axys_rod_material">
                <color rgba="0.61568627450980395466 0.81176470588235294379 0.92941176470588238168 1.0"/>
            </material>
        </visual>
        <collision>
            <origin xyz="-0.019217739019543454704 -0.025322796751039211571 -0.010000003715208094501" rpy="2.3919443049460285885e-16 -1.0692622008545688203e-15 1.2985250346548162792" />
            <geometry>
                <mesh filename="package://omnibot_description/urdf/axys_rod.stl"/>
            </geometry>
        </collision>
        <visual>
            <origin xyz="-0.0256937959235729943 -0.018315214244011369937 -0.010000001453652873629" rpy="-3.1415926535897922278 -5.6242178490559706487e-16 0.25132812119095593317" />
            <geometry>
                <mesh filename="package://omnibot_description/urdf/axys_rod.stl"/>
            </geometry>
            <material name="axys_rod_material">
                <color rgba="0.61568627450980395466 0.81176470588235294379 0.92941176470588238168 1.0"/>
            </material>
        </visual>
        <collision>
            <origin xyz="-0.0256937959235729943 -0.018315214244011369937 -0.010000001453652873629" rpy="-3.1415926535897922278 -5.6242178490559706487e-16 0.25132812119095593317" />
            <geometry>
                <mesh filename="package://omnibot_description/urdf/axys_rod.stl"/>
            </geometry>
        </collision>
        <visual>
            <origin xyz="0.028708342606700673616 0.013093873839403408557 -0.024199995144404323755" rpy="-3.1415926535897926719 -4.0019020663288617633e-16 0.79586976703605805117" />
            <geometry>
                <mesh filename="package://omnibot_description/urdf/axys_rod.stl"/>
            </geometry>
            <material name="axys_rod_material">
                <color rgba="0.61568627450980395466 0.81176470588235294379 0.92941176470588238168 1.0"/>
            </material>
        </visual>
        <collision>
            <origin xyz="0.028708342606700673616 0.013093873839403408557 -0.024199995144404323755" rpy="-3.1415926535897926719 -4.0019020663288617633e-16 0.79586976703605805117" />
            <geometry>
                <mesh filename="package://omnibot_description/urdf/axys_rod.stl"/>
            </geometry>
        </collision>
        <visual>
            <origin xyz="0.025693839153634018269 -0.018315204092972516697 -0.024199999328581897617" rpy="-3.1415926535897926719 2.536147399332963651e-16 -0.25132764401668150622" />
            <geometry>
                <mesh filename="package://omnibot_description/urdf/axys_rod.stl"/>
            </geometry>
            <material name="axys_rod_material">
                <color rgba="0.61568627450980395466 0.81176470588235294379 0.92941176470588238168 1.0"/>
            </material>
        </visual>
        <collision>
            <origin xyz="0.025693839153634018269 -0.018315204092972516697 -0.024199999328581897617" rpy="-3.1415926535897926719 2.536147399332963651e-16 -0.25132764401668150622" />
            <geometry>
                <mesh filename="package://omnibot_description/urdf/axys_rod.stl"/>
            </geometry>
        </collision>
        <visual>
            <origin xyz="-1.9642151837320764862e-09 -1.7891379870682566633e-10 -0.022199999809267817463" rpy="-3.1415926535897926719 -3.5759385660046339317e-16 1.0471975511965982975" />
            <geometry>
                <mesh filename="package://omnibot_description/urdf/plate2.stl"/>
            </geometry>
            <material name="plate2_material">
                <color rgba="0.98039215686274505668 0.79607843137254896693 0.26274509803921569651 1.0"/>
            </material>
        </visual>
        <!-- Shapes for plate2 -->
        <collision>
            <origin xyz="-1.9642151837092111461e-09 -1.7891379861967707062e-10 -0.02419999980926781924" rpy="-3.1415926535897926719 -3.5759385660046339317e-16 1.0471975511965982975" />
            <geometry>
                <cylinder length="0.0030000000000000000625" radius="0.034000000000000002442" />
            </geometry>
        </collision>
        <visual>
            <origin xyz="0.015937773618267953024 0.0042705139175611122465 -0.012000000000002980505" rpy="3.141592653589793116 -7.7644984175797900276e-18 2.454092347805215957e-17" />
            <geometry>
                <mesh filename="package://omnibot_description/urdf/spacer.stl"/>
            </geometry>
            <material name="spacer_material">
                <color rgba="1 0.7568627450980391913 0.054901960784313724728 1.0"/>
            </material>
        </visual>
        <collision>
            <origin xyz="0.015937773618267953024 0.0042705139175611122465 -0.012000000000002980505" rpy="3.141592653589793116 -7.7644984175797900276e-18 2.454092347805215957e-17" />
            <geometry>
                <mesh filename="package://omnibot_description/urdf/spacer.stl"/>
            </geometry>
        </collision>
        <visual>
            <origin xyz="2.0017589148768610841e-11 -1.9338662615719925952e-11 -0.012000000000003160916" rpy="-1.2454419035563118145e-17 -7.7644984175797900276e-18 2.454092347805215957e-17" />
            <geometry>
                <mesh filename="package://omnibot_description/urdf/plate1.stl"/>
            </geometry>
            <material name="plate1_material">
                <color rgba="1 0.7568627450980391913 0.054901960784313724728 1.0"/>
            </material>
        </visual>
        <!-- Shapes for plate1 -->
        <collision>
            <origin xyz="2.0017589125903358e-11 -1.9338662702868524896e-11 -0.010000000000003160874" rpy="-1.2454419035563118145e-17 -7.7644984175797900276e-18 2.454092347805215957e-17" />
            <geometry>
                <cylinder length="0.0030000000000000000625" radius="0.034000000000000002442" />
            </geometry>
        </collision>
        <visual>
            <origin xyz="-0.028790909644556446356 0.01317815306864731327 -0.010000000622265844963" rpy="-3.1415926535897922278 7.2498576146944507703e-16 -0.79586931499755364516" />
            <geometry>
                <mesh filename="package://omnibot_description/urdf/axys_rod.stl"/>
            </geometry>
            <material name="axys_rod_material">
                <color rgba="0.61568627450980395466 0.81176470588235294379 0.92941176470588238168 1.0"/>
            </material>
        </visual>
        <collision>
            <origin xyz="-0.028790909644556446356 0.01317815306864731327 -0.010000000622265844963" rpy="-3.1415926535897922278 7.2498576146944507703e-16 -0.79586931499755364516" />
            <geometry>
                <mesh filename="package://omnibot_description/urdf/axys_rod.stl"/>
            </geometry>
        </collision>
        <visual>
            <origin xyz="0.025808116021085236724 0.018344566682607671426 -0.010000000481623388948" rpy="1.1236260499216621671e-15 -5.6242178490559706487e-16 0.25132812119095593317" />
            <geometry>
                <mesh filename="package://omnibot_description/urdf/axys_rod.stl"/>
            </geometry>
            <material name="axys_rod_material">
                <color rgba="0.61568627450980395466 0.81176470588235294379 0.92941176470588238168 1.0"/>
            </material>
        </visual>
        <collision>
            <origin xyz="0.025808116021085236724 0.018344566682607671426 -0.010000000481623388948" rpy="1.1236260499216621671e-15 -5.6242178490559706487e-16 0.25132812119095593317" />
            <geometry>
                <mesh filename="package://omnibot_description/urdf/axys_rod.stl"/>
            </geometry>
        </collision>
        <visual>
            <origin xyz="-0.025693825391882980924 0.01831527492757106107 -0.024199999573447900092" rpy="6.3352770215469594043e-16 3.1433490143144370466e-16 -0.25132764401668117316" />
            <geometry>
                <mesh filename="package://omnibot_description/urdf/axys_rod.stl"/>
            </geometry>
            <material name="axys_rod_material">
                <color rgba="0.61568627450980395466 0.81176470588235294379 0.92941176470588238168 1.0"/>
            </material>
        </visual>
        <collision>
            <origin xyz="-0.025693825391882980924 0.01831527492757106107 -0.024199999573447900092" rpy="6.3352770215469594043e-16 3.1433490143144370466e-16 -0.25132764401668117316" />
            <geometry>
                <mesh filename="package://omnibot_description/urdf/axys_rod.stl"/>
            </geometry>
        </collision>
        <visual>
            <origin xyz="-0.015937773364185392477 -0.0042705132347587246994 -0.012000000000003285816" rpy="3.141592653589793116 -7.7644984175797900276e-18 2.454092347805215957e-17" />
            <geometry>
                <mesh filename="package://omnibot_description/urdf/spacer.stl"/>
            </geometry>
            <material name="spacer_material">
                <color rgba="1 0.7568627450980391913 0.054901960784313724728 1.0"/>
            </material>
        </visual>
        <collision>
            <origin xyz="-0.015937773364185392477 -0.0042705132347587246994 -0.012000000000003285816" rpy="3.141592653589793116 -7.7644984175797900276e-18 2.454092347805215957e-17" />
            <geometry>
                <mesh filename="package://omnibot_description/urdf/spacer.stl"/>
            </geometry>
        </collision>
        <visual>
            <origin xyz="0.028790823204502415111 -0.01317823560143211066 -0.010000000285351182128" rpy="9.4858016401645068199e-16 7.2498576146944507703e-16 -0.79586931499755364516" />
            <geometry>
                <mesh filename="package://omnibot_description/urdf/axys_rod.stl"/>
            </geometry>
            <material name="axys_rod_material">
                <color rgba="0.61568627450980395466 0.81176470588235294379 0.92941176470588238168 1.0"/>
            </material>
        </visual>
        <collision>
            <origin xyz="0.028790823204502415111 -0.01317823560143211066 -0.010000000285351182128" rpy="9.4858016401645068199e-16 7.2498576146944507703e-16 -0.79586931499755364516" />
            <geometry>
                <mesh filename="package://omnibot_description/urdf/axys_rod.stl"/>
            </geometry>
        </collision>
        <visual>
            <origin xyz="0.003014507118005808721 0.031409130275868862858 -0.024199999101464600426" rpy="3.1415926535897926719 -8.7528312188624444855e-16 1.8430678811938712158" />
            <geometry>
                <mesh filename="package://omnibot_description/urdf/axys_rod.stl"/>
            </geometry>
            <material name="axys_rod_material">
                <color rgba="0.61568627450980395466 0.81176470588235294379 0.92941176470588238168 1.0"/>
            </material>
        </visual>
        <collision>
            <origin xyz="0.003014507118005808721 0.031409130275868862858 -0.024199999101464600426" rpy="3.1415926535897926719 -8.7528312188624444855e-16 1.8430678811938712158" />
            <geometry>
                <mesh filename="package://omnibot_description/urdf/axys_rod.stl"/>
            </geometry>
        </collision>
        <visual>
            <origin xyz="-0.028708344080531238152 -0.013093882512642342902 -0.024199998418286350343" rpy="7.630998749265247437e-16 -4.0019020663288617633e-16 0.79586976703605805117" />
            <geometry>
                <mesh filename="package://omnibot_description/urdf/axys_rod.stl"/>
            </geometry>
            <material name="axys_rod_material">
                <color rgba="0.61568627450980395466 0.81176470588235294379 0.92941176470588238168 1.0"/>
            </material>
        </visual>
        <collision>
            <origin xyz="-0.028708344080531238152 -0.013093882512642342902 -0.024199998418286350343" rpy="7.630998749265247437e-16 -4.0019020663288617633e-16 0.79586976703605805117" />
            <geometry>
                <mesh filename="package://omnibot_description/urdf/axys_rod.stl"/>
            </geometry>
        </collision>
        <inertial>
            <origin xyz="-9.4588917160628263354e-06 -8.8415141495136123444e-06 -0.015131125342708447168" rpy="0 0 0"/>
            <mass value="0.019223052335254620093" />
            <inertia ixx="5.3992629534633116632e-06" ixy="-7.3246329002137853468e-08"  ixz="-1.2642889979757766234e-09" iyy="5.6557979176500123252e-06" iyz="1.9098649289547097471e-09" izz="8.6846392930505551149e-06" />
        </inertial>
    </link>

    <link name="roller_25">
        <visual>
            <origin xyz="0 0 -1.7347234759768070944e-18" rpy="-9.1355942858765001246e-17 1.3086155217874158504e-17 6.338390528770257e-17" />
            <geometry>
                <mesh filename="package://omnibot_description/urdf/roller.stl"/>
            </geometry>
            <material name="roller_material">
                <color rgba="0.098039215686274508443 0.098039215686274508443 0.098039215686274508443 1.0"/>
            </material>
        </visual>
        <!-- Shapes for roller -->
        <collision>
            <origin xyz="0 0 -1.7347234759768070944e-18" rpy="-9.1355942858765001246e-17 1.3086155217874158504e-17 6.338390528770257e-17" />
            <geometry>
                <sphere radius="0.007700000000000000247" />
            </geometry>
        </collision>
        <inertial>
            <origin xyz="4.0756121962864205179e-11 8.4957103194350890961e-11 2.428384730612916946e-11" rpy="0 0 0"/>
            <mass value="0.0037899803393768708749" />
            <inertia ixx="1.8303635244743854193e-07" ixy="4.2716079357302465501e-16"  ixz="-1.7514569717245809086e-15" iyy="1.8303636075213770966e-07" iyz="-3.342914321931132021e-15" izz="9.8097062080638907831e-08" />
        </inertial>
    </link>

    <joint name="roller3_1" type="revolute">
        <origin xyz="-0.020681651273558386561 0.021119338664790876514 -0.010000000622265817207" rpy="1.5707963267948985564 0.98155021618507098946 -0.79586931499755286801" />
        <parent link="wheel_3" />
        <child link="roller_25" />
        <axis xyz="0 0 1"/>
        <limit effort="1" velocity="20" />
        <joint_properties friction="0.0"/>
    </joint>

    <link name="roller_26">
        <visual>
            <origin xyz="-6.9388939039072283776e-18 -2.7755575615628913511e-17 0" rpy="-1.057222307256755754e-17 -9.6822170767443595194e-20 -2.8699459896474235049e-17" />
            <geometry>
                <mesh filename="package://omnibot_description/urdf/roller.stl"/>
            </geometry>
            <material name="roller_material">
                <color rgba="0.098039215686274508443 0.098039215686274508443 0.098039215686274508443 1.0"/>
            </material>
        </visual>
        <!-- Shapes for roller -->
        <collision>
            <origin xyz="-6.9388939039072283776e-18 -2.7755575615628913511e-17 0" rpy="-1.057222307256755754e-17 -9.6822170767443595194e-20 -2.8699459896474235049e-17" />
            <geometry>
                <sphere radius="0.007700000000000000247" />
            </geometry>
        </collision>
        <inertial>
            <origin xyz="4.0756115023970307734e-11 8.4957075438775288257e-11 2.428384904085265513e-11" rpy="0 0 0"/>
            <mass value="0.0037899803393768708749" />
            <inertia ixx="1.8303635244743854193e-07" ixy="4.2716079967822435366e-16"  ixz="-1.751456986937698582e-15" iyy="1.8303636075213781554e-07" iyz="-3.342914309265361187e-15" izz="9.80970620806389343e-08" />
        </inertial>
    </link>

    <joint name="roller3_2" type="revolute">
        <origin xyz="-0.028516433936169503782 -0.0073217973661773650199 -0.010000001453652873629" rpy="1.5707963267948978903 0.12996521041089167947 0.25132812119095521153" />
        <parent link="wheel_3" />
        <child link="roller_26" />
        <axis xyz="0 0 1"/>
        <limit effort="1" velocity="20" />
        <joint_properties friction="0.0"/>
    </joint>

    <link name="roller_27">
        <visual>
            <origin xyz="2.7755575615628913511e-17 0 1.7347234759768070944e-18" rpy="6.8963637520063186898e-17 -1.7210856551687102018e-17 -7.7828747940638303795e-19" />
            <geometry>
                <mesh filename="package://omnibot_description/urdf/roller.stl"/>
            </geometry>
            <material name="roller_material">
                <color rgba="0.098039215686274508443 0.098039215686274508443 0.098039215686274508443 1.0"/>
            </material>
        </visual>
        <!-- Shapes for roller -->
        <collision>
            <origin xyz="2.7755575615628913511e-17 0 1.7347234759768070944e-18" rpy="6.8963637520063186898e-17 -1.7210856551687102018e-17 -7.7828747940638303795e-19" />
            <geometry>
                <sphere radius="0.007700000000000000247" />
            </geometry>
        </collision>
        <inertial>
            <origin xyz="4.075614971843982727e-11 8.4957103194350903886e-11 2.4283850775576134338e-11" rpy="0 0 0"/>
            <mass value="0.0037899803393768708749" />
            <inertia ixx="1.8303635244743854193e-07" ixy="4.2716081215996582063e-16"  ixz="-1.7514569796603926364e-15" iyy="1.8303636075213781554e-07" iyz="-3.3429142860113545272e-15" izz="9.8097062080638907831e-08" />
        </inertial>
    </link>

    <joint name="roller3_3" type="revolute">
        <origin xyz="-0.0082858436691589792966 -0.028375035936988181329 -0.010000003715208094501" rpy="1.5707963267948956698 0.9703739388243279862 -1.8430676189349766148" />
        <parent link="wheel_3" />
        <child link="roller_27" />
        <axis xyz="0 0 1"/>
        <limit effort="1" velocity="20" />
        <joint_properties friction="0.0"/>
    </joint>

    <link name="roller_28">
        <visual>
            <origin xyz="1.3877787807814456755e-17 0 -3.4694469519536141888e-18" rpy="6.8963637520063186898e-17 -1.7210856551687102018e-17 -7.7828747940638303795e-19" />
            <geometry>
                <mesh filename="package://omnibot_description/urdf/roller.stl"/>
            </geometry>
            <material name="roller_material">
                <color rgba="0.098039215686274508443 0.098039215686274508443 0.098039215686274508443 1.0"/>
            </material>
        </visual>
        <!-- Shapes for roller -->
        <collision>
            <origin xyz="1.3877787807814456755e-17 0 -3.4694469519536141888e-18" rpy="6.8963637520063186898e-17 -1.7210856551687102018e-17 -7.7828747940638303795e-19" />
            <geometry>
                <sphere radius="0.007700000000000000247" />
            </geometry>
        </collision>
        <inertial>
            <origin xyz="4.0756135840652019455e-11 8.4957103194350903886e-11 2.4283845571405706408e-11" rpy="0 0 0"/>
            <mass value="0.0037899803393768708749" />
            <inertia ixx="1.8303635244743854193e-07" ixy="4.2716081215996582063e-16"  ixz="-1.7514569796603926364e-15" iyy="1.8303636075213781554e-07" iyz="-3.3429142860113545272e-15" izz="9.8097062080638907831e-08" />
        </inertial>
    </link>

    <joint name="roller3_4" type="revolute">
        <origin xyz="0.0079490519369571285835 0.028470515462351499159 -0.0099999970627584339189" rpy="1.5707963267948956698 0.9703739388243279862 -1.8430676189349766148" />
        <parent link="wheel_3" />
        <child link="roller_28" />
        <axis xyz="0 0 1"/>
        <limit effort="1" velocity="20" />
        <joint_properties friction="0.0"/>
    </joint>

    <link name="roller_29">
        <visual>
            <origin xyz="0 0 5.2041704279304212832e-18" rpy="-5.2006409085214947e-17 -4.1488311595070334227e-17 3.430966771816442121e-17" />
            <geometry>
                <mesh filename="package://omnibot_description/urdf/roller.stl"/>
            </geometry>
            <material name="roller_material">
                <color rgba="0.098039215686274508443 0.098039215686274508443 0.098039215686274508443 1.0"/>
            </material>
        </visual>
        <!-- Shapes for roller -->
        <collision>
            <origin xyz="0 0 5.2041704279304212832e-18" rpy="-5.2006409085214947e-17 -4.1488311595070334227e-17 3.430966771816442121e-17" />
            <geometry>
                <sphere radius="0.007700000000000000247" />
            </geometry>
        </collision>
        <inertial>
            <origin xyz="4.0756121962864218103e-11 8.4957103194350890961e-11 2.4283854245023083061e-11" rpy="0 0 0"/>
            <mass value="0.0037899803393768708749" />
            <inertia ixx="1.8303635244743854193e-07" ixy="4.2716082955247286952e-16"  ixz="-1.7514569771766301553e-15" iyy="1.830363607521377626e-07" iyz="-3.3429143153932035109e-15" izz="9.80970620806389343e-08" />
        </inertial>
    </link>

    <joint name="roller3_5" type="revolute">
        <origin xyz="0.020599080645981773796 0.021035055769849118901 -0.024199995144404254366" rpy="1.5707963267948974462 -0.60012852644593328577 0.7958697670360587173" />
        <parent link="wheel_3" />
        <child link="roller_29" />
        <axis xyz="0 0 1"/>
        <limit effort="1" velocity="20" />
        <joint_properties friction="0.0"/>
    </joint>

    <link name="roller_30">
        <visual>
            <origin xyz="-1.3877787807814456755e-17 1.3877787807814456755e-17 -8.6736173798840354721e-18" rpy="9.1355942858765001246e-17 1.3086155217874158504e-17 -6.338390528770257e-17" />
            <geometry>
                <mesh filename="package://omnibot_description/urdf/roller.stl"/>
            </geometry>
            <material name="roller_material">
                <color rgba="0.098039215686274508443 0.098039215686274508443 0.098039215686274508443 1.0"/>
            </material>
        </visual>
        <!-- Shapes for roller -->
        <collision>
            <origin xyz="-1.3877787807814456755e-17 1.3877787807814456755e-17 -8.6736173798840354721e-18" rpy="9.1355942858765001246e-17 1.3086155217874158504e-17 -6.338390528770257e-17" />
            <geometry>
                <sphere radius="0.007700000000000000247" />
            </geometry>
        </collision>
        <inertial>
            <origin xyz="4.0756108085076423213e-11 8.4957117072138698775e-11 2.4283840367235278477e-11" rpy="0 0 0"/>
            <mass value="0.0037899803393768708749" />
            <inertia ixx="1.8303635244743854193e-07" ixy="4.271608242617420295e-16"  ixz="-1.7514569717245815003e-15" iyy="1.8303636075213770966e-07" iyz="-3.3429142896165888869e-15" izz="9.8097062080638907831e-08" />
        </inertial>
    </link>

    <joint name="roller3_6" type="revolute">
        <origin xyz="0.0206815648335043345 -0.021119421197575691251 -0.010000000285351223761" rpy="1.5707963267948945596 -0.98155021618507098946 2.34572333859224047" />
        <parent link="wheel_3" />
        <child link="roller_30" />
        <axis xyz="0 0 1"/>
        <limit effort="1" velocity="20" />
        <joint_properties friction="0.0"/>
    </joint>

    <link name="roller_31">
        <visual>
            <origin xyz="2.7755575615628913511e-17 0 3.9031278209478159624e-18" rpy="-6.8092232839210934151e-18 -1.027900486430717868e-17 7.3190472780373689684e-17" />
            <geometry>
                <mesh filename="package://omnibot_description/urdf/roller.stl"/>
            </geometry>
            <material name="roller_material">
                <color rgba="0.098039215686274508443 0.098039215686274508443 0.098039215686274508443 1.0"/>
            </material>
        </visual>
        <!-- Shapes for roller -->
        <collision>
            <origin xyz="2.7755575615628913511e-17 0 3.9031278209478159624e-18" rpy="-6.8092232839210934151e-18 -1.027900486430717868e-17 7.3190472780373689684e-17" />
            <geometry>
                <sphere radius="0.007700000000000000247" />
            </geometry>
        </collision>
        <inertial>
            <origin xyz="4.075614971843982727e-11 8.4957103194350903886e-11 2.4283852943980476078e-11" rpy="0 0 0"/>
            <mass value="0.0037899803393768708749" />
            <inertia ixx="1.8303635244743854193e-07" ixy="4.271608159049202163e-16"  ixz="-1.7514569763998979865e-15" iyy="1.8303636075213781554e-07" iyz="-3.3429143054775741587e-15" izz="9.80970620806389343e-08" />
        </inertial>
    </link>

    <joint name="roller3_7" type="revolute">
        <origin xyz="0.0079173979793228238533 -0.028356884977337792897 -0.024199999508976416385" rpy="1.5707963267948983344 1.051990792840859168 -1.2985247723959194577" />
        <parent link="wheel_3" />
        <child link="roller_31" />
        <axis xyz="0 0 1"/>
        <limit effort="1" velocity="20" />
        <joint_properties friction="0.0"/>
    </joint>

    <link name="roller_32">
        <visual>
            <origin xyz="1.3877787807814456755e-17 0 1.7347234759768070944e-18" rpy="-3.4504113418151379288e-19 2.4299479685659417839e-17 3.0637320463894800399e-18" />
            <geometry>
                <mesh filename="package://omnibot_description/urdf/roller.stl"/>
            </geometry>
            <material name="roller_material">
                <color rgba="0.098039215686274508443 0.098039215686274508443 0.098039215686274508443 1.0"/>
            </material>
        </visual>
        <!-- Shapes for roller -->
        <collision>
            <origin xyz="1.3877787807814456755e-17 0 1.7347234759768070944e-18" rpy="-3.4504113418151379288e-19 2.4299479685659417839e-17 3.0637320463894800399e-18" />
            <geometry>
                <sphere radius="0.007700000000000000247" />
            </geometry>
        </collision>
        <inertial>
            <origin xyz="4.0756135840652019455e-11 8.4957103194350890961e-11 2.4283850775576131107e-11" rpy="0 0 0"/>
            <mass value="0.0037899803393768708749" />
            <inertia ixx="1.8303635244743854193e-07" ixy="4.2716080368214507052e-16"  ixz="-1.7514569828898479763e-15" iyy="1.830363607521377626e-07" iyz="-3.3429142941825852261e-15" izz="9.80970620806389343e-08" />
        </inertial>
    </link>

    <joint name="roller3_8" type="revolute">
        <origin xyz="0.028516471920454498912 -0.0073217858682495138775 -0.024199999328581869862" rpy="1.5707963267948952257 0.98120498930390365189 2.8902650095731114988" />
        <parent link="wheel_3" />
        <child link="roller_32" />
        <axis xyz="0 0 1"/>
        <limit effort="1" velocity="20" />
        <joint_properties friction="0.0"/>
    </joint>

    <link name="roller_33">
        <visual>
            <origin xyz="-1.3877787807814456755e-17 0 7.8062556418956319249e-18" rpy="1.9157077653018818515e-17 -4.4373991813381658386e-17 4.019356234047508005e-17" />
            <geometry>
                <mesh filename="package://omnibot_description/urdf/roller.stl"/>
            </geometry>
            <material name="roller_material">
                <color rgba="0.098039215686274508443 0.098039215686274508443 0.098039215686274508443 1.0"/>
            </material>
        </visual>
        <!-- Shapes for roller -->
        <collision>
            <origin xyz="-1.3877787807814456755e-17 0 7.8062556418956319249e-18" rpy="1.9157077653018818515e-17 -4.4373991813381658386e-17 4.019356234047508005e-17" />
            <geometry>
                <sphere radius="0.007700000000000000247" />
            </geometry>
        </collision>
        <inertial>
            <origin xyz="4.0756108085076423213e-11 8.4957103194350890961e-11 2.4283856847108309951e-11" rpy="0 0 0"/>
            <mass value="0.0037899803393768708749" />
            <inertia ixx="1.8303635244743864781e-07" ixy="4.2716083949853341864e-16"  ixz="-1.751456976657343729e-15" iyy="1.830363607521377626e-07" iyz="-3.3429143074584098082e-15" izz="9.809706208063898724e-08" />
        </inertial>
    </link>

    <joint name="roller3_9" type="revolute">
        <origin xyz="-0.0079173874319014240358 0.028356888222933203381 -0.024199999101464600426" rpy="1.5707963267948958919 -1.0519907928408602782 1.8430678811938712158" />
        <parent link="wheel_3" />
        <child link="roller_33" />
        <axis xyz="0 0 1"/>
        <limit effort="1" velocity="20" />
        <joint_properties friction="0.0"/>
    </joint>

    <link name="roller_34">
        <visual>
            <origin xyz="-1.3877787807814456755e-17 3.4694469519536141888e-18 -1.7347234759768070944e-18" rpy="2.4258078252098803542e-18 1.3064319734432134978e-17 1.547339326721106241e-17" />
            <geometry>
                <mesh filename="package://omnibot_description/urdf/roller.stl"/>
            </geometry>
            <material name="roller_material">
                <color rgba="0.098039215686274508443 0.098039215686274508443 0.098039215686274508443 1.0"/>
            </material>
        </visual>
        <!-- Shapes for roller -->
        <collision>
            <origin xyz="-1.3877787807814456755e-17 3.4694469519536141888e-18 -1.7347234759768070944e-18" rpy="2.4258078252098803542e-18 1.3064319734432134978e-17 1.547339326721106241e-17" />
            <geometry>
                <sphere radius="0.007700000000000000247" />
            </geometry>
        </collision>
        <inertial>
            <origin xyz="4.0756108085076403826e-11 8.4957106663797855839e-11 2.4283847306129179153e-11" rpy="0 0 0"/>
            <mass value="0.0037899803393768708749" />
            <inertia ixx="1.8303635244743854193e-07" ixy="4.2716081667819919579e-16"  ixz="-1.7514569890494251883e-15" iyy="1.830363607521377626e-07" iyz="-3.3429143095769608502e-15" izz="9.80970620806389343e-08" />
        </inertial>
    </link>

    <joint name="roller3_10" type="revolute">
        <origin xyz="-0.028516458158703447689 0.0073218567028480677911 -0.024199999573447900092" rpy="1.5707963267948956698 0.98120498930390487313 2.8902650095731106106" />
        <parent link="wheel_3" />
        <child link="roller_34" />
        <axis xyz="0 0 1"/>
        <limit effort="1" velocity="20" />
        <joint_properties friction="0.0"/>
    </joint>

    <link name="roller_35">
        <visual>
            <origin xyz="-1.3877787807814456755e-17 0 -1.7347234759768070944e-18" rpy="-5.2006409085214947e-17 -4.1488311595070334227e-17 3.430966771816442121e-17" />
            <geometry>
                <mesh filename="package://omnibot_description/urdf/roller.stl"/>
            </geometry>
            <material name="roller_material">
                <color rgba="0.098039215686274508443 0.098039215686274508443 0.098039215686274508443 1.0"/>
            </material>
        </visual>
        <!-- Shapes for roller -->
        <collision>
            <origin xyz="-1.3877787807814456755e-17 0 -1.7347234759768070944e-18" rpy="-5.2006409085214947e-17 -4.1488311595070334227e-17 3.430966771816442121e-17" />
            <geometry>
                <sphere radius="0.007700000000000000247" />
            </geometry>
        </collision>
        <inertial>
            <origin xyz="4.0756108085076410289e-11 8.4957103194350890961e-11 2.4283847306129179153e-11" rpy="0 0 0"/>
            <mass value="0.0037899803393768708749" />
            <inertia ixx="1.8303635244743854193e-07" ixy="4.2716082955247286952e-16"  ixz="-1.7514569771766301553e-15" iyy="1.830363607521377626e-07" iyz="-3.3429143153932035109e-15" izz="9.80970620806389343e-08" />
        </inertial>
    </link>

    <joint name="roller3_11" type="revolute">
        <origin xyz="-0.020599082119812324454 -0.02103506444308805845 -0.024199998418286350343" rpy="1.5707963267948974462 -0.60012852644593328577 0.7958697670360587173" />
        <parent link="wheel_3" />
        <child link="roller_35" />
        <axis xyz="0 0 1"/>
        <limit effort="1" velocity="20" />
        <joint_properties friction="0.0"/>
    </joint>

    <link name="roller_36">
        <visual>
            <origin xyz="6.9388939039072283776e-18 0 -3.4694469519536141888e-18" rpy="-1.1268743259741396852e-17 -1.992414704174456577e-17 3.4691976098257111765e-17" />
            <geometry>
                <mesh filename="package://omnibot_description/urdf/roller.stl"/>
            </geometry>
            <material name="roller_material">
                <color rgba="0.098039215686274508443 0.098039215686274508443 0.098039215686274508443 1.0"/>
            </material>
        </visual>
        <!-- Shapes for roller -->
        <collision>
            <origin xyz="6.9388939039072283776e-18 0 -3.4694469519536141888e-18" rpy="-1.1268743259741396852e-17 -1.992414704174456577e-17 3.4691976098257111765e-17" />
            <geometry>
                <sphere radius="0.007700000000000000247" />
            </geometry>
        </collision>
        <inertial>
            <origin xyz="4.075612890175812201e-11 8.4957103194350903886e-11 2.4283845571405706408e-11" rpy="0 0 0"/>
            <mass value="0.0037899803393768708749" />
            <inertia ixx="1.8303635244743854193e-07" ixy="4.2716082562761070789e-16"  ixz="-1.7514569755248761155e-15" iyy="1.8303636075213781554e-07" iyz="-3.3429143081568459544e-15" izz="9.809706208063898724e-08" />
        </inertial>
    </link>

    <joint name="roller3_12" type="revolute">
        <origin xyz="0.028630754033681760085 0.0073511498047736847233 -0.010000000481623361193" rpy="1.5707963267948976682 0.12996521041089265092 0.25132812119095498948" />
        <parent link="wheel_3" />
        <child link="roller_36" />
        <axis xyz="0 0 1"/>
        <limit effort="1" velocity="20" />
        <joint_properties friction="0.0"/>
    </joint>

    <joint name="wheel3" type="revolute">
        <origin xyz="2.6263408339213767581e-17 0.015229328657860304735 3.0000000000016124879e-05" rpy="3.141592653589793116 -4.3371326877914994301e-16 -2.6462604399390747822" />
        <parent link="motor_3" />
        <child link="wheel_3" />
        <axis xyz="0 0 1"/>
        <limit effort="1" velocity="20" />
        <joint_properties friction="0.0"/>
    </joint>

    <joint name="motor3" type="fixed">
        <origin xyz="-0.072435351823797927695 -0.043144348079105873661 1.2143064331837649661e-17" rpy="-1.570796326794896558 1.578226579417481623e-16 2.1079931297550063007" />
        <parent link="base" />
        <child link="motor_3" />
        <axis xyz="0 0 1"/>
        <limit effort="1" velocity="20" />
        <joint_properties friction="0.0"/>
    </joint>


</robot>
