<robot name="onshape">
    <link name="body">
        <collision>
            <origin xyz="0 0 0" rpy="0 -0 0" />
            <geometry>
                <mesh filename="package:///plate.stl"/>
            </geometry>
        </collision>
        <visual>
            <origin xyz="0 0 0" rpy="0 -0 0" />
            <geometry>
                <mesh filename="package:///plate.stl"/>
            </geometry>
            <material name="plate_material">
                <color rgba="0.68235294117647060652 0.33333333333333331483 0.73725490196078435901 1.0"/>
            </material>
        </visual>
        <collision>
            <origin xyz="0 0 0.022999999999999999611" rpy="0 -0 0" />
            <geometry>
                <mesh filename="package:///plate.stl"/>
            </geometry>
        </collision>
        <visual>
            <origin xyz="0 0 0.022999999999999999611" rpy="0 -0 0" />
            <geometry>
                <mesh filename="package:///plate.stl"/>
            </geometry>
            <material name="plate_material">
                <color rgba="0.68235294117647060652 0.33333333333333331483 0.73725490196078435901 1.0"/>
            </material>
        </visual>
        <collision>
            <origin xyz="0 6.9388939039072283776e-18 0" rpy="0 -0 -2.0943951023931952626" />
            <geometry>
                <mesh filename="package:///motor.stl"/>
            </geometry>
        </collision>
        <visual>
            <origin xyz="0 6.9388939039072283776e-18 0" rpy="0 -0 -2.0943951023931952626" />
            <geometry>
                <mesh filename="package:///motor.stl"/>
            </geometry>
            <material name="motor_material">
                <color rgba="0.64705882352941179736 0.64705882352941179736 0.64705882352941179736 1.0"/>
            </material>
        </visual>
        <collision>
            <origin xyz="0 0 0" rpy="0 -0 0" />
            <geometry>
                <mesh filename="package:///motor.stl"/>
            </geometry>
        </collision>
        <visual>
            <origin xyz="0 0 0" rpy="0 -0 0" />
            <geometry>
                <mesh filename="package:///motor.stl"/>
            </geometry>
            <material name="motor_material">
                <color rgba="0.64705882352941179736 0.64705882352941179736 0.64705882352941179736 1.0"/>
            </material>
        </visual>
        <collision>
            <origin xyz="-1.7347234759768070944e-18 -6.9388939039072283776e-18 2.6020852139652106416e-18" rpy="0 -0 2.0943951023931957067" />
            <geometry>
                <mesh filename="package:///motor.stl"/>
            </geometry>
        </collision>
        <visual>
            <origin xyz="-1.7347234759768070944e-18 -6.9388939039072283776e-18 2.6020852139652106416e-18" rpy="0 -0 2.0943951023931957067" />
            <geometry>
                <mesh filename="package:///motor.stl"/>
            </geometry>
            <material name="motor_material">
                <color rgba="0.64705882352941179736 0.64705882352941179736 0.64705882352941179736 1.0"/>
            </material>
        </visual>
        <inertial>
            <origin xyz="0.00041313742631781931545 0.00023852500429690030306 0.0129603621972746684" rpy="0 0 0"/>
            <mass value="0.55184045573988327327" />
            <inertia ixx="0.00061573183967726478893" ixy="-4.5433878869427433121e-06"  ixz="-9.0368619367302114059e-09" iyy="0.0006209780921163835345" iyz="-5.2174346717752650079e-09" izz="0.0011894065910678659325" />
        </inertial>
    </link>

    <joint name="body_frame" type="fixed">
        <origin xyz="0.0041869852016127150768 0.002417357033244084321 0.014499999999999997266" rpy="0 -0 0.52359877559829937077" />
        <parent link="body" />
        <child link="body" />
        <axis xyz="0 0 0"/>
    </joint>

    <link name="wheel">
        <collision>
            <origin xyz="-1.0873096856216548664e-17 0.013000000000000001138 0.075000000000000011102" rpy="1.570796326794896558 1.0471975511965980754 0" />
            <geometry>
                <mesh filename="package:///wheel.stl"/>
            </geometry>
        </collision>
        <visual>
            <origin xyz="-1.0873096856216548664e-17 0.013000000000000001138 0.075000000000000011102" rpy="1.570796326794896558 1.0471975511965980754 0" />
            <geometry>
                <mesh filename="package:///wheel.stl"/>
            </geometry>
            <material name="wheel_material">
                <color rgba="0.94117647058823528106 0.87450980392156862919 0.67843137254901964006 1.0"/>
            </material>
        </visual>
        <inertial>
            <origin xyz="-9.2850734045857308274e-11 -1.4381200032914653875e-09 -0.0025000000554400089725" rpy="0 0 0"/>
            <mass value="0.01924908488748922758" />
            <inertia ixx="6.8765144932724321509e-06" ixy="4.7414145390036950856e-13"  ixz="-1.4288918501014582948e-14" iyy="6.8765142522306713877e-06" iyz="2.2762036751622371319e-14" izz="1.367364354725972861e-05" />
        </inertial>
    </link>

    <link name="passivewheel">
        <collision>
            <origin xyz="0 1.3877787807814456755e-17 0.003999999999999992277" rpy="3.141592653589793116 2.24259073184045143e-18 1.2907791712102774454e-17" />
            <geometry>
                <mesh filename="package:///passivewheel.stl"/>
            </geometry>
        </collision>
        <visual>
            <origin xyz="0 1.3877787807814456755e-17 0.003999999999999992277" rpy="3.141592653589793116 2.24259073184045143e-18 1.2907791712102774454e-17" />
            <geometry>
                <mesh filename="package:///passivewheel.stl"/>
            </geometry>
            <material name="passivewheel_material">
                <color rgba="0.30196078431372547213 0.29019607843137257275 0.26274509803921569651 1.0"/>
            </material>
        </visual>
        <inertial>
            <origin xyz="-7.3389395038143459303e-20 1.3355585844945038714e-17 0.0019999999999999918017" rpy="0 0 0"/>
            <mass value="0.0028590609658248017193" />
            <inertia ixx="2.7747274432609138953e-08" ixy="3.2194254007337155093e-25"  ixz="2.0568644105019387053e-24" iyy="2.7747274432609138953e-08" iyz="2.6537420953333751573e-24" izz="4.8977394258054644615e-08" />
        </inertial>
    </link>

    <joint name="w1_1_passive" type="revolute">
        <origin xyz="-0.01349025032165082974 -0.035046585372318354856 -0.0025000000000000160982" rpy="1.57079632679489678 1.3942429024899487544 1.2566370614359179125" />
        <parent link="wheel" />
        <child link="passivewheel" />
        <axis xyz="0 0 1"/>
        <limit effort="1" velocity="20" />
        <joint_properties friction="0.0"/>
    </joint>

    <link name="passivewheel_2">
        <collision>
            <origin xyz="-1.3877787807814456755e-17 0 -2.168404344971008868e-18" rpy="-3.141592653589793116 6.4550111140484228673e-17 5.5327585353806306102e-32" />
            <geometry>
                <mesh filename="package:///passivewheel.stl"/>
            </geometry>
        </collision>
        <visual>
            <origin xyz="-1.3877787807814456755e-17 0 -2.168404344971008868e-18" rpy="-3.141592653589793116 6.4550111140484228673e-17 5.5327585353806306102e-32" />
            <geometry>
                <mesh filename="package:///passivewheel.stl"/>
            </geometry>
            <material name="passivewheel_material">
                <color rgba="0.30196078431372547213 0.29019607843137257275 0.26274509803921569651 1.0"/>
            </material>
        </visual>
        <inertial>
            <origin xyz="-1.3809418800533706559e-17 -3.8878508430785589058e-19 -0.0020000000000000026437" rpy="0 0 0"/>
            <mass value="0.0028590609658248017193" />
            <inertia ixx="2.7747274432609138953e-08" ixy="3.0703793890113740208e-39"  ixz="-3.1434780373742685841e-24" iyy="2.7747274432609138953e-08" iyz="2.3906373829315416642e-39" izz="4.8977394258054644615e-08" />
        </inertial>
    </link>

    <joint name="w1_2_passive" type="revolute">
        <origin xyz="-0.0020000000000000030774 -0.037499999999999991673 -0.0025000000000000160982" rpy="3.1415926535897926719 1.570796326794896336 0" />
        <parent link="wheel" />
        <child link="passivewheel_2" />
        <axis xyz="0 0 1"/>
        <limit effort="1" velocity="20" />
        <joint_properties friction="0.0"/>
    </joint>

    <link name="passivewheel_3">
        <collision>
            <origin xyz="1.3877787807814456755e-17 0 -6.9388939039072283776e-18" rpy="1.0605811429304414209e-17 -2.2971953405687063788e-17 5.5750143630728103276e-18" />
            <geometry>
                <mesh filename="package:///passivewheel.stl"/>
            </geometry>
        </collision>
        <visual>
            <origin xyz="1.3877787807814456755e-17 0 -6.9388939039072283776e-18" rpy="1.0605811429304414209e-17 -2.2971953405687063788e-17 5.5750143630728103276e-18" />
            <geometry>
                <mesh filename="package:///passivewheel.stl"/>
            </geometry>
            <material name="passivewheel_material">
                <color rgba="0.30196078431372547213 0.29019607843137257275 0.26274509803921569651 1.0"/>
            </material>
        </visual>
        <inertial>
            <origin xyz="1.3905308927300039323e-17 4.1565009266969546537e-19 0.0019999999999999935364" rpy="0 0 0"/>
            <mass value="0.0028590609658248017193" />
            <inertia ixx="2.7747274432609152187e-08" ixy="-6.1988126641668727105e-25"  ixz="9.8948593172824365931e-25" iyy="2.7747274432609152187e-08" iyz="9.5217141345128624456e-25" izz="4.8977394258054644615e-08" />
        </inertial>
    </link>

    <joint name="w1_3_passive" type="revolute">
        <origin xyz="0.0096860242564702249413 -0.036282653349818151656 -0.0025000000000000022204" rpy="-1.5707963267948970021 1.3942429024899487544 -1.2566370614359163582" />
        <parent link="wheel" />
        <child link="passivewheel_3" />
        <axis xyz="0 0 1"/>
        <limit effort="1" velocity="20" />
        <joint_properties friction="0.0"/>
    </joint>

    <link name="passivewheel_4">
        <collision>
            <origin xyz="0 -3.4694469519536141888e-18 -1.7347234759768070944e-18" rpy="3.141592653589793116 -9.2648223631817248895e-18 -2.4114629845777995328e-17" />
            <geometry>
                <mesh filename="package:///passivewheel.stl"/>
            </geometry>
        </collision>
        <visual>
            <origin xyz="0 -3.4694469519536141888e-18 -1.7347234759768070944e-18" rpy="3.141592653589793116 -9.2648223631817248895e-18 -2.4114629845777995328e-17" />
            <geometry>
                <mesh filename="package:///passivewheel.stl"/>
            </geometry>
            <material name="passivewheel_material">
                <color rgba="0.30196078431372547213 0.29019607843137257275 0.26274509803921569651 1.0"/>
            </material>
        </visual>
        <inertial>
            <origin xyz="3.9637933319539232973e-20 -3.5354567787878240831e-18 -0.00200000000000000221" rpy="0 0 0"/>
            <mass value="0.0028590609658248017193" />
            <inertia ixx="2.7747274432609132335e-08" ixy="-9.818584559492467786e-25"  ixz="-3.9172825179549281124e-25" iyy="2.7747274432609138953e-08" iyz="-8.9323964595110991721e-24" izz="4.8977394258054644615e-08" />
        </inertial>
    </link>

    <joint name="w1_4_passive" type="revolute">
        <origin xyz="0.020423912972217832945 -0.031513707793645477639 -0.0025000000000000022204" rpy="1.5707963267948961139 1.2436334312925148016 -0.94247779607693771275" />
        <parent link="wheel" />
        <child link="passivewheel_4" />
        <axis xyz="0 0 1"/>
        <limit effort="1" velocity="20" />
        <joint_properties friction="0.0"/>
    </joint>

    <link name="passivewheel_5">
        <collision>
            <origin xyz="0 1.7347234759768070944e-18 0" rpy="3.141592653589793116 -1.3456433594919861096e-17 3.656313051612270579e-17" />
            <geometry>
                <mesh filename="package:///passivewheel.stl"/>
            </geometry>
        </collision>
        <visual>
            <origin xyz="0 1.7347234759768070944e-18 0" rpy="3.141592653589793116 -1.3456433594919861096e-17 3.656313051612270579e-17" />
            <geometry>
                <mesh filename="package:///passivewheel.stl"/>
            </geometry>
            <material name="passivewheel_material">
                <color rgba="0.30196078431372547213 0.29019607843137257275 0.26274509803921569651 1.0"/>
            </material>
        </visual>
        <inertial>
            <origin xyz="1.2572964806480117772e-19 1.3525131803507800484e-18 -0.0020000000000000000416" rpy="0 0 0"/>
            <mass value="0.0028590609658248017193" />
            <inertia ixx="2.7747274432609152187e-08" ixy="1.6626078856182311648e-24"  ixz="-2.3836963923489821158e-24" iyy="2.7747274432609138953e-08" iyz="-1.4208433492962210142e-24" izz="4.8977394258054618145e-08" />
        </inertial>
    </link>

    <joint name="w1_5_passive" type="revolute">
        <origin xyz="0.029162566784475575654 -0.023659980949717641929 -0.0025000000000000022204" rpy="1.5707963267948961139 1.1338247319171002037 -0.6283185307179586232" />
        <parent link="wheel" />
        <child link="passivewheel_5" />
        <axis xyz="0 0 1"/>
        <limit effort="1" velocity="20" />
        <joint_properties friction="0.0"/>
    </joint>

    <link name="passivewheel_6">
        <collision>
            <origin xyz="0 -1.7347234759768070944e-18 0" rpy="-3.141592653589793116 -1.3143774050201536165e-17 3.6726775171310805267e-19" />
            <geometry>
                <mesh filename="package:///passivewheel.stl"/>
            </geometry>
        </collision>
        <visual>
            <origin xyz="0 -1.7347234759768070944e-18 0" rpy="-3.141592653589793116 -1.3143774050201536165e-17 3.6726775171310805267e-19" />
            <geometry>
                <mesh filename="package:///passivewheel.stl"/>
            </geometry>
            <material name="passivewheel_material">
                <color rgba="0.30196078431372547213 0.29019607843137257275 0.26274509803921569651 1.0"/>
            </material>
        </visual>
        <inertial>
            <origin xyz="-7.8572716477689042097e-21 -2.087365068675410756e-18 -0.0020000000000000004753" rpy="0 0 0"/>
            <mass value="0.0028590609658248017193" />
            <inertia ixx="2.7747274432609138953e-08" ixy="1.4670395607922852901e-26"  ixz="8.7899777470056078363e-25" iyy="2.7747274432609132335e-08" iyz="-3.1226846778144340307e-25" izz="4.8977394258054644615e-08" />
        </inertial>
    </link>

    <joint name="w1_6_passive" type="revolute">
        <origin xyz="0.035046585372318361795 -0.013490250321650838414 -0.0025000000000000160982" rpy="1.5707963267948958919 1.068649938797565202 -0.31415926535897914507" />
        <parent link="wheel" />
        <child link="passivewheel_6" />
        <axis xyz="0 0 1"/>
        <limit effort="1" velocity="20" />
        <joint_properties friction="0.0"/>
    </joint>

    <link name="passivewheel_7">
        <collision>
            <origin xyz="0 -1.7347234759768070944e-18 -0.0040000000000000000833" rpy="-1.9721522630552270131e-31 -9.8607613152487747128e-32 2.157041537718000011e-32" />
            <geometry>
                <mesh filename="package:///passivewheel.stl"/>
            </geometry>
        </collision>
        <visual>
            <origin xyz="0 -1.7347234759768070944e-18 -0.0040000000000000000833" rpy="-1.9721522630552270131e-31 -9.8607613152487747128e-32 2.157041537718000011e-32" />
            <geometry>
                <mesh filename="package:///passivewheel.stl"/>
            </geometry>
            <material name="passivewheel_material">
                <color rgba="0.30196078431372547213 0.29019607843137257275 0.26274509803921569651 1.0"/>
            </material>
        </visual>
        <inertial>
            <origin xyz="1.3144003607491478492e-20 -1.3459383916689514446e-18 -0.001999999999999999608" rpy="0 0 0"/>
            <mass value="0.0028590609658248017193" />
            <inertia ixx="2.7747274432609138953e-08" ixy="-1.7100578145613461239e-40"  ixz="-2.0934514429147132918e-39" iyy="2.7747274432609138953e-08" iyz="-1.5131272898998891301e-38" izz="4.8977394258054644615e-08" />
        </inertial>
    </link>

    <joint name="w1_7_passive" type="revolute">
        <origin xyz="0.03750000000000001249 -0.0020000000000000035111 -0.002500000000000029976" rpy="1.5707963267948961139 1.0471975511965985195 -1.3322676295501712824e-15" />
        <parent link="wheel" />
        <child link="passivewheel_7" />
        <axis xyz="0 0 1"/>
        <limit effort="1" velocity="20" />
        <joint_properties friction="0.0"/>
    </joint>

    <link name="passivewheel_8">
        <collision>
            <origin xyz="-1.3877787807814456755e-17 1.7347234759768070944e-18 0.0039999999999999983485" rpy="-3.141592653589793116 5.4263473105651871679e-18 9.0880681723985115898e-18" />
            <geometry>
                <mesh filename="package:///passivewheel.stl"/>
            </geometry>
        </collision>
        <visual>
            <origin xyz="-1.3877787807814456755e-17 1.7347234759768070944e-18 0.0039999999999999983485" rpy="-3.141592653589793116 5.4263473105651871679e-18 9.0880681723985115898e-18" />
            <geometry>
                <mesh filename="package:///passivewheel.stl"/>
            </geometry>
            <material name="passivewheel_material">
                <color rgba="0.30196078431372547213 0.29019607843137257275 0.26274509803921569651 1.0"/>
            </material>
        </visual>
        <inertial>
            <origin xyz="-1.39026879545276651e-17 1.3728715132693207397e-18 0.0019999999999999974395" rpy="0 0 0"/>
            <mass value="0.0028590609658248017193" />
            <inertia ixx="2.7747274432609132335e-08" ixy="3.0265835184021123358e-25"  ixz="7.8108532674192053742e-25" iyy="2.7747274432609138953e-08" iyz="-5.3388811923078709672e-25" izz="4.8977394258054671085e-08" />
        </inertial>
    </link>

    <joint name="w1_8_passive" type="revolute">
        <origin xyz="0.036282653349818151656 0.0096860242564702162676 -0.0025000000000000160982" rpy="-1.5707963267948972241 1.0686499387975658681 0.31415926535897825689" />
        <parent link="wheel" />
        <child link="passivewheel_8" />
        <axis xyz="0 0 1"/>
        <limit effort="1" velocity="20" />
        <joint_properties friction="0.0"/>
    </joint>

    <link name="passivewheel_9">
        <collision>
            <origin xyz="0 1.7347234759768070944e-18 -0.0040000000000000035527" rpy="-9.8189196653712580315e-18 5.3586962338473830768e-17 3.6520257520190010152e-17" />
            <geometry>
                <mesh filename="package:///passivewheel.stl"/>
            </geometry>
        </collision>
        <visual>
            <origin xyz="0 1.7347234759768070944e-18 -0.0040000000000000035527" rpy="-9.8189196653712580315e-18 5.3586962338473830768e-17 3.6520257520190010152e-17" />
            <geometry>
                <mesh filename="package:///passivewheel.stl"/>
            </geometry>
            <material name="passivewheel_material">
                <color rgba="0.30196078431372547213 0.29019607843137257275 0.26274509803921569651 1.0"/>
            </material>
        </visual>
        <inertial>
            <origin xyz="-6.2910653951519590993e-20 2.0040269266005324057e-18 -0.0020000000000000030774" rpy="0 0 0"/>
            <mass value="0.0028590609658248017193" />
            <inertia ixx="2.7747274432609138953e-08" ixy="1.8130416685858218011e-24"  ixz="-3.3493716242300389813e-24" iyy="2.7747274432609152187e-08" iyz="-3.1983977983588641089e-24" izz="4.8977394258054644615e-08" />
        </inertial>
    </link>

    <joint name="w1_9_passive" type="revolute">
        <origin xyz="0.031513707793645484578 0.020423912972217836415 -0.002500000000000029976" rpy="1.5707963267948956698 1.1338247319171008698 0.62831853071795773502" />
        <parent link="wheel" />
        <child link="passivewheel_9" />
        <axis xyz="0 0 1"/>
        <limit effort="1" velocity="20" />
        <joint_properties friction="0.0"/>
    </joint>

    <link name="passivewheel_10">
        <collision>
            <origin xyz="2.7755575615628913511e-17 -1.8431436932253575378e-18 1.7347234759768070944e-18" rpy="-3.141592653589793116 4.1524607592453028539e-17 -3.6954129233239061213e-17" />
            <geometry>
                <mesh filename="package:///passivewheel.stl"/>
            </geometry>
        </collision>
        <visual>
            <origin xyz="2.7755575615628913511e-17 -1.8431436932253575378e-18 1.7347234759768070944e-18" rpy="-3.141592653589793116 4.1524607592453028539e-17 -3.6954129233239061213e-17" />
            <geometry>
                <mesh filename="package:///passivewheel.stl"/>
            </geometry>
            <material name="passivewheel_material">
                <color rgba="0.30196078431372547213 0.29019607843137257275 0.26274509803921569651 1.0"/>
            </material>
        </visual>
        <inertial>
            <origin xyz="2.7566683816603316379e-17 -2.2703087901879130451e-18 -0.0019999999999999983069" rpy="0 0 0"/>
            <mass value="0.0028590609658248017193" />
            <inertia ixx="2.7747274432609152187e-08" ixy="-1.7520000295910394304e-24"  ixz="3.7953988973273953645e-24" iyy="2.7747274432609138953e-08" iyz="2.8329576022967801355e-24" izz="4.897739425805463138e-08" />
        </inertial>
    </link>

    <joint name="w1_10_passive" type="revolute">
        <origin xyz="0.023659980949717641929 0.029162566784475561776 -0.0025000000000000022204" rpy="1.57079632679489678 1.2436334312925150236 0.94247779607693804582" />
        <parent link="wheel" />
        <child link="passivewheel_10" />
        <axis xyz="0 0 1"/>
        <limit effort="1" velocity="20" />
        <joint_properties friction="0.0"/>
    </joint>

    <link name="passivewheel_11">
        <collision>
            <origin xyz="0 1.7347234759768070944e-18 7.8062556418956319249e-18" rpy="3.141592653589793116 -4.9837115474694518269e-17 -2.832439431147285365e-18" />
            <geometry>
                <mesh filename="package:///passivewheel.stl"/>
            </geometry>
        </collision>
        <visual>
            <origin xyz="0 1.7347234759768070944e-18 7.8062556418956319249e-18" rpy="3.141592653589793116 -4.9837115474694518269e-17 -2.832439431147285365e-18" />
            <geometry>
                <mesh filename="package:///passivewheel.stl"/>
            </geometry>
            <material name="passivewheel_material">
                <color rgba="0.30196078431372547213 0.29019607843137257275 0.26274509803921569651 1.0"/>
            </material>
        </visual>
        <inertial>
            <origin xyz="5.4999930559418229448e-20 1.3094378821905764855e-18 -0.0019999999999999926691" rpy="0 0 0"/>
            <mass value="0.0028590609658248017193" />
            <inertia ixx="2.7747274432609138953e-08" ixy="-1.4009756099871121518e-25"  ixz="3.5784700182555961329e-25" iyy="2.7747274432609138953e-08" iyz="6.7240469214320536079e-25" izz="4.8977394258054644615e-08" />
        </inertial>
    </link>

    <joint name="w1_11_passive" type="revolute">
        <origin xyz="0.013490250321650848822 0.035046585372318347917 -0.0025000000000000022204" rpy="1.5707963267948974462 1.3942429024899489765 1.2566370614359181346" />
        <parent link="wheel" />
        <child link="passivewheel_11" />
        <axis xyz="0 0 1"/>
        <limit effort="1" velocity="20" />
        <joint_properties friction="0.0"/>
    </joint>

    <link name="passivewheel_12">
        <collision>
            <origin xyz="2.7755575615628913511e-17 0 -4.7704895589362195096e-18" rpy="3.141592653589793116 1.4874168143337490956e-17 -3.0814879110195773649e-33" />
            <geometry>
                <mesh filename="package:///passivewheel.stl"/>
            </geometry>
        </collision>
        <visual>
            <origin xyz="2.7755575615628913511e-17 0 -4.7704895589362195096e-18" rpy="3.141592653589793116 1.4874168143337490956e-17 -3.0814879110195773649e-33" />
            <geometry>
                <mesh filename="package:///passivewheel.stl"/>
            </geometry>
            <material name="passivewheel_material">
                <color rgba="0.30196078431372547213 0.29019607843137257275 0.26274509803921569651 1.0"/>
            </material>
        </visual>
        <inertial>
            <origin xyz="2.7576423350598049896e-17 -3.8878508430785574613e-19 -0.0020000000000000048121" rpy="0 0 0"/>
            <mass value="0.0028590609658248017193" />
            <inertia ixx="2.7747274432609138953e-08" ixy="-8.550289072782777654e-41"  ixz="4.29636745629682793e-24" iyy="2.7747274432609138953e-08" iyz="-1.2073859865554802375e-39" izz="4.897739425805463138e-08" />
        </inertial>
    </link>

    <joint name="w1_12_passive" type="revolute">
        <origin xyz="0.0020000000000000173889 0.037499999999999991673 -0.0025000000000000160982" rpy="1.4808442108026812057e-16 1.570796326794896558 0" />
        <parent link="wheel" />
        <child link="passivewheel_12" />
        <axis xyz="0 0 1"/>
        <limit effort="1" velocity="20" />
        <joint_properties friction="0.0"/>
    </joint>

    <link name="passivewheel_13">
        <collision>
            <origin xyz="0 0 -1.3010426069826053208e-18" rpy="3.141592653589793116 7.6005314700030557032e-17 3.4000836062698346875e-17" />
            <geometry>
                <mesh filename="package:///passivewheel.stl"/>
            </geometry>
        </collision>
        <visual>
            <origin xyz="0 0 -1.3010426069826053208e-18" rpy="3.141592653589793116 7.6005314700030557032e-17 3.4000836062698346875e-17" />
            <geometry>
                <mesh filename="package:///passivewheel.stl"/>
            </geometry>
            <material name="passivewheel_material">
                <color rgba="0.30196078431372547213 0.29019607843137257275 0.26274509803921569651 1.0"/>
            </material>
        </visual>
        <inertial>
            <origin xyz="8.5319351185389006939e-20 -3.9268826450192511638e-19 -0.0020000000000000017764" rpy="0 0 0"/>
            <mass value="0.0028590609658248017193" />
            <inertia ixx="2.7747274432609138953e-08" ixy="8.222430789516415274e-25"  ixz="-3.8764205523359715114e-24" iyy="2.7747274432609138953e-08" iyz="5.1576301699577572868e-26" izz="4.8977394258054644615e-08" />
        </inertial>
    </link>

    <joint name="w1_13_passive" type="revolute">
        <origin xyz="-0.0096860242564702041246 0.036282653349818144717 -0.0025000000000000160982" rpy="-1.5707963267948970021 1.3942429024899489765 -1.2566370614359188007" />
        <parent link="wheel" />
        <child link="passivewheel_13" />
        <axis xyz="0 0 1"/>
        <limit effort="1" velocity="20" />
        <joint_properties friction="0.0"/>
    </joint>

    <link name="passivewheel_14">
        <collision>
            <origin xyz="0 -6.9388939039072283776e-18 -0.0040000000000000035527" rpy="3.5339169383046097755e-17 1.2857060756905343313e-16 7.1986184521316773997e-18" />
            <geometry>
                <mesh filename="package:///passivewheel.stl"/>
            </geometry>
        </collision>
        <visual>
            <origin xyz="0 -6.9388939039072283776e-18 -0.0040000000000000035527" rpy="3.5339169383046097755e-17 1.2857060756905343313e-16 7.1986184521316773997e-18" />
            <geometry>
                <mesh filename="package:///passivewheel.stl"/>
            </geometry>
            <material name="passivewheel_material">
                <color rgba="0.30196078431372547213 0.29019607843137257275 0.26274509803921569651 1.0"/>
            </material>
        </visual>
        <inertial>
            <origin xyz="9.59088121248229857e-20 -6.3787844047574842771e-18 -0.0020000000000000030774" rpy="0 0 0"/>
            <mass value="0.0028590609658248017193" />
            <inertia ixx="2.7747274432609132335e-08" ixy="7.2189636708855444382e-25"  ixz="-1.5406816034629518575e-24" iyy="2.7747274432609138953e-08" iyz="5.1760773369626793724e-24" izz="4.8977394258054644615e-08" />
        </inertial>
    </link>

    <joint name="w1_14_passive" type="revolute">
        <origin xyz="-0.020423912972217815598 0.031513707793645470701 -0.0025000000000000160982" rpy="-1.5707963267948970021 1.2436334312925148016 -0.94247779607693882298" />
        <parent link="wheel" />
        <child link="passivewheel_14" />
        <axis xyz="0 0 1"/>
        <limit effort="1" velocity="20" />
        <joint_properties friction="0.0"/>
    </joint>

    <link name="passivewheel_15">
        <collision>
            <origin xyz="1.3877787807814456755e-17 6.9388939039072283776e-18 -0.0040000000000000052874" rpy="2.9551949684066360605e-17 6.4680702793369217857e-17 -2.0435621666398590365e-18" />
            <geometry>
                <mesh filename="package:///passivewheel.stl"/>
            </geometry>
        </collision>
        <visual>
            <origin xyz="1.3877787807814456755e-17 6.9388939039072283776e-18 -0.0040000000000000052874" rpy="2.9551949684066360605e-17 6.4680702793369217857e-17 -2.0435621666398590365e-18" />
            <geometry>
                <mesh filename="package:///passivewheel.stl"/>
            </geometry>
            <material name="passivewheel_material">
                <color rgba="0.30196078431372547213 0.29019607843137257275 0.26274509803921569651 1.0"/>
            </material>
        </visual>
        <inertial>
            <origin xyz="1.38446081737515573e-17 7.3508302965683856254e-18 -0.0020000000000000048121" rpy="0 0 0"/>
            <mass value="0.0028590609658248017193" />
            <inertia ixx="2.7747274432609152187e-08" ixy="3.5080217846092293037e-25"  ixz="-2.9291187437266199238e-24" iyy="2.7747274432609138953e-08" iyz="1.3869314363071410057e-24" izz="4.8977394258054644615e-08" />
        </inertial>
    </link>

    <joint name="w1_15_passive" type="revolute">
        <origin xyz="-0.029162566784475565246 0.023659980949717641929 -0.0025000000000000160982" rpy="-1.570796326794896558 1.1338247319171002037 -0.62831853071795873422" />
        <parent link="wheel" />
        <child link="passivewheel_15" />
        <axis xyz="0 0 1"/>
        <limit effort="1" velocity="20" />
        <joint_properties friction="0.0"/>
    </joint>

    <link name="passivewheel_16">
        <collision>
            <origin xyz="6.9388939039072283776e-18 -1.3877787807814456755e-17 -0.0040000000000000000833" rpy="2.0815540962319684379e-17 2.3325222191449634317e-17 -9.4187539408049581448e-18" />
            <geometry>
                <mesh filename="package:///passivewheel.stl"/>
            </geometry>
        </collision>
        <visual>
            <origin xyz="6.9388939039072283776e-18 -1.3877787807814456755e-17 -0.0040000000000000000833" rpy="2.0815540962319684379e-17 2.3325222191449634317e-17 -9.4187539408049581448e-18" />
            <geometry>
                <mesh filename="package:///passivewheel.stl"/>
            </geometry>
            <material name="passivewheel_material">
                <color rgba="0.30196078431372547213 0.29019607843137257275 0.26274509803921569651 1.0"/>
            </material>
        </visual>
        <inertial>
            <origin xyz="6.9731348015477367089e-18 -1.3308876793583039968e-17 -0.001999999999999999608" rpy="0 0 0"/>
            <mass value="0.0028590609658248017193" />
            <inertia ixx="2.7747274432609138953e-08" ixy="-1.7980356864332561743e-25"  ixz="-1.3057589301001113359e-25" iyy="2.7747274432609132335e-08" iyz="4.988623870527148174e-24" izz="4.8977394258054644615e-08" />
        </inertial>
    </link>

    <joint name="w1_16_passive" type="revolute">
        <origin xyz="-0.035046585372318347917 0.013490250321650843618 -0.0025000000000000160982" rpy="-1.57079632679489678 1.068649938797565202 -0.31415926535897920058" />
        <parent link="wheel" />
        <child link="passivewheel_16" />
        <axis xyz="0 0 1"/>
        <limit effort="1" velocity="20" />
        <joint_properties friction="0.0"/>
    </joint>

    <link name="passivewheel_17">
        <collision>
            <origin xyz="0 1.3877787807814456755e-17 0.004000000000000001818" rpy="-3.141592653589793116 5.6927750113195693506e-46 1.5407439555100090038e-33" />
            <geometry>
                <mesh filename="package:///passivewheel.stl"/>
            </geometry>
        </collision>
        <visual>
            <origin xyz="0 1.3877787807814456755e-17 0.004000000000000001818" rpy="-3.141592653589793116 5.6927750113195693506e-46 1.5407439555100090038e-33" />
            <geometry>
                <mesh filename="package:///passivewheel.stl"/>
            </geometry>
            <material name="passivewheel_material">
                <color rgba="0.30196078431372547213 0.29019607843137257275 0.26274509803921569651 1.0"/>
            </material>
        </visual>
        <inertial>
            <origin xyz="1.3144003607491675598e-20 1.3489002723506598987e-17 0.0020000000000000013427" rpy="0 0 0"/>
            <mass value="0.0028590609658248017193" />
            <inertia ixx="2.7747274432609138953e-08" ixy="2.3200516120204129001e-53"  ixz="-7.1559356282578372849e-53" iyy="2.7747274432609138953e-08" iyz="1.8914091123780699049e-39" izz="4.8977394258054644615e-08" />
        </inertial>
    </link>

    <joint name="w1_17_passive" type="revolute">
        <origin xyz="-0.037499999999999984734 0.00200000000000001045 -0.0025000000000000022204" rpy="1.570796326794896558 1.0471975511965980754 -1.1102230246251671407e-16" />
        <parent link="wheel" />
        <child link="passivewheel_17" />
        <axis xyz="0 0 1"/>
        <limit effort="1" velocity="20" />
        <joint_properties friction="0.0"/>
    </joint>

    <link name="passivewheel_18">
        <collision>
            <origin xyz="6.9388939039072283776e-18 -1.3877787807814456755e-17 1.7347234759768070944e-18" rpy="3.141592653589793116 1.5104320982862703616e-17 6.7316026760298097164e-18" />
            <geometry>
                <mesh filename="package:///passivewheel.stl"/>
            </geometry>
        </collision>
        <visual>
            <origin xyz="6.9388939039072283776e-18 -1.3877787807814456755e-17 1.7347234759768070944e-18" rpy="3.141592653589793116 1.5104320982862703616e-17 6.7316026760298097164e-18" />
            <geometry>
                <mesh filename="package:///passivewheel.stl"/>
            </geometry>
            <material name="passivewheel_material">
                <color rgba="0.30196078431372547213 0.29019607843137257275 0.26274509803921569651 1.0"/>
            </material>
        </visual>
        <inertial>
            <origin xyz="6.928413688074689226e-18 -1.4171078014342309384e-17 -0.0019999999999999991743" rpy="0 0 0"/>
            <mass value="0.0028590609658248017193" />
            <inertia ixx="2.7747274432609132335e-08" ixy="1.2903784237169375324e-25"  ixz="1.5942261534687003794e-25" iyy="2.7747274432609132335e-08" iyz="-2.5757979467226097657e-24" izz="4.8977394258054671085e-08" />
        </inertial>
    </link>

    <joint name="w1_18_passive" type="revolute">
        <origin xyz="-0.0362826533498181239 -0.0096860242564702127982 -0.0024999999999999883427" rpy="-1.5707963267948938935 1.0686499387975656461 0.31415926535897814587" />
        <parent link="wheel" />
        <child link="passivewheel_18" />
        <axis xyz="0 0 1"/>
        <limit effort="1" velocity="20" />
        <joint_properties friction="0.0"/>
    </joint>

    <link name="passivewheel_19">
        <collision>
            <origin xyz="-6.9388939039072283776e-18 0 5.2041704279304212832e-18" rpy="-3.141592653589793116 1.3496410181940207346e-18 -1.5245637946293870321e-17" />
            <geometry>
                <mesh filename="package:///passivewheel.stl"/>
            </geometry>
        </collision>
        <visual>
            <origin xyz="-6.9388939039072283776e-18 0 5.2041704279304212832e-18" rpy="-3.141592653589793116 1.3496410181940207346e-18 -1.5245637946293870321e-17" />
            <geometry>
                <mesh filename="package:///passivewheel.stl"/>
            </geometry>
            <material name="passivewheel_material">
                <color rgba="0.30196078431372547213 0.29019607843137257275 0.26274509803921569651 1.0"/>
            </material>
        </visual>
        <inertial>
            <origin xyz="-6.9842151949629750445e-18 -4.6710052572284971106e-19 -0.0019999999999999952711" rpy="0 0 0"/>
            <mass value="0.0028590609658248017193" />
            <inertia ixx="2.7747274432609138953e-08" ixy="3.1869839452145016417e-25"  ixz="1.3942900338500529766e-24" iyy="2.7747274432609152187e-08" iyz="4.9003822723262553069e-24" izz="4.8977394258054644615e-08" />
        </inertial>
    </link>

    <joint name="w1_19_passive" type="revolute">
        <origin xyz="-0.031513707793645470701 -0.020423912972217829476 -0.0025000000000000160982" rpy="-1.5707963267948941155 1.1338247319171006477 0.62831853071795706889" />
        <parent link="wheel" />
        <child link="passivewheel_19" />
        <axis xyz="0 0 1"/>
        <limit effort="1" velocity="20" />
        <joint_properties friction="0.0"/>
    </joint>

    <link name="passivewheel_20">
        <collision>
            <origin xyz="0 0 6.0715321659188248304e-18" rpy="-3.141592653589793116 1.2007284601235612259e-18 -7.2214532127279410078e-17" />
            <geometry>
                <mesh filename="package:///passivewheel.stl"/>
            </geometry>
        </collision>
        <visual>
            <origin xyz="0 0 6.0715321659188248304e-18" rpy="-3.141592653589793116 1.2007284601235612259e-18 -7.2214532127279410078e-17" />
            <geometry>
                <mesh filename="package:///passivewheel.stl"/>
            </geometry>
            <material name="passivewheel_material">
                <color rgba="0.30196078431372547213 0.29019607843137257275 0.26274509803921569651 1.0"/>
            </material>
        </visual>
        <inertial>
            <origin xyz="1.0358631496176200319e-19 -6.879065974045736169e-21 -0.0019999999999999939701" rpy="0 0 0"/>
            <mass value="0.0028590609658248017193" />
            <inertia ixx="2.7747274432609138953e-08" ixy="-2.1175645110053025579e-24"  ixz="-2.2481313125060064923e-24" iyy="2.7747274432609138953e-08" iyz="-8.4380873873483155073e-24" izz="4.897739425805463138e-08" />
        </inertial>
    </link>

    <joint name="w1_20_passive" type="revolute">
        <origin xyz="-0.023659980949717648868 -0.029162566784475575654 -0.002500000000000029976" rpy="-1.5707963267948930053 1.2436334312925152457 0.9424777960769359364" />
        <parent link="wheel" />
        <child link="passivewheel_20" />
        <axis xyz="0 0 1"/>
        <limit effort="1" velocity="20" />
        <joint_properties friction="0.0"/>
    </joint>

    <joint name="wheel1_speed" type="revolute">
        <origin xyz="0.069282032302755147679 -0.039999999999999986955 0.012999999999999999403" rpy="-1.570796326794896558 -0 1.0471975511965980754" />
        <parent link="body" />
        <child link="wheel" />
        <axis xyz="0 0 1"/>
        <limit effort="1" velocity="20" />
        <joint_properties friction="0.0"/>
    </joint>

    <link name="wheel_2">
        <collision>
            <origin xyz="-2.4524884524755275109e-17 -0.013000000000000001138 -0.080000000000000001665" rpy="-1.570796326794896558 -1.0471975511965980754 0" />
            <geometry>
                <mesh filename="package:///wheel.stl"/>
            </geometry>
        </collision>
        <visual>
            <origin xyz="-2.4524884524755275109e-17 -0.013000000000000001138 -0.080000000000000001665" rpy="-1.570796326794896558 -1.0471975511965980754 0" />
            <geometry>
                <mesh filename="package:///wheel.stl"/>
            </geometry>
            <material name="wheel_material">
                <color rgba="0.94117647058823528106 0.87450980392156862919 0.67843137254901964006 1.0"/>
            </material>
        </visual>
        <inertial>
            <origin xyz="-9.2850740984751212181e-11 1.4381200032914653875e-09 -0.0024999999445599677128" rpy="0 0 0"/>
            <mass value="0.01924908488748922758" />
            <inertia ixx="6.8765144932724329979e-06" ixy="-4.7414145390036950856e-13"  ixz="1.4288919017465510263e-14" iyy="6.8765142522306713877e-06" iyz="2.2762036751622368163e-14" izz="1.3673643547259731998e-05" />
        </inertial>
    </link>

    <link name="passivewheel_21">
        <collision>
            <origin xyz="1.3877787807814456755e-17 1.3877787807814456755e-17 0.0040000000000000026854" rpy="3.141592653589793116 1.588839737631802679e-17 -2.1144054105653696368e-17" />
            <geometry>
                <mesh filename="package:///passivewheel.stl"/>
            </geometry>
        </collision>
        <visual>
            <origin xyz="1.3877787807814456755e-17 1.3877787807814456755e-17 0.0040000000000000026854" rpy="3.141592653589793116 1.588839737631802679e-17 -2.1144054105653696368e-17" />
            <geometry>
                <mesh filename="package:///passivewheel.stl"/>
            </geometry>
            <material name="passivewheel_material">
                <color rgba="0.30196078431372547213 0.29019607843137257275 0.26274509803921569651 1.0"/>
            </material>
        </visual>
        <inertial>
            <origin xyz="1.3863729582814696298e-17 1.3639348694924993343e-17 0.0020000000000000026437" rpy="0 0 0"/>
            <mass value="0.0028590609658248017193" />
            <inertia ixx="2.7747274432609138953e-08" ixy="-1.6626958139664610827e-25"  ixz="2.2528741530249790086e-25" iyy="2.7747274432609132335e-08" iyz="-4.2977084004095360008e-24" izz="4.897739425805463138e-08" />
        </inertial>
    </link>

    <joint name="w3_1_passive" type="revolute">
        <origin xyz="-0.01349025032165083321 0.035046585372318361795 -0.0024999999999999744649" rpy="1.570796326794896336 -1.3942429024899474221 1.8849555921538720948" />
        <parent link="wheel_2" />
        <child link="passivewheel_21" />
        <axis xyz="0 0 1"/>
        <limit effort="1" velocity="20" />
        <joint_properties friction="0.0"/>
    </joint>

    <link name="passivewheel_22">
        <collision>
            <origin xyz="0 0 -1.3010426069826053208e-18" rpy="-3.141592653589793116 8.7528123511648235824e-18 6.0237787774954329551e-33" />
            <geometry>
                <mesh filename="package:///passivewheel.stl"/>
            </geometry>
        </collision>
        <visual>
            <origin xyz="0 0 -1.3010426069826053208e-18" rpy="-3.141592653589793116 8.7528123511648235824e-18 6.0237787774954329551e-33" />
            <geometry>
                <mesh filename="package:///passivewheel.stl"/>
            </geometry>
            <material name="passivewheel_material">
                <color rgba="0.30196078431372547213 0.29019607843137257275 0.26274509803921569651 1.0"/>
            </material>
        </visual>
        <inertial>
            <origin xyz="-1.0954871532329177169e-19 -3.8878508430785584243e-19 -0.0020000000000000017764" rpy="0 0 0"/>
            <mass value="0.0028590609658248017193" />
            <inertia ixx="2.7747274432609138953e-08" ixy="-1.0337593659242183066e-39"  ixz="2.761718147467931185e-24" iyy="2.7747274432609138953e-08" iyz="1.4292916685100201133e-39" izz="4.8977394258054644615e-08" />
        </inertial>
    </link>

    <joint name="w3_2_passive" type="revolute">
        <origin xyz="-0.0020000000000000061132 0.037499999999999991673 -0.0024999999999999744649" rpy="9.8607613152626344305e-32 -1.570796326794896336 0" />
        <parent link="wheel_2" />
        <child link="passivewheel_22" />
        <axis xyz="0 0 1"/>
        <limit effort="1" velocity="20" />
        <joint_properties friction="0.0"/>
    </joint>

    <link name="passivewheel_23">
        <collision>
            <origin xyz="-2.7755575615628913511e-17 6.9388939039072283776e-18 8.6736173798840354721e-19" rpy="2.4867400122110584334e-17 -6.0459534800813790139e-17 -2.5094327585150125538e-17" />
            <geometry>
                <mesh filename="package:///passivewheel.stl"/>
            </geometry>
        </collision>
        <visual>
            <origin xyz="-2.7755575615628913511e-17 6.9388939039072283776e-18 8.6736173798840354721e-19" rpy="2.4867400122110584334e-17 -6.0459534800813790139e-17 -2.5094327585150125538e-17" />
            <geometry>
                <mesh filename="package:///passivewheel.stl"/>
            </geometry>
            <material name="passivewheel_material">
                <color rgba="0.30196078431372547213 0.29019607843137257275 0.26274509803921569651 1.0"/>
            </material>
        </visual>
        <inertial>
            <origin xyz="-2.8059443161984962639e-17 7.2649696683370143127e-18 0.002000000000000000909" rpy="0 0 0"/>
            <mass value="0.0028590609658248017193" />
            <inertia ixx="2.7747274432609138953e-08" ixy="-2.8214545285185205807e-25"  ixz="-6.0856125292746512702e-24" iyy="2.7747274432609138953e-08" iyz="-8.4566696604766690639e-25" izz="4.897739425805463138e-08" />
        </inertial>
    </link>

    <joint name="w3_3_passive" type="revolute">
        <origin xyz="0.0096860242564702249413 0.036282653349818151656 -0.0024999999999999744649" rpy="-1.570796326794896336 -1.3942429024899476442 -1.8849555921538700964" />
        <parent link="wheel_2" />
        <child link="passivewheel_23" />
        <axis xyz="0 0 1"/>
        <limit effort="1" velocity="20" />
        <joint_properties friction="0.0"/>
    </joint>

    <link name="passivewheel_24">
        <collision>
            <origin xyz="0 -3.4694469519536141888e-18 1.7347234759768070944e-18" rpy="3.141592653589793116 6.7326892476616911829e-17 6.093277025662465445e-17" />
            <geometry>
                <mesh filename="package:///passivewheel.stl"/>
            </geometry>
        </collision>
        <visual>
            <origin xyz="0 -3.4694469519536141888e-18 1.7347234759768070944e-18" rpy="3.141592653589793116 6.7326892476616911829e-17 6.093277025662465445e-17" />
            <geometry>
                <mesh filename="package:///passivewheel.stl"/>
            </geometry>
            <material name="passivewheel_material">
                <color rgba="0.30196078431372547213 0.29019607843137257275 0.26274509803921569651 1.0"/>
            </material>
        </visual>
        <inertial>
            <origin xyz="2.7640851665307859234e-20 -3.9576905023284255706e-18 -0.0019999999999999987406" rpy="0 0 0"/>
            <mass value="0.0028590609658248017193" />
            <inertia ixx="2.7747274432609132335e-08" ixy="1.7954333292338777512e-24"  ixz="-2.2231466836568448836e-24" iyy="2.7747274432609138953e-08" iyz="1.7256460825159017299e-24" izz="4.8977394258054644615e-08" />
        </inertial>
    </link>

    <joint name="w3_4_passive" type="revolute">
        <origin xyz="0.020423912972217822537 0.031513707793645477639 -0.0024999999999999744649" rpy="1.570796326794896558 -1.2436334312925134693 -2.1991148575128431908" />
        <parent link="wheel_2" />
        <child link="passivewheel_24" />
        <axis xyz="0 0 1"/>
        <limit effort="1" velocity="20" />
        <joint_properties friction="0.0"/>
    </joint>

    <link name="passivewheel_25">
        <collision>
            <origin xyz="0 -2.6020852139652106416e-18 -1.7347234759768070944e-18" rpy="3.141592653589793116 1.2686448352393286238e-17 3.232191850791916046e-18" />
            <geometry>
                <mesh filename="package:///passivewheel.stl"/>
            </geometry>
        </collision>
        <visual>
            <origin xyz="0 -2.6020852139652106416e-18 -1.7347234759768070944e-18" rpy="3.141592653589793116 1.2686448352393286238e-17 3.232191850791916046e-18" />
            <geometry>
                <mesh filename="package:///passivewheel.stl"/>
            </geometry>
            <material name="passivewheel_material">
                <color rgba="0.30196078431372547213 0.29019607843137257275 0.26274509803921569651 1.0"/>
            </material>
        </visual>
        <inertial>
            <origin xyz="1.1085800567942901451e-21 -2.816788376896614595e-18 -0.00200000000000000221" rpy="0 0 0"/>
            <mass value="0.0028590609658248017193" />
            <inertia ixx="2.7747274432609138953e-08" ixy="3.9152888402175232178e-25"  ixz="-5.7282521856387848242e-26" iyy="2.7747274432609138953e-08" iyz="-4.4787734403613652717e-24" izz="4.8977394258054644615e-08" />
        </inertial>
    </link>

    <joint name="w3_5_passive" type="revolute">
        <origin xyz="0.029162566784475579124 0.023659980949717641929 -0.0024999999999999883427" rpy="1.57079632679489678 -1.1338247319170990934 -2.5132741228718233906" />
        <parent link="wheel_2" />
        <child link="passivewheel_25" />
        <axis xyz="0 0 1"/>
        <limit effort="1" velocity="20" />
        <joint_properties friction="0.0"/>
    </joint>

    <link name="passivewheel_26">
        <collision>
            <origin xyz="0 4.336808689942017736e-19 -1.7347234759768070944e-18" rpy="-3.141592653589793116 -1.062604576121794328e-17 3.2626277555443630867e-18" />
            <geometry>
                <mesh filename="package:///passivewheel.stl"/>
            </geometry>
        </collision>
        <visual>
            <origin xyz="0 4.336808689942017736e-19 -1.7347234759768070944e-18" rpy="-3.141592653589793116 -1.062604576121794328e-17 3.2626277555443630867e-18" />
            <geometry>
                <mesh filename="package:///passivewheel.stl"/>
            </geometry>
            <material name="passivewheel_material">
                <color rgba="0.30196078431372547213 0.29019607843137257275 0.26274509803921569651 1.0"/>
            </material>
        </visual>
        <inertial>
            <origin xyz="-2.1080151504099763172e-20 4.5978710076217554119e-20 -0.00200000000000000221" rpy="0 0 0"/>
            <mass value="0.0028590609658248017193" />
            <inertia ixx="2.7747274432609152187e-08" ixy="3.5863134406022050051e-26"  ixz="1.1329487768945923552e-24" iyy="2.7747274432609132335e-08" iyz="1.760784014601400988e-24" izz="4.8977394258054644615e-08" />
        </inertial>
    </link>

    <joint name="w3_6_passive" type="revolute">
        <origin xyz="0.035046585372318347917 0.013490250321650838414 -0.0024999999999999605871" rpy="1.570796326794896336 -1.0686499387975645359 -2.8274333882308080312" />
        <parent link="wheel_2" />
        <child link="passivewheel_26" />
        <axis xyz="0 0 1"/>
        <limit effort="1" velocity="20" />
        <joint_properties friction="0.0"/>
    </joint>

    <link name="passivewheel_27">
        <collision>
            <origin xyz="0 -3.4694469519536141888e-18 -0.0040000000000000000833" rpy="-1.9721522630552270131e-31 -9.8607613152487747128e-32 2.157041537718000011e-32" />
            <geometry>
                <mesh filename="package:///passivewheel.stl"/>
            </geometry>
        </collision>
        <visual>
            <origin xyz="0 -3.4694469519536141888e-18 -0.0040000000000000000833" rpy="-1.9721522630552270131e-31 -9.8607613152487747128e-32 2.157041537718000011e-32" />
            <geometry>
                <mesh filename="package:///passivewheel.stl"/>
            </geometry>
            <material name="passivewheel_material">
                <color rgba="0.30196078431372547213 0.29019607843137257275 0.26274509803921569651 1.0"/>
            </material>
        </visual>
        <inertial>
            <origin xyz="1.3144003607491478492e-20 -3.0806618676457587316e-18 -0.001999999999999999608" rpy="0 0 0"/>
            <mass value="0.0028590609658248017193" />
            <inertia ixx="2.7747274432609138953e-08" ixy="-1.7100578145613461239e-40"  ixz="-2.0934514429147132918e-39" iyy="2.7747274432609138953e-08" iyz="-1.5131272898998891301e-38" izz="4.8977394258054644615e-08" />
        </inertial>
    </link>

    <joint name="w3_7_passive" type="revolute">
        <origin xyz="0.037499999999999998612 0.0020000000000000052458 -0.0024999999999999744649" rpy="1.5707963267948938935 -1.0471975511965967431 3.1415926535897917837" />
        <parent link="wheel_2" />
        <child link="passivewheel_27" />
        <axis xyz="0 0 1"/>
        <limit effort="1" velocity="20" />
        <joint_properties friction="0.0"/>
    </joint>

    <link name="passivewheel_28">
        <collision>
            <origin xyz="1.3877787807814456755e-17 0 0.0040000000000000000833" rpy="3.141592653589793116 -4.882488366120950769e-18 4.7854877233039646343e-19" />
            <geometry>
                <mesh filename="package:///passivewheel.stl"/>
            </geometry>
        </collision>
        <visual>
            <origin xyz="1.3877787807814456755e-17 0 0.0040000000000000000833" rpy="3.141592653589793116 -4.882488366120950769e-18 4.7854877233039646343e-19" />
            <geometry>
                <mesh filename="package:///passivewheel.stl"/>
            </geometry>
            <material name="passivewheel_material">
                <color rgba="0.30196078431372547213 0.29019607843137257275 0.26274509803921569651 1.0"/>
            </material>
        </visual>
        <inertial>
            <origin xyz="1.3891404170615629552e-17 -3.3282172198687012123e-19 0.001999999999999999608" rpy="0 0 0"/>
            <mass value="0.0028590609658248017193" />
            <inertia ixx="2.7747274432609138953e-08" ixy="1.0771779218686171972e-25"  ixz="1.2390828337864395725e-25" iyy="2.7747274432609138953e-08" iyz="-1.5153514521365081538e-24" izz="4.8977394258054644615e-08" />
        </inertial>
    </link>

    <joint name="w3_8_passive" type="revolute">
        <origin xyz="0.036282653349818144717 -0.0096860242564702162676 -0.0024999999999999883427" rpy="-1.57079632679489678 -1.0686499387975643138 2.827433388230806699" />
        <parent link="wheel_2" />
        <child link="passivewheel_28" />
        <axis xyz="0 0 1"/>
        <limit effort="1" velocity="20" />
        <joint_properties friction="0.0"/>
    </joint>

    <link name="passivewheel_29">
        <collision>
            <origin xyz="1.3877787807814456755e-17 1.7347234759768070944e-18 -0.0039999999999999983485" rpy="2.3466876340876330183e-17 2.6850575910324388113e-17 5.5004626049315720055e-18" />
            <geometry>
                <mesh filename="package:///passivewheel.stl"/>
            </geometry>
        </collision>
        <visual>
            <origin xyz="1.3877787807814456755e-17 1.7347234759768070944e-18 -0.0039999999999999983485" rpy="2.3466876340876330183e-17 2.6850575910324388113e-17 5.5004626049315720055e-18" />
            <geometry>
                <mesh filename="package:///passivewheel.stl"/>
            </geometry>
            <material name="passivewheel_material">
                <color rgba="0.30196078431372547213 0.29019607843137257275 0.26274509803921569651 1.0"/>
            </material>
        </visual>
        <inertial>
            <origin xyz="1.3934306305445495775e-17 2.044465595225455292e-18 -0.0019999999999999978732" rpy="0 0 0"/>
            <mass value="0.0028590609658248017193" />
            <inertia ixx="2.7747274432609138953e-08" ixy="6.3465958976455254393e-25"  ixz="3.1715454881006856123e-25" iyy="2.7747274432609138953e-08" iyz="-1.2845173736088264376e-24" izz="4.8977394258054644615e-08" />
        </inertial>
    </link>

    <joint name="w3_9_passive" type="revolute">
        <origin xyz="0.031513707793645477639 -0.020423912972217836415 -0.0024999999999999605871" rpy="1.570796326794896336 -1.1338247319170990934 2.5132741228718220583" />
        <parent link="wheel_2" />
        <child link="passivewheel_29" />
        <axis xyz="0 0 1"/>
        <limit effort="1" velocity="20" />
        <joint_properties friction="0.0"/>
    </joint>

    <link name="passivewheel_30">
        <collision>
            <origin xyz="0 2.0599841277224584246e-18 0" rpy="-3.141592653589793116 4.8268233694740457199e-17 -4.6228937368023756984e-17" />
            <geometry>
                <mesh filename="package:///passivewheel.stl"/>
            </geometry>
        </collision>
        <visual>
            <origin xyz="0 2.0599841277224584246e-18 0" rpy="-3.141592653589793116 4.8268233694740457199e-17 -4.6228937368023756984e-17" />
            <geometry>
                <mesh filename="package:///passivewheel.stl"/>
            </geometry>
            <material name="passivewheel_material">
                <color rgba="0.30196078431372547213 0.29019607843137257275 0.26274509803921569651 1.0"/>
            </material>
        </visual>
        <inertial>
            <origin xyz="-4.9323721035098106288e-20 1.5791311253584447974e-18 -0.0020000000000000004753" rpy="0 0 0"/>
            <mass value="0.0028590609658248017193" />
            <inertia ixx="2.7747274432609138953e-08" ixy="-5.5378200374576852853e-25"  ixz="1.9044126240658215277e-25" iyy="2.7747274432609138953e-08" iyz="3.352267832324266293e-24" izz="4.8977394258054644615e-08" />
        </inertial>
    </link>

    <joint name="w3_10_passive" type="revolute">
        <origin xyz="0.02365998094971763846 -0.029162566784475561776 -0.0024999999999999883427" rpy="1.570796326794896558 -1.2436334312925134693 2.1991148575128445231" />
        <parent link="wheel_2" />
        <child link="passivewheel_30" />
        <axis xyz="0 0 1"/>
        <limit effort="1" velocity="20" />
        <joint_properties friction="0.0"/>
    </joint>

    <link name="passivewheel_31">
        <collision>
            <origin xyz="1.3877787807814456755e-17 0 4.336808689942017736e-18" rpy="3.141592653589793116 3.7632137412847723814e-17 9.2376249921293862455e-18" />
            <geometry>
                <mesh filename="package:///passivewheel.stl"/>
            </geometry>
        </collision>
        <visual>
            <origin xyz="1.3877787807814456755e-17 0 4.336808689942017736e-18" rpy="3.141592653589793116 3.7632137412847723814e-17 9.2376249921293862455e-18" />
            <geometry>
                <mesh filename="package:///passivewheel.stl"/>
            </geometry>
            <material name="passivewheel_material">
                <color rgba="0.30196078431372547213 0.29019607843137257275 0.26274509803921569651 1.0"/>
            </material>
        </visual>
        <inertial>
            <origin xyz="1.3845278489622160686e-17 -4.866480552674828737e-19 -0.0019999999999999961385" rpy="0 0 0"/>
            <mass value="0.0028590609658248017193" />
            <inertia ixx="2.7747274432609138953e-08" ixy="-4.4042049468994306876e-25"  ixz="7.3801126209039338604e-26" iyy="2.7747274432609132335e-08" iyz="1.7108530910632692265e-24" izz="4.8977394258054644615e-08" />
        </inertial>
    </link>

    <joint name="w3_11_passive" type="revolute">
        <origin xyz="0.013490250321650855761 -0.035046585372318347917 -0.0024999999999999883427" rpy="1.5707963267948945596 -1.3942429024899476442 1.8849555921538723169" />
        <parent link="wheel_2" />
        <child link="passivewheel_31" />
        <axis xyz="0 0 1"/>
        <limit effort="1" velocity="20" />
        <joint_properties friction="0.0"/>
    </joint>

    <link name="passivewheel_32">
        <collision>
            <origin xyz="1.3877787807814456755e-17 0 -7.3725747729014301513e-18" rpy="3.141592653589793116 -2.1777293602490363178e-17 0" />
            <geometry>
                <mesh filename="package:///passivewheel.stl"/>
            </geometry>
        </collision>
        <visual>
            <origin xyz="1.3877787807814456755e-17 0 -7.3725747729014301513e-18" rpy="3.141592653589793116 -2.1777293602490363178e-17 0" />
            <geometry>
                <mesh filename="package:///passivewheel.stl"/>
            </geometry>
            <material name="passivewheel_material">
                <color rgba="0.30196078431372547213 0.29019607843137257275 0.26274509803921569651 1.0"/>
            </material>
        </visual>
        <inertial>
            <origin xyz="1.4061450786457814586e-17 -3.8878508430785584243e-19 -0.0020000000000000074142" rpy="0 0 0"/>
            <mass value="0.0028590609658248017193" />
            <inertia ixx="2.7747274432609138953e-08" ixy="1.0687861340978458048e-41"  ixz="-3.571526992417674736e-24" iyy="2.7747274432609138953e-08" iyz="-3.4201156291131065755e-40" izz="4.897739425805463138e-08" />
        </inertial>
    </link>

    <joint name="w3_12_passive" type="revolute">
        <origin xyz="0.0020000000000000113173 -0.037499999999999991673 -0.0024999999999999744649" rpy="-3.141592653589793116 -1.570796326794896336 0" />
        <parent link="wheel_2" />
        <child link="passivewheel_32" />
        <axis xyz="0 0 1"/>
        <limit effort="1" velocity="20" />
        <joint_properties friction="0.0"/>
    </joint>

    <link name="passivewheel_33">
        <collision>
            <origin xyz="0 0 8.6736173798840354721e-19" rpy="3.141592653589793116 -4.3687519342455411596e-17 -1.1247906280202580235e-17" />
            <geometry>
                <mesh filename="package:///passivewheel.stl"/>
            </geometry>
        </collision>
        <visual>
            <origin xyz="0 0 8.6736173798840354721e-19" rpy="3.141592653589793116 -4.3687519342455411596e-17 -1.1247906280202580235e-17" />
            <geometry>
                <mesh filename="package:///passivewheel.stl"/>
            </geometry>
            <material name="passivewheel_material">
                <color rgba="0.30196078431372547213 0.29019607843137257275 0.26274509803921569651 1.0"/>
            </material>
        </visual>
        <inertial>
            <origin xyz="-4.9974397631083975222e-21 -2.8891905698926124572e-19 -0.001999999999999999608" rpy="0 0 0"/>
            <mass value="0.0028590609658248017193" />
            <inertia ixx="2.7747274432609138953e-08" ixy="-5.3620142900914166417e-25"  ixz="1.6564699006610561621e-24" iyy="2.7747274432609132335e-08" iyz="-2.9773053943313251792e-24" izz="4.8977394258054644615e-08" />
        </inertial>
    </link>

    <joint name="w3_13_passive" type="revolute">
        <origin xyz="-0.0096860242564702093288 -0.036282653349818144717 -0.0024999999999999744649" rpy="-1.5707963267948958919 -1.3942429024899476442 -1.8849555921538718728" />
        <parent link="wheel_2" />
        <child link="passivewheel_33" />
        <axis xyz="0 0 1"/>
        <limit effort="1" velocity="20" />
        <joint_properties friction="0.0"/>
    </joint>

    <link name="passivewheel_34">
        <collision>
            <origin xyz="0 -6.9388939039072283776e-18 -0.0039999999999999940117" rpy="-6.2932144094926240948e-17 7.7359787068982304428e-18 1.0424787038990604622e-17" />
            <geometry>
                <mesh filename="package:///passivewheel.stl"/>
            </geometry>
        </collision>
        <visual>
            <origin xyz="0 -6.9388939039072283776e-18 -0.0039999999999999940117" rpy="-6.2932144094926240948e-17 7.7359787068982304428e-18 1.0424787038990604622e-17" />
            <geometry>
                <mesh filename="package:///passivewheel.stl"/>
            </geometry>
            <material name="passivewheel_material">
                <color rgba="0.30196078431372547213 0.29019607843137257275 0.26274509803921569651 1.0"/>
            </material>
        </visual>
        <inertial>
            <origin xyz="5.0127690977002308532e-21 -6.4376604233522946508e-18 -0.0019999999999999939701" rpy="0 0 0"/>
            <mass value="0.0028590609658248017193" />
            <inertia ixx="2.7747274432609138953e-08" ixy="-9.0505540410161245851e-25"  ixz="-4.13775663380503058e-25" iyy="2.7747274432609138953e-08" iyz="1.0075192455050837813e-24" izz="4.897739425805463138e-08" />
        </inertial>
    </link>

    <joint name="w3_14_passive" type="revolute">
        <origin xyz="-0.020423912972217812128 -0.031513707793645470701 -0.0024999999999999883427" rpy="-1.570796326794896558 -1.2436334312925139134 -2.1991148575128436349" />
        <parent link="wheel_2" />
        <child link="passivewheel_34" />
        <axis xyz="0 0 1"/>
        <limit effort="1" velocity="20" />
        <joint_properties friction="0.0"/>
    </joint>

    <link name="passivewheel_35">
        <collision>
            <origin xyz="0 6.9388939039072283776e-18 -0.0040000000000000000833" rpy="9.7836374262210272872e-17 4.0089083709518006613e-18 -2.5751613999071144278e-17" />
            <geometry>
                <mesh filename="package:///passivewheel.stl"/>
            </geometry>
        </collision>
        <visual>
            <origin xyz="0 6.9388939039072283776e-18 -0.0040000000000000000833" rpy="9.7836374262210272872e-17 4.0089083709518006613e-18 -2.5751613999071144278e-17" />
            <geometry>
                <mesh filename="package:///passivewheel.stl"/>
            </geometry>
            <material name="passivewheel_material">
                <color rgba="0.30196078431372547213 0.29019607843137257275 0.26274509803921569651 1.0"/>
            </material>
        </visual>
        <inertial>
            <origin xyz="-9.435184819763592228e-20 7.1336117711989546907e-18 -0.001999999999999999608" rpy="0 0 0"/>
            <mass value="0.0028590609658248017193" />
            <inertia ixx="2.7747274432609138953e-08" ixy="-1.8972677166412156952e-25"  ixz="-2.7436696382265580701e-24" iyy="2.7747274432609138953e-08" iyz="-2.0377605740362109538e-24" izz="4.8977394258054644615e-08" />
        </inertial>
    </link>

    <joint name="w3_15_passive" type="revolute">
        <origin xyz="-0.02916256678447559994 -0.023659980949717641929 -0.0024999999999999744649" rpy="-1.57079632679489678 -1.1338247319170995375 -2.5132741228718229465" />
        <parent link="wheel_2" />
        <child link="passivewheel_35" />
        <axis xyz="0 0 1"/>
        <limit effort="1" velocity="20" />
        <joint_properties friction="0.0"/>
    </joint>

    <link name="passivewheel_36">
        <collision>
            <origin xyz="0 0 -0.0039999999999999983485" rpy="-3.1122941480890448544e-17 5.7689532162848557285e-17 -1.3722917839065559143e-17" />
            <geometry>
                <mesh filename="package:///passivewheel.stl"/>
            </geometry>
        </collision>
        <visual>
            <origin xyz="0 0 -0.0039999999999999983485" rpy="-3.1122941480890448544e-17 5.7689532162848557285e-17 -1.3722917839065559143e-17" />
            <geometry>
                <mesh filename="package:///passivewheel.stl"/>
            </geometry>
            <material name="passivewheel_material">
                <color rgba="0.30196078431372547213 0.29019607843137257275 0.26274509803921569651 1.0"/>
            </material>
        </visual>
        <inertial>
            <origin xyz="-7.0113454038893982985e-20 2.6152511733072497638e-19 -0.0019999999999999983069" rpy="0 0 0"/>
            <mass value="0.0028590609658248017193" />
            <inertia ixx="2.7747274432609138953e-08" ixy="-4.1531813406688685718e-25"  ixz="-3.6395939448465482481e-24" iyy="2.7747274432609138953e-08" iyz="-3.9800075863732780935e-24" izz="4.897739425805463138e-08" />
        </inertial>
    </link>

    <joint name="w3_16_passive" type="revolute">
        <origin xyz="-0.035046585372318354856 -0.013490250321650843618 -0.0024999999999999744649" rpy="-1.570796326794896558 -1.0686499387975647579 -2.8274333882308080312" />
        <parent link="wheel_2" />
        <child link="passivewheel_36" />
        <axis xyz="0 0 1"/>
        <limit effort="1" velocity="20" />
        <joint_properties friction="0.0"/>
    </joint>

    <link name="passivewheel_37">
        <collision>
            <origin xyz="0 1.3877787807814456755e-17 0.0040000000000000000833" rpy="-3.141592653589793116 5.6927750113195693506e-46 1.5407439555100090038e-33" />
            <geometry>
                <mesh filename="package:///passivewheel.stl"/>
            </geometry>
        </collision>
        <visual>
            <origin xyz="0 1.3877787807814456755e-17 0.0040000000000000000833" rpy="-3.141592653589793116 5.6927750113195693506e-46 1.5407439555100090038e-33" />
            <geometry>
                <mesh filename="package:///passivewheel.stl"/>
            </geometry>
            <material name="passivewheel_material">
                <color rgba="0.30196078431372547213 0.29019607843137257275 0.26274509803921569651 1.0"/>
            </material>
        </visual>
        <inertial>
            <origin xyz="1.3144003607491675598e-20 1.3489002723506598987e-17 0.001999999999999999608" rpy="0 0 0"/>
            <mass value="0.0028590609658248017193" />
            <inertia ixx="2.7747274432609138953e-08" ixy="2.3200516120204129001e-53"  ixz="-7.1559356282578372849e-53" iyy="2.7747274432609138953e-08" iyz="1.8914091123780699049e-39" izz="4.8977394258054644615e-08" />
        </inertial>
    </link>

    <joint name="w3_17_passive" type="revolute">
        <origin xyz="-0.037499999999999991673 -0.00200000000000001045 -0.0024999999999999605871" rpy="1.5707963267948978903 -1.0471975511965974093 3.141592653589793116" />
        <parent link="wheel_2" />
        <child link="passivewheel_37" />
        <axis xyz="0 0 1"/>
        <limit effort="1" velocity="20" />
        <joint_properties friction="0.0"/>
    </joint>

    <link name="passivewheel_38">
        <collision>
            <origin xyz="0 0 0" rpy="3.141592653589793116 -7.5081381232081935584e-18 1.9294710559903498435e-18" />
            <geometry>
                <mesh filename="package:///passivewheel.stl"/>
            </geometry>
        </collision>
        <visual>
            <origin xyz="0 0 0" rpy="3.141592653589793116 -7.5081381232081935584e-18 1.9294710559903498435e-18" />
            <geometry>
                <mesh filename="package:///passivewheel.stl"/>
            </geometry>
            <material name="passivewheel_material">
                <color rgba="0.30196078431372547213 0.29019607843137257275 0.26274509803921569651 1.0"/>
            </material>
        </visual>
        <inertial>
            <origin xyz="-5.2327050485749279973e-20 -2.9812751753200311083e-19 -0.0020000000000000000416" rpy="0 0 0"/>
            <mass value="0.0028590609658248017193" />
            <inertia ixx="2.7747274432609132335e-08" ixy="1.583089527735654864e-25"  ixz="1.8116311833901342587e-24" iyy="2.7747274432609138953e-08" iyz="-3.2432274571662518619e-24" izz="4.897739425805463138e-08" />
        </inertial>
    </link>

    <joint name="w3_18_passive" type="revolute">
        <origin xyz="-0.036282653349818130839 0.0096860242564702127982 -0.0024999999999999883427" rpy="-1.570796326794896336 -1.0686499387975638697 2.827433388230806699" />
        <parent link="wheel_2" />
        <child link="passivewheel_38" />
        <axis xyz="0 0 1"/>
        <limit effort="1" velocity="20" />
        <joint_properties friction="0.0"/>
    </joint>

    <link name="passivewheel_39">
        <collision>
            <origin xyz="0 0 -3.4694469519536141888e-18" rpy="-3.141592653589793116 1.1348276211869118125e-17 -2.9998065824634806655e-18" />
            <geometry>
                <mesh filename="package:///passivewheel.stl"/>
            </geometry>
        </collision>
        <visual>
            <origin xyz="0 0 -3.4694469519536141888e-18" rpy="-3.141592653589793116 1.1348276211869118125e-17 -2.9998065824634806655e-18" />
            <geometry>
                <mesh filename="package:///passivewheel.stl"/>
            </geometry>
            <material name="passivewheel_material">
                <color rgba="0.30196078431372547213 0.29019607843137257275 0.26274509803921569651 1.0"/>
            </material>
        </visual>
        <inertial>
            <origin xyz="-1.8325646666161096803e-20 -3.0869362364870108151e-19 -0.0020000000000000039448" rpy="0 0 0"/>
            <mass value="0.0028590609658248017193" />
            <inertia ixx="2.7747274432609152187e-08" ixy="1.5498500937106406337e-25"  ixz="4.5576699992011170113e-25" iyy="2.7747274432609132335e-08" iyz="-9.3835266313226708676e-25" izz="4.8977394258054644615e-08" />
        </inertial>
    </link>

    <joint name="w3_19_passive" type="revolute">
        <origin xyz="-0.031513707793645470701 0.020423912972217829476 -0.0024999999999999744649" rpy="-1.570796326794896558 -1.1338247319170982053 2.5132741228718216142" />
        <parent link="wheel_2" />
        <child link="passivewheel_39" />
        <axis xyz="0 0 1"/>
        <limit effort="1" velocity="20" />
        <joint_properties friction="0.0"/>
    </joint>

    <link name="passivewheel_40">
        <collision>
            <origin xyz="0 1.3877787807814456755e-17 -4.336808689942017736e-18" rpy="3.141592653589793116 -2.7045188105149930583e-17 -2.5344537095918517171e-17" />
            <geometry>
                <mesh filename="package:///passivewheel.stl"/>
            </geometry>
        </collision>
        <visual>
            <origin xyz="0 1.3877787807814456755e-17 -4.336808689942017736e-18" rpy="3.141592653589793116 -2.7045188105149930583e-17 -2.5344537095918517171e-17" />
            <geometry>
                <mesh filename="package:///passivewheel.stl"/>
            </geometry>
            <material name="passivewheel_material">
                <color rgba="0.30196078431372547213 0.29019607843137257275 0.26274509803921569651 1.0"/>
            </material>
        </visual>
        <inertial>
            <origin xyz="4.883189243643719114e-20 1.3264723027919856203e-17 -0.0020000000000000048121" rpy="0 0 0"/>
            <mass value="0.0028590609658248017193" />
            <inertia ixx="2.7747274432609138953e-08" ixy="1.1380052292860255804e-24"  ixz="-1.2351964427131325723e-25" iyy="2.7747274432609152187e-08" iyz="3.5294894577681889104e-24" izz="4.8977394258054644615e-08" />
        </inertial>
    </link>

    <joint name="w3_20_passive" type="revolute">
        <origin xyz="-0.023659980949717666215 0.029162566784475582593 -0.0024999999999999605871" rpy="-1.57079632679489678 -1.243633431292512137 2.1991148575128405263" />
        <parent link="wheel_2" />
        <child link="passivewheel_40" />
        <axis xyz="0 0 1"/>
        <limit effort="1" velocity="20" />
        <joint_properties friction="0.0"/>
    </joint>

    <joint name="wheel3_speed" type="revolute">
        <origin xyz="-0.06928203230275507829 -0.040000000000000070222 0.012999999999999999403" rpy="1.570796326794896558 -0 2.0943951023931961508" />
        <parent link="body" />
        <child link="wheel_2" />
        <axis xyz="0 0 1"/>
        <limit effort="1" velocity="20" />
        <joint_properties friction="0.0"/>
    </joint>

    <link name="wheel_3">
        <collision>
            <origin xyz="-7.1248210056989328012e-18 0.013000000000000001138 0.07500000000000002498" rpy="1.570796326794896558 1.0471975511965980754 0" />
            <geometry>
                <mesh filename="package:///wheel.stl"/>
            </geometry>
        </collision>
        <visual>
            <origin xyz="-7.1248210056989328012e-18 0.013000000000000001138 0.07500000000000002498" rpy="1.570796326794896558 1.0471975511965980754 0" />
            <geometry>
                <mesh filename="package:///wheel.stl"/>
            </geometry>
            <material name="wheel_material">
                <color rgba="0.94117647058823528106 0.87450980392156862919 0.67843137254901964006 1.0"/>
            </material>
        </visual>
        <inertial>
            <origin xyz="-9.2850727106963404367e-11 -1.4381200032914653875e-09 -0.0025000000554400020336" rpy="0 0 0"/>
            <mass value="0.01924908488748922758" />
            <inertia ixx="6.8765144932724321509e-06" ixy="4.7414145390036950856e-13"  ixz="-1.4288918170432563009e-14" iyy="6.8765142522306713877e-06" iyz="2.2762036751622393407e-14" izz="1.367364354725972861e-05" />
        </inertial>
    </link>

    <link name="passivewheel_41">
        <collision>
            <origin xyz="0 0 0.0040000000000000000833" rpy="3.141592653589793116 -3.6128666986922277916e-18 1.1996293612747033489e-17" />
            <geometry>
                <mesh filename="package:///passivewheel.stl"/>
            </geometry>
        </collision>
        <visual>
            <origin xyz="0 0 0.0040000000000000000833" rpy="3.141592653589793116 -3.6128666986922277916e-18 1.1996293612747033489e-17" />
            <geometry>
                <mesh filename="package:///passivewheel.stl"/>
            </geometry>
            <material name="passivewheel_material">
                <color rgba="0.30196078431372547213 0.29019607843137257275 0.26274509803921569651 1.0"/>
            </material>
        </visual>
        <inertial>
            <origin xyz="3.3426973102980285356e-21 -5.0575809627011528176e-19 0.001999999999999999608" rpy="0 0 0"/>
            <mass value="0.0028590609658248017193" />
            <inertia ixx="2.7747274432609152187e-08" ixy="-3.8699834064473393929e-25"  ixz="3.4026842515785166523e-25" iyy="2.7747274432609132335e-08" iyz="2.3321831628382024989e-24" izz="4.8977394258054644615e-08" />
        </inertial>
    </link>

    <joint name="w2_1_passive" type="revolute">
        <origin xyz="-0.013490250321650821066 -0.035046585372318347917 -0.0025000000000000022204" rpy="-1.5707963267948950037 -1.3942429024899474221 -1.8849555921538756476" />
        <parent link="wheel_3" />
        <child link="passivewheel_41" />
        <axis xyz="0 0 1"/>
        <limit effort="1" velocity="20" />
        <joint_properties friction="0.0"/>
    </joint>

    <link name="passivewheel_42">
        <collision>
            <origin xyz="0 3.4694469519536141888e-18 0" rpy="-3.141592653589793116 6.2985913561852352134e-32 -3.0730707173339120466e-32" />
            <geometry>
                <mesh filename="package:///passivewheel.stl"/>
            </geometry>
        </collision>
        <visual>
            <origin xyz="0 3.4694469519536141888e-18 0" rpy="-3.141592653589793116 6.2985913561852352134e-32 -3.0730707173339120466e-32" />
            <geometry>
                <mesh filename="package:///passivewheel.stl"/>
            </geometry>
            <material name="passivewheel_material">
                <color rgba="0.30196078431372547213 0.29019607843137257275 0.26274509803921569651 1.0"/>
            </material>
        </visual>
        <inertial>
            <origin xyz="1.3144003607491725251e-20 3.0806618676457579612e-18 -0.0020000000000000004753" rpy="0 0 0"/>
            <mass value="0.0028590609658248017193" />
            <inertia ixx="2.7747274432609138953e-08" ixy="-1.0337593659244953058e-39"  ixz="-2.9550734155447394345e-39" iyy="2.7747274432609138953e-08" iyz="1.7291354310178474619e-39" izz="4.8977394258054644615e-08" />
        </inertial>
    </link>

    <joint name="w2_2_passive" type="revolute">
        <origin xyz="-0.0020000000000000000416 -0.037499999999999984734 -0.0025000000000000022204" rpy="-0 -1.5707963267948961139 0" />
        <parent link="wheel_3" />
        <child link="passivewheel_42" />
        <axis xyz="0 0 1"/>
        <limit effort="1" velocity="20" />
        <joint_properties friction="0.0"/>
    </joint>

    <link name="passivewheel_43">
        <collision>
            <origin xyz="1.3877787807814456755e-17 0 8.6736173798840354721e-19" rpy="6.1547346583310785461e-17 2.9150407302657955384e-18 2.5086018469333970472e-17" />
            <geometry>
                <mesh filename="package:///passivewheel.stl"/>
            </geometry>
        </collision>
        <visual>
            <origin xyz="1.3877787807814456755e-17 0 8.6736173798840354721e-19" rpy="6.1547346583310785461e-17 2.9150407302657955384e-18 2.5086018469333970472e-17" />
            <geometry>
                <mesh filename="package:///passivewheel.stl"/>
            </geometry>
            <material name="passivewheel_material">
                <color rgba="0.30196078431372547213 0.29019607843137257275 0.26274509803921569651 1.0"/>
            </material>
        </visual>
        <inertial>
            <origin xyz="1.3887701566727105168e-17 4.2332701037397460932e-19 0.0020000000000000013427" rpy="0 0 0"/>
            <mass value="0.0028590609658248017193" />
            <inertia ixx="2.7747274432609138953e-08" ixy="-2.8001833562694219915e-25"  ixz="-1.5998891910957683259e-25" iyy="2.7747274432609152187e-08" iyz="2.5536578819324672528e-24" izz="4.8977394258054644615e-08" />
        </inertial>
    </link>

    <joint name="w2_3_passive" type="revolute">
        <origin xyz="0.0096860242564702301454 -0.036282653349818144717 -0.0025000000000000160982" rpy="1.5707963267948947816 -1.3942429024899469781 1.8849555921538736492" />
        <parent link="wheel_3" />
        <child link="passivewheel_43" />
        <axis xyz="0 0 1"/>
        <limit effort="1" velocity="20" />
        <joint_properties friction="0.0"/>
    </joint>

    <link name="passivewheel_44">
        <collision>
            <origin xyz="1.3877787807814456755e-17 -1.7347234759768070944e-18 0" rpy="-3.141592653589793116 2.0947714449222972289e-17 4.609066871119071539e-17" />
            <geometry>
                <mesh filename="package:///passivewheel.stl"/>
            </geometry>
        </collision>
        <visual>
            <origin xyz="1.3877787807814456755e-17 -1.7347234759768070944e-18 0" rpy="-3.141592653589793116 2.0947714449222972289e-17 4.609066871119071539e-17" />
            <geometry>
                <mesh filename="package:///passivewheel.stl"/>
            </geometry>
            <material name="passivewheel_material">
                <color rgba="0.30196078431372547213 0.29019607843137257275 0.26274509803921569651 1.0"/>
            </material>
        </visual>
        <inertial>
            <origin xyz="1.3819580820059662768e-17 -2.2859008055820168773e-18 -0.002000000000000000909" rpy="0 0 0"/>
            <mass value="0.0028590609658248017193" />
            <inertia ixx="2.7747274432609138953e-08" ixy="1.4930288523455643976e-24"  ixz="1.1660508357683266564e-24" iyy="2.7747274432609138953e-08" iyz="5.1312977384935296504e-24" izz="4.8977394258054671085e-08" />
        </inertial>
    </link>

    <joint name="w2_4_passive" type="revolute">
        <origin xyz="0.020423912972217843353 -0.031513707793645470701 -0.0025000000000000022204" rpy="-1.5707963267948972241 -1.2436334312925123591 2.1991148575128507403" />
        <parent link="wheel_3" />
        <child link="passivewheel_44" />
        <axis xyz="0 0 1"/>
        <limit effort="1" velocity="20" />
        <joint_properties friction="0.0"/>
    </joint>

    <link name="passivewheel_45">
        <collision>
            <origin xyz="-1.3877787807814456755e-17 -5.2041704279304212832e-18 0" rpy="-3.141592653589793116 1.2151999894153162595e-17 3.2488486145960919556e-17" />
            <geometry>
                <mesh filename="package:///passivewheel.stl"/>
            </geometry>
        </collision>
        <visual>
            <origin xyz="-1.3877787807814456755e-17 -5.2041704279304212832e-18 0" rpy="-3.141592653589793116 1.2151999894153162595e-17 3.2488486145960919556e-17" />
            <geometry>
                <mesh filename="package:///passivewheel.stl"/>
            </geometry>
            <material name="passivewheel_material">
                <color rgba="0.30196078431372547213 0.29019607843137257275 0.26274509803921569651 1.0"/>
            </material>
        </visual>
        <inertial>
            <origin xyz="-1.3823038022721641805e-17 -5.3918673282449353329e-18 -0.0020000000000000004753" rpy="0 0 0"/>
            <mass value="0.0028590609658248017193" />
            <inertia ixx="2.7747274432609152187e-08" ixy="1.7167416921942920158e-24"  ixz="-1.3560562575786920406e-24" iyy="2.7747274432609138953e-08" iyz="-2.2497570690155879447e-24" izz="4.8977394258054644615e-08" />
        </inertial>
    </link>

    <joint name="w2_5_passive" type="revolute">
        <origin xyz="0.029162566784475579124 -0.023659980949717641929 -0.0025000000000000022204" rpy="-1.5707963267948972241 -1.1338247319170977612 2.5132741228718300519" />
        <parent link="wheel_3" />
        <child link="passivewheel_45" />
        <axis xyz="0 0 1"/>
        <limit effort="1" velocity="20" />
        <joint_properties friction="0.0"/>
    </joint>

    <link name="passivewheel_46">
        <collision>
            <origin xyz="1.3877787807814456755e-17 -1.7347234759768070944e-18 0" rpy="3.141592653589793116 1.3544772562487964245e-17 1.6815360055220320544e-17" />
            <geometry>
                <mesh filename="package:///passivewheel.stl"/>
            </geometry>
        </collision>
        <visual>
            <origin xyz="1.3877787807814456755e-17 -1.7347234759768070944e-18 0" rpy="3.141592653589793116 1.3544772562487964245e-17 1.6815360055220320544e-17" />
            <geometry>
                <mesh filename="package:///passivewheel.stl"/>
            </geometry>
            <material name="passivewheel_material">
                <color rgba="0.30196078431372547213 0.29019607843137257275 0.26274509803921569651 1.0"/>
            </material>
        </visual>
        <inertial>
            <origin xyz="1.3917324279514773163e-17 -2.0120811024416399875e-18 -0.0020000000000000004753" rpy="0 0 0"/>
            <mass value="0.0028590609658248017193" />
            <inertia ixx="2.7747274432609132335e-08" ixy="3.3905463178548110247e-25"  ixz="-1.0221476790313607142e-24" iyy="2.7747274432609138953e-08" iyz="-3.1936183103934103372e-24" izz="4.8977394258054644615e-08" />
        </inertial>
    </link>

    <joint name="w2_6_passive" type="revolute">
        <origin xyz="0.035046585372318368734 -0.013490250321650834944 -0.0025000000000000022204" rpy="-1.57079632679489678 -1.0686499387975618713 2.8274333882308106958" />
        <parent link="wheel_3" />
        <child link="passivewheel_46" />
        <axis xyz="0 0 1"/>
        <limit effort="1" velocity="20" />
        <joint_properties friction="0.0"/>
    </joint>

    <link name="passivewheel_47">
        <collision>
            <origin xyz="0 -6.9388939039072283776e-18 -0.0040000000000000000833" rpy="1.7081027882436035908e-31 -1.1963780461894121664e-31 -2.1122828256193035998e-17" />
            <geometry>
                <mesh filename="package:///passivewheel.stl"/>
            </geometry>
        </collision>
        <visual>
            <origin xyz="0 -6.9388939039072283776e-18 -0.0040000000000000000833" rpy="1.7081027882436035908e-31 -1.1963780461894121664e-31 -2.1122828256193035998e-17" />
            <geometry>
                <mesh filename="package:///passivewheel.stl"/>
            </geometry>
            <material name="passivewheel_material">
                <color rgba="0.30196078431372547213 0.29019607843137257275 0.26274509803921569651 1.0"/>
            </material>
        </visual>
        <inertial>
            <origin xyz="1.3144003607491982544e-20 -6.55010881959937215e-18 -0.001999999999999999608" rpy="0 0 0"/>
            <mass value="0.0028590609658248017193" />
            <inertia ixx="2.7747274432609132335e-08" ixy="-2.1168737816247390034e-24"  ixz="1.1345013917719866807e-38" iyy="2.7747274432609138953e-08" iyz="-3.6263226868866728243e-39" izz="4.8977394258054644615e-08" />
        </inertial>
    </link>

    <joint name="w2_7_passive" type="revolute">
        <origin xyz="0.037500000000000019429 -0.0020000000000000000416 -0.0025000000000000160982" rpy="-1.5707963267948947816 -0.39309481042651905902 -3.141592653589793116" />
        <parent link="wheel_3" />
        <child link="passivewheel_47" />
        <axis xyz="0 0 1"/>
        <limit effort="1" velocity="20" />
        <joint_properties friction="0.0"/>
    </joint>

    <link name="passivewheel_48">
        <collision>
            <origin xyz="-1.3877787807814456755e-17 -5.6378512969246230568e-18 0.0040000000000000000833" rpy="3.141592653589793116 1.9149295566951270733e-17 5.6341460381355172192e-17" />
            <geometry>
                <mesh filename="package:///passivewheel.stl"/>
            </geometry>
        </collision>
        <visual>
            <origin xyz="-1.3877787807814456755e-17 -5.6378512969246230568e-18 0.0040000000000000000833" rpy="3.141592653589793116 1.9149295566951270733e-17 5.6341460381355172192e-17" />
            <geometry>
                <mesh filename="package:///passivewheel.stl"/>
            </geometry>
            <material name="passivewheel_material">
                <color rgba="0.30196078431372547213 0.29019607843137257275 0.26274509803921569651 1.0"/>
            </material>
        </visual>
        <inertial>
            <origin xyz="-1.3796671028089454271e-17 -6.1171755218026938017e-18 0.001999999999999999608" rpy="0 0 0"/>
            <mass value="0.0028590609658248017193" />
            <inertia ixx="2.7747274432609132335e-08" ixy="-4.146656232993897538e-25"  ixz="-2.1959054866482389958e-24" iyy="2.7747274432609138953e-08" iyz="-6.3888106869411608082e-27" izz="4.8977394258054644615e-08" />
        </inertial>
    </link>

    <joint name="w2_8_passive" type="revolute">
        <origin xyz="0.036282653349818144717 0.0096860242564702145329 -0.0025000000000000022204" rpy="1.570796326794896558 -1.0686499387975689768 -2.8274333882308089194" />
        <parent link="wheel_3" />
        <child link="passivewheel_48" />
        <axis xyz="0 0 1"/>
        <limit effort="1" velocity="20" />
        <joint_properties friction="0.0"/>
    </joint>

    <link name="passivewheel_49">
        <collision>
            <origin xyz="-1.3877787807814456755e-17 8.6736173798840354721e-19 -0.0040000000000000087569" rpy="1.9612493098700965072e-17 -3.9032688374932649092e-17 8.8112409513400593202e-18" />
            <geometry>
                <mesh filename="package:///passivewheel.stl"/>
            </geometry>
        </collision>
        <visual>
            <origin xyz="-1.3877787807814456755e-17 8.6736173798840354721e-19 -0.0040000000000000087569" rpy="1.9612493098700965072e-17 -3.9032688374932649092e-17 8.8112409513400593202e-18" />
            <geometry>
                <mesh filename="package:///passivewheel.stl"/>
            </geometry>
            <material name="passivewheel_material">
                <color rgba="0.30196078431372547213 0.29019607843137257275 0.26274509803921569651 1.0"/>
            </material>
        </visual>
        <inertial>
            <origin xyz="-1.3971249770167124296e-17 1.0614657123491535565e-18 -0.0020000000000000087153" rpy="0 0 0"/>
            <mass value="0.0028590609658248017193" />
            <inertia ixx="2.7747274432609138953e-08" ixy="1.6088374868196211185e-24"  ixz="-1.5275904963639765658e-24" iyy="2.7747274432609138953e-08" iyz="-4.223293509920232141e-24" izz="4.897739425805463138e-08" />
        </inertial>
    </link>

    <joint name="w2_9_passive" type="revolute">
        <origin xyz="0.031513707793645484578 0.020423912972217836415 -0.0025000000000000160982" rpy="-1.570796326794896558 -1.1338247319171015359 -2.5132741228718282755" />
        <parent link="wheel_3" />
        <child link="passivewheel_49" />
        <axis xyz="0 0 1"/>
        <limit effort="1" velocity="20" />
        <joint_properties friction="0.0"/>
    </joint>

    <link name="passivewheel_50">
        <collision>
            <origin xyz="1.3877787807814456755e-17 0 -8.6736173798840354721e-19" rpy="-3.141592653589793116 2.0622478850122694688e-17 1.0218879666417348132e-17" />
            <geometry>
                <mesh filename="package:///passivewheel.stl"/>
            </geometry>
        </collision>
        <visual>
            <origin xyz="1.3877787807814456755e-17 0 -8.6736173798840354721e-19" rpy="-3.141592653589793116 2.0622478850122694688e-17 1.0218879666417348132e-17" />
            <geometry>
                <mesh filename="package:///passivewheel.stl"/>
            </geometry>
            <material name="passivewheel_material">
                <color rgba="0.30196078431372547213 0.29019607843137257275 0.26274509803921569651 1.0"/>
            </material>
        </visual>
        <inertial>
            <origin xyz="1.3805506482906995936e-17 -4.3936072305220106243e-19 -0.0020000000000000013427" rpy="0 0 0"/>
            <mass value="0.0028590609658248017193" />
            <inertia ixx="2.7747274432609138953e-08" ixy="8.5888737302020840658e-25"  ixz="1.5197374170152993861e-24" iyy="2.7747274432609138953e-08" iyz="2.012177563521079686e-24" izz="4.8977394258054644615e-08" />
        </inertial>
    </link>

    <joint name="w2_10_passive" type="revolute">
        <origin xyz="0.023659980949717641929 0.029162566784475568715 -0.0025000000000000022204" rpy="-1.570796326794896336 -1.2436334312925130252 -2.1991148575128507403" />
        <parent link="wheel_3" />
        <child link="passivewheel_50" />
        <axis xyz="0 0 1"/>
        <limit effort="1" velocity="20" />
        <joint_properties friction="0.0"/>
    </joint>

    <link name="passivewheel_51">
        <collision>
            <origin xyz="-1.3877787807814456755e-17 -6.9388939039072283776e-18 -2.6020852139652106416e-18" rpy="3.141592653589793116 1.2149600917911983097e-17 3.7616807374715351477e-17" />
            <geometry>
                <mesh filename="package:///passivewheel.stl"/>
            </geometry>
        </collision>
        <visual>
            <origin xyz="-1.3877787807814456755e-17 -6.9388939039072283776e-18 -2.6020852139652106416e-18" rpy="3.141592653589793116 1.2149600917911983097e-17 3.7616807374715351477e-17" />
            <geometry>
                <mesh filename="package:///passivewheel.stl"/>
            </geometry>
            <material name="passivewheel_material">
                <color rgba="0.30196078431372547213 0.29019607843137257275 0.26274509803921569651 1.0"/>
            </material>
        </visual>
        <inertial>
            <origin xyz="-1.3914282147580492108e-17 -7.5557187755865681371e-18 -0.0020000000000000026437" rpy="0 0 0"/>
            <mass value="0.0028590609658248017193" />
            <inertia ixx="2.7747274432609132335e-08" ixy="7.0140745179338840345e-25"  ixz="8.7846004594501263422e-25" iyy="2.7747274432609138953e-08" iyz="4.8557461831016217607e-24" izz="4.897739425805463138e-08" />
        </inertial>
    </link>

    <joint name="w2_11_passive" type="revolute">
        <origin xyz="0.013490250321650855761 0.035046585372318354856 -0.0025000000000000022204" rpy="-1.5707963267948956698 -1.3942429024899476442 -1.8849555921538736492" />
        <parent link="wheel_3" />
        <child link="passivewheel_51" />
        <axis xyz="0 0 1"/>
        <limit effort="1" velocity="20" />
        <joint_properties friction="0.0"/>
    </joint>

    <link name="passivewheel_52">
        <collision>
            <origin xyz="0 0 0" rpy="3.141592653589793116 -1.3044059530804947457e-32 0" />
            <geometry>
                <mesh filename="package:///passivewheel.stl"/>
            </geometry>
        </collision>
        <visual>
            <origin xyz="0 0 0" rpy="3.141592653589793116 -1.3044059530804947457e-32 0" />
            <geometry>
                <mesh filename="package:///passivewheel.stl"/>
            </geometry>
            <material name="passivewheel_material">
                <color rgba="0.30196078431372547213 0.29019607843137257275 0.26274509803921569651 1.0"/>
            </material>
        </visual>
        <inertial>
            <origin xyz="1.3144003607491636478e-20 -3.8878508430785584243e-19 -0.0020000000000000004753" rpy="0 0 0"/>
            <mass value="0.0028590609658248017193" />
            <inertia ixx="2.7747274432609138953e-08" ixy="0"  ixz="1.328423727866061323e-39" iyy="2.7747274432609138953e-08" iyz="0" izz="4.8977394258054644615e-08" />
        </inertial>
    </link>

    <joint name="w2_12_passive" type="revolute">
        <origin xyz="0.0020000000000000139194 0.037499999999999991673 -0.0025000000000000022204" rpy="3.141592653589793116 -1.570796326794896336 0" />
        <parent link="wheel_3" />
        <child link="passivewheel_52" />
        <axis xyz="0 0 1"/>
        <limit effort="1" velocity="20" />
        <joint_properties friction="0.0"/>
    </joint>

    <link name="passivewheel_53">
        <collision>
            <origin xyz="-1.3877787807814456755e-17 1.3877787807814456755e-17 0" rpy="-3.141592653589793116 -2.1148781938858259153e-18 -3.5481745521054712813e-17" />
            <geometry>
                <mesh filename="package:///passivewheel.stl"/>
            </geometry>
        </collision>
        <visual>
            <origin xyz="-1.3877787807814456755e-17 1.3877787807814456755e-17 0" rpy="-3.141592653589793116 -2.1148781938858259153e-18 -3.5481745521054712813e-17" />
            <geometry>
                <mesh filename="package:///passivewheel.stl"/>
            </geometry>
            <material name="passivewheel_material">
                <color rgba="0.30196078431372547213 0.29019607843137257275 0.26274509803921569651 1.0"/>
            </material>
        </visual>
        <inertial>
            <origin xyz="-1.3874070768807395417e-17 1.3584839071873218528e-17 -0.0020000000000000004753" rpy="0 0 0"/>
            <mass value="0.0028590609658248017193" />
            <inertia ixx="2.7747274432609138953e-08" ixy="-5.2021868964381289536e-25"  ixz="2.8953618658329110958e-25" iyy="2.7747274432609132335e-08" iyz="-6.6630886857557852229e-25" izz="4.8977394258054644615e-08" />
        </inertial>
    </link>

    <joint name="w2_13_passive" type="revolute">
        <origin xyz="-0.0096860242564702006551 0.036282653349818151656 -0.0025000000000000160982" rpy="1.5707963267948958919 -1.3942429024899476442 1.8849555921538738712" />
        <parent link="wheel_3" />
        <child link="passivewheel_53" />
        <axis xyz="0 0 1"/>
        <limit effort="1" velocity="20" />
        <joint_properties friction="0.0"/>
    </joint>

    <link name="passivewheel_54">
        <collision>
            <origin xyz="1.3877787807814456755e-17 0 -0.0040000000000000061548" rpy="9.7053390604459319468e-17 3.7169295545582185549e-17 -6.8547666555834873272e-18" />
            <geometry>
                <mesh filename="package:///passivewheel.stl"/>
            </geometry>
        </collision>
        <visual>
            <origin xyz="1.3877787807814456755e-17 0 -0.0040000000000000061548" rpy="9.7053390604459319468e-17 3.7169295545582185549e-17 -6.8547666555834873272e-18" />
            <geometry>
                <mesh filename="package:///passivewheel.stl"/>
            </geometry>
            <material name="passivewheel_material">
                <color rgba="0.30196078431372547213 0.29019607843137257275 0.26274509803921569651 1.0"/>
            </material>
        </visual>
        <inertial>
            <origin xyz="1.3859993150385018439e-17 5.5829009944681797893e-19 -0.0020000000000000052458" rpy="0 0 0"/>
            <mass value="0.0028590609658248017193" />
            <inertia ixx="2.7747274432609132335e-08" ixy="-1.1098763547079170061e-24"  ixz="-1.7889941436810656893e-24" iyy="2.7747274432609138953e-08" iyz="6.843924041306376744e-24" izz="4.8977394258054671085e-08" />
        </inertial>
    </link>

    <joint name="w2_14_passive" type="revolute">
        <origin xyz="-0.020423912972217812128 0.031513707793645477639 -0.0025000000000000022204" rpy="1.570796326794896558 -1.2436334312925132473 2.1991148575128502962" />
        <parent link="wheel_3" />
        <child link="passivewheel_54" />
        <axis xyz="0 0 1"/>
        <limit effort="1" velocity="20" />
        <joint_properties friction="0.0"/>
    </joint>

    <link name="passivewheel_55">
        <collision>
            <origin xyz="0 -1.3877787807814456755e-17 -0.0040000000000000035527" rpy="-2.6089343893096280682e-17 1.609663984953015032e-18 2.3161932260058612908e-17" />
            <geometry>
                <mesh filename="package:///passivewheel.stl"/>
            </geometry>
        </collision>
        <visual>
            <origin xyz="0 -1.3877787807814456755e-17 -0.0040000000000000035527" rpy="-2.6089343893096280682e-17 1.609663984953015032e-18 2.3161932260058612908e-17" />
            <geometry>
                <mesh filename="package:///passivewheel.stl"/>
            </geometry>
            <material name="passivewheel_material">
                <color rgba="0.30196078431372547213 0.29019607843137257275 0.26274509803921569651 1.0"/>
            </material>
        </visual>
        <inertial>
            <origin xyz="-2.4234993111544020127e-20 -1.3467041057703875676e-17 -0.0020000000000000035111" rpy="0 0 0"/>
            <mass value="0.0028590609658248017193" />
            <inertia ixx="2.7747274432609138953e-08" ixy="1.7276306003964488552e-24"  ixz="-9.6002671797414975939e-25" iyy="2.7747274432609132335e-08" iyz="-1.8609560247660124558e-25" izz="4.897739425805463138e-08" />
        </inertial>
    </link>

    <joint name="w2_15_passive" type="revolute">
        <origin xyz="-0.029162566784475568715 0.023659980949717641929 -0.0025000000000000022204" rpy="1.570796326794896336 -1.1338247319170990934 2.5132741228718296078" />
        <parent link="wheel_3" />
        <child link="passivewheel_55" />
        <axis xyz="0 0 1"/>
        <limit effort="1" velocity="20" />
        <joint_properties friction="0.0"/>
    </joint>

    <link name="passivewheel_56">
        <collision>
            <origin xyz="-6.9388939039072283776e-18 1.3877787807814456755e-17 -0.0040000000000000000833" rpy="-2.9264521963125037701e-17 5.1064456669351041511e-18 3.7959073516742216808e-17" />
            <geometry>
                <mesh filename="package:///passivewheel.stl"/>
            </geometry>
        </collision>
        <visual>
            <origin xyz="-6.9388939039072283776e-18 1.3877787807814456755e-17 -0.0040000000000000000833" rpy="-2.9264521963125037701e-17 5.1064456669351041511e-18 3.7959073516742216808e-17" />
            <geometry>
                <mesh filename="package:///passivewheel.stl"/>
            </geometry>
            <material name="passivewheel_material">
                <color rgba="0.30196078431372547213 0.29019607843137257275 0.26274509803921569651 1.0"/>
            </material>
        </visual>
        <inertial>
            <origin xyz="-6.8494090374988592009e-18 1.4086446962198752423e-17 -0.001999999999999999608" rpy="0 0 0"/>
            <mass value="0.0028590609658248017193" />
            <inertia ixx="2.7747274432609132335e-08" ixy="3.9474623993243784293e-24"  ixz="1.7277983184036664024e-24" iyy="2.7747274432609125718e-08" iyz="-5.2230600650323945647e-24" izz="4.8977394258054644615e-08" />
        </inertial>
    </link>

    <joint name="w2_16_passive" type="revolute">
        <origin xyz="-0.035046585372318354856 0.013490250321650847087 -0.0025000000000000160982" rpy="1.57079632679489678 -1.06864993879756498 2.8274333882308102517" />
        <parent link="wheel_3" />
        <child link="passivewheel_56" />
        <axis xyz="0 0 1"/>
        <limit effort="1" velocity="20" />
        <joint_properties friction="0.0"/>
    </joint>

    <link name="passivewheel_57">
        <collision>
            <origin xyz="-1.7347234759768070944e-18 0 0.0040000000000000000833" rpy="3.141592653589793116 -2.5238089354745245888e-32 2.8466621022239409214e-17" />
            <geometry>
                <mesh filename="package:///passivewheel.stl"/>
            </geometry>
        </collision>
        <visual>
            <origin xyz="-1.7347234759768070944e-18 0 0.0040000000000000000833" rpy="3.141592653589793116 -2.5238089354745245888e-32 2.8466621022239409214e-17" />
            <geometry>
                <mesh filename="package:///passivewheel.stl"/>
            </geometry>
            <material name="passivewheel_material">
                <color rgba="0.30196078431372547213 0.29019607843137257275 0.26274509803921569651 1.0"/>
            </material>
        </visual>
        <inertial>
            <origin xyz="-1.7215794723693153165e-18 -3.8878508430785574613e-19 0.001999999999999999608" rpy="0 0 0"/>
            <mass value="0.0028590609658248017193" />
            <inertia ixx="2.7747274432609138953e-08" ixy="2.1776378506652018043e-24"  ixz="-2.9505796342776318742e-39" iyy="2.7747274432609132335e-08" iyz="-1.3866791917505356575e-39" izz="4.8977394258054644615e-08" />
        </inertial>
    </link>

    <joint name="w2_17_passive" type="revolute">
        <origin xyz="-0.037499999999999991673 0.0020000000000000139194 -0.0025000000000000022204" rpy="-1.5707963267948972241 -0.39309481042651966964 -3.141592653589793116" />
        <parent link="wheel_3" />
        <child link="passivewheel_57" />
        <axis xyz="0 0 1"/>
        <limit effort="1" velocity="20" />
        <joint_properties friction="0.0"/>
    </joint>

    <link name="passivewheel_58">
        <collision>
            <origin xyz="0 0 0" rpy="3.141592653589793116 -7.7914149517891205323e-18 -7.7837927380634981e-17" />
            <geometry>
                <mesh filename="package:///passivewheel.stl"/>
            </geometry>
        </collision>
        <visual>
            <origin xyz="0 0 0" rpy="3.141592653589793116 -7.7914149517891205323e-18 -7.7837927380634981e-17" />
            <geometry>
                <mesh filename="package:///passivewheel.stl"/>
            </geometry>
            <material name="passivewheel_material">
                <color rgba="0.30196078431372547213 0.29019607843137257275 0.26274509803921569651 1.0"/>
            </material>
        </visual>
        <inertial>
            <origin xyz="4.7128297503407399441e-20 -5.2983509611712228724e-19 -0.0020000000000000004753" rpy="0 0 0"/>
            <mass value="0.0028590609658248017193" />
            <inertia ixx="2.7747274432609138953e-08" ixy="-8.8909433350643132045e-26"  ixz="-6.1604055147530624197e-25" iyy="2.7747274432609138953e-08" iyz="2.3792788769181164149e-24" izz="4.8977394258054644615e-08" />
        </inertial>
    </link>

    <joint name="w2_18_passive" type="revolute">
        <origin xyz="-0.036282653349818116961 -0.0096860242564702110635 -0.0024999999999999883427" rpy="1.5707963267948970021 -1.0686499387975580966 -2.8274333882308093635" />
        <parent link="wheel_3" />
        <child link="passivewheel_58" />
        <axis xyz="0 0 1"/>
        <limit effort="1" velocity="20" />
        <joint_properties friction="0.0"/>
    </joint>

    <link name="passivewheel_59">
        <collision>
            <origin xyz="-1.3877787807814456755e-17 6.9388939039072283776e-18 0" rpy="3.141592653589793116 3.709485243889688405e-18 -1.0803437149480344933e-17" />
            <geometry>
                <mesh filename="package:///passivewheel.stl"/>
            </geometry>
        </collision>
        <visual>
            <origin xyz="-1.3877787807814456755e-17 6.9388939039072283776e-18 0" rpy="3.141592653589793116 3.709485243889688405e-18 -1.0803437149480344933e-17" />
            <geometry>
                <mesh filename="package:///passivewheel.stl"/>
            </geometry>
            <material name="passivewheel_material">
                <color rgba="0.30196078431372547213 0.29019607843137257275 0.26274509803921569651 1.0"/>
            </material>
        </visual>
        <inertial>
            <origin xyz="-1.3825821744758845709e-17 6.5155097681576998466e-18 -0.0020000000000000004753" rpy="0 0 0"/>
            <mass value="0.0028590609658248017193" />
            <inertia ixx="2.7747274432609138953e-08" ixy="6.374363413939742405e-25"  ixz="-1.053629760816014345e-24" iyy="2.7747274432609132335e-08" iyz="9.5359874006751863704e-28" izz="4.8977394258054644615e-08" />
        </inertial>
    </link>

    <joint name="w2_19_passive" type="revolute">
        <origin xyz="-0.031513707793645470701 -0.020423912972217826006 -0.0025000000000000022204" rpy="1.5707963267948970021 -1.1338247319170962069 -2.5132741228718282755" />
        <parent link="wheel_3" />
        <child link="passivewheel_59" />
        <axis xyz="0 0 1"/>
        <limit effort="1" velocity="20" />
        <joint_properties friction="0.0"/>
    </joint>

    <link name="passivewheel_60">
        <collision>
            <origin xyz="-2.7755575615628913511e-17 1.3877787807814456755e-17 0" rpy="3.141592653589793116 2.5315538914918274566e-17 -8.3895761041947024416e-17" />
            <geometry>
                <mesh filename="package:///passivewheel.stl"/>
            </geometry>
        </collision>
        <visual>
            <origin xyz="-2.7755575615628913511e-17 1.3877787807814456755e-17 0" rpy="3.141592653589793116 2.5315538914918274566e-17 -8.3895761041947024416e-17" />
            <geometry>
                <mesh filename="package:///passivewheel.stl"/>
            </geometry>
            <material name="passivewheel_material">
                <color rgba="0.30196078431372547213 0.29019607843137257275 0.26274509803921569651 1.0"/>
            </material>
        </visual>
        <inertial>
            <origin xyz="-2.7777633724253711772e-17 1.333625407993940913e-17 -0.0020000000000000000416" rpy="0 0 0"/>
            <mass value="0.0028590609658248017193" />
            <inertia ixx="2.7747274432609138953e-08" ixy="-1.3361843603203250938e-24"  ixz="1.5961665907700313876e-25" iyy="2.7747274432609138953e-08" iyz="3.1197734975407984815e-24" izz="4.897739425805463138e-08" />
        </inertial>
    </link>

    <joint name="w2_20_passive" type="revolute">
        <origin xyz="-0.023659980949717645399 -0.029162566784475568715 -0.0025000000000000160982" rpy="1.5707963267948972241 -1.2436334312925112489 -2.1991148575128476317" />
        <parent link="wheel_3" />
        <child link="passivewheel_60" />
        <axis xyz="0 0 1"/>
        <limit effort="1" velocity="20" />
        <joint_properties friction="0.0"/>
    </joint>

    <joint name="wheel2_speed" type="revolute">
        <origin xyz="-6.7964690206827526099e-17 0.080000000000000182077 0.013000000000000034098" rpy="1.570796326794896558 -0 6.2948235302926373743e-16" />
        <parent link="body" />
        <child link="wheel_3" />
        <axis xyz="0 0 1"/>
        <limit effort="1" velocity="20" />
        <joint_properties friction="0.0"/>
    </joint>


</robot>
