<?xml version="1.0"?>

<robot xmlns:xacro="http://www.ros.org/wiki/xacro" name="roller">

    <material name="green">
        <color rgba="0 1 0 1.0"/>
    </material>

    <xacro:macro name="roller" params="id wheel_id pitch x y z">
        <link name="roller_${wheel_id}_${id}_link">
            <inertial>
                <origin xyz="4.0756135840652012993e-11 8.4957117072138698775e-11 2.4283850775576134338e-11" rpy="0 0 0"/>
                <mass value="0.0037899803393768708749" />
                <inertia ixx="1.8303635244743848899e-07" ixy="4.2716081106694475295e-16"  ixz="-1.7514569765292920798e-15" iyy="1.830363607521377626e-07" iyz="-3.3429142897629588724e-15" izz="9.8097062080638907831e-08" />
            </inertial>
            <visual>
                <origin rpy="0 0 0" xyz="0 0 0"/>
                <geometry>
                    <mesh filename="package://omnibot_description/meshes/wheel/roller.stl"/>
                </geometry>
                <material name="green"/>
            </visual>
            <collision>
                <origin rpy="0 0 0" xyz="0 0 0"/>
                <geometry>
                    <mesh filename="package://omnibot_description/meshes/wheel/colision_omni_roller.stl"/>
                </geometry>
            </collision>
        </link>

        <joint name="roller_${wheel_id}_${id}_joint" type="continuous">
            <parent link="wheel_${wheel_id}_link"/>
            <child link="roller_${wheel_id}_${id}_link"/>
            <axis xyz="0 0 1"/>
            <origin rpy="0 ${pitch} 0" xyz="${x} ${y} ${z}"/>
        </joint>
    </xacro:macro>
</robot>
